[I] Loading dataset AQSOL...
train, test, val sizes : 7831 996 996
[I] Finished loading.
[I] Data load time: 6.7158s
Traceback (most recent call last):
  File "/afs/crc.nd.edu/user/p/psoga/benchmarking-gnns/train/train_molecules_graph_regression.py", line 57, in evaluate_network_sparse
    batch_pos_enc = batch_graphs.ndata['pos_enc'].to(device)
  File "/afs/crc.nd.edu/user/p/psoga/.conda/envs/gnn/lib/python3.10/site-packages/dgl/view.py", line 67, in __getitem__
    return self._graph._get_n_repr(self._ntid, self._nodes)[key]
  File "/afs/crc.nd.edu/user/p/psoga/.conda/envs/gnn/lib/python3.10/site-packages/dgl/frame.py", line 523, in __getitem__
    return self._columns[name].data
KeyError: 'pos_enc'

During handling of the above exception, another exception occurred:

Traceback (most recent call last):
  File "/afs/crc.nd.edu/user/p/psoga/benchmarking-gnns/main_molecules_graph_regression.py", line 304, in <module>
    main()    
  File "/afs/crc.nd.edu/user/p/psoga/benchmarking-gnns/main_molecules_graph_regression.py", line 302, in main
    train_val_pipeline(MODEL_NAME, dataset, params, net_params, dirs)
  File "/afs/crc.nd.edu/user/p/psoga/benchmarking-gnns/main_molecules_graph_regression.py", line 120, in train_val_pipeline
    epoch_val_loss, epoch_val_mae = evaluate_network(model, device, val_loader, epoch)
  File "/afs/crc.nd.edu/user/p/psoga/benchmarking-gnns/train/train_molecules_graph_regression.py", line 60, in evaluate_network_sparse
    batch_scores = model.forward(batch_graphs, batch_x, batch_e)
  File "/afs/crc.nd.edu/user/p/psoga/benchmarking-gnns/nets/molecules_graph_regression/graph_transformer.py", line 50, in forward
    h = self.pe_layer(g, h, pos_enc)
  File "/afs/crc.nd.edu/user/p/psoga/.conda/envs/gnn/lib/python3.10/site-packages/torch/nn/modules/module.py", line 1130, in _call_impl
    return forward_call(*input, **kwargs)
  File "/afs/crc.nd.edu/user/p/psoga/benchmarking-gnns/layers/pe_layer.py", line 130, in forward
    B = torch.eye(kron_prod.shape[1]).to(self.device) - kron_prod
RuntimeError: CUDA out of memory. Tried to allocate 2.96 GiB (GPU 0; 10.92 GiB total capacity; 5.95 GiB already allocated; 1.79 GiB free; 8.43 GiB reserved in total by PyTorch) If reserved memory is >> allocated memory try setting max_split_size_mb to avoid fragmentation.  See documentation for Memory Management and PYTORCH_CUDA_ALLOC_CONF
