--- Logging error ---
Traceback (most recent call last):
  File "/afs/crc.nd.edu/user/p/psoga/.conda/envs/gnn/lib/python3.10/logging/__init__.py", line 1104, in emit
    self.flush()
  File "/afs/crc.nd.edu/user/p/psoga/.conda/envs/gnn/lib/python3.10/logging/__init__.py", line 1084, in flush
    self.stream.flush()
OSError: [Errno 5] Input/output error
Call stack:
  File "/afs/crc.nd.edu/user/p/psoga/benchmarking-gnns/main_SBMs_node_classification.py", line 382, in <module>
    net_params['in_dim'] = torch.unique(dataset.train[0][0].ndata['feat'],dim=0).size(0) # node_dim (feat is an integer)
  File "/afs/crc.nd.edu/user/p/psoga/benchmarking-gnns/main_SBMs_node_classification.py", line 380, in main
    dataset.test.spatial_pos_lists = []
  File "/afs/crc.nd.edu/user/p/psoga/benchmarking-gnns/main_SBMs_node_classification.py", line 231, in train_val_pipeline
    # writer.add_scalar('train/_loss', epoch_train_loss, epoch)
Message: '\tTime: 139.93s, LR: 0.00000, Train Loss: 0.3530, Train Acc: 84.2176,\n                            Val Loss: 0.3494, Val Acc: 84.4809, Test Acc: 84.4943'
Arguments: ()
--- Logging error ---
Traceback (most recent call last):
  File "/afs/crc.nd.edu/user/p/psoga/.conda/envs/gnn/lib/python3.10/logging/__init__.py", line 1104, in emit
    self.flush()
  File "/afs/crc.nd.edu/user/p/psoga/.conda/envs/gnn/lib/python3.10/logging/__init__.py", line 1084, in flush
    self.stream.flush()
OSError: [Errno 5] Input/output error
Call stack:
  File "/afs/crc.nd.edu/user/p/psoga/benchmarking-gnns/main_SBMs_node_classification.py", line 382, in <module>
    net_params['in_dim'] = torch.unique(dataset.train[0][0].ndata['feat'],dim=0).size(0) # node_dim (feat is an integer)
  File "/afs/crc.nd.edu/user/p/psoga/benchmarking-gnns/main_SBMs_node_classification.py", line 380, in main
    dataset.test.spatial_pos_lists = []
  File "/afs/crc.nd.edu/user/p/psoga/benchmarking-gnns/main_SBMs_node_classification.py", line 189, in train_val_pipeline
    else:
Message: 'Epoch 211/1000'
Arguments: ()
--- Logging error ---
Traceback (most recent call last):
  File "/afs/crc.nd.edu/user/p/psoga/.conda/envs/gnn/lib/python3.10/logging/__init__.py", line 1104, in emit
    self.flush()
  File "/afs/crc.nd.edu/user/p/psoga/.conda/envs/gnn/lib/python3.10/logging/__init__.py", line 1084, in flush
    self.stream.flush()
OSError: [Errno 5] Input/output error
Call stack:
  File "/afs/crc.nd.edu/user/p/psoga/benchmarking-gnns/main_SBMs_node_classification.py", line 382, in <module>
    net_params['in_dim'] = torch.unique(dataset.train[0][0].ndata['feat'],dim=0).size(0) # node_dim (feat is an integer)
  File "/afs/crc.nd.edu/user/p/psoga/benchmarking-gnns/main_SBMs_node_classification.py", line 380, in main
    dataset.test.spatial_pos_lists = []
  File "/afs/crc.nd.edu/user/p/psoga/benchmarking-gnns/main_SBMs_node_classification.py", line 231, in train_val_pipeline
    # writer.add_scalar('train/_loss', epoch_train_loss, epoch)
Message: '\tTime: 139.75s, LR: 0.00000, Train Loss: 0.3528, Train Acc: 84.2409,\n                            Val Loss: 0.3499, Val Acc: 84.3827, Test Acc: 84.4260'
Arguments: ()
--- Logging error ---
Traceback (most recent call last):
  File "/afs/crc.nd.edu/user/p/psoga/.conda/envs/gnn/lib/python3.10/logging/__init__.py", line 1104, in emit
    self.flush()
  File "/afs/crc.nd.edu/user/p/psoga/.conda/envs/gnn/lib/python3.10/logging/__init__.py", line 1084, in flush
    self.stream.flush()
OSError: [Errno 5] Input/output error
Call stack:
  File "/afs/crc.nd.edu/user/p/psoga/benchmarking-gnns/main_SBMs_node_classification.py", line 382, in <module>
    net_params['in_dim'] = torch.unique(dataset.train[0][0].ndata['feat'],dim=0).size(0) # node_dim (feat is an integer)
  File "/afs/crc.nd.edu/user/p/psoga/benchmarking-gnns/main_SBMs_node_classification.py", line 380, in main
    dataset.test.spatial_pos_lists = []
  File "/afs/crc.nd.edu/user/p/psoga/benchmarking-gnns/main_SBMs_node_classification.py", line 189, in train_val_pipeline
    else:
Message: 'Epoch 212/1000'
Arguments: ()
--- Logging error ---
Traceback (most recent call last):
  File "/afs/crc.nd.edu/user/p/psoga/.conda/envs/gnn/lib/python3.10/logging/__init__.py", line 1104, in emit
    self.flush()
  File "/afs/crc.nd.edu/user/p/psoga/.conda/envs/gnn/lib/python3.10/logging/__init__.py", line 1084, in flush
    self.stream.flush()
OSError: [Errno 5] Input/output error
Call stack:
  File "/afs/crc.nd.edu/user/p/psoga/benchmarking-gnns/main_SBMs_node_classification.py", line 382, in <module>
    net_params['in_dim'] = torch.unique(dataset.train[0][0].ndata['feat'],dim=0).size(0) # node_dim (feat is an integer)
  File "/afs/crc.nd.edu/user/p/psoga/benchmarking-gnns/main_SBMs_node_classification.py", line 380, in main
    dataset.test.spatial_pos_lists = []
  File "/afs/crc.nd.edu/user/p/psoga/benchmarking-gnns/main_SBMs_node_classification.py", line 231, in train_val_pipeline
    # writer.add_scalar('train/_loss', epoch_train_loss, epoch)
Message: '\tTime: 139.62s, LR: 0.00000, Train Loss: 0.3527, Train Acc: 84.2454,\n                            Val Loss: 0.3499, Val Acc: 84.3393, Test Acc: 84.4951'
Arguments: ()
--- Logging error ---
Traceback (most recent call last):
  File "/afs/crc.nd.edu/user/p/psoga/.conda/envs/gnn/lib/python3.10/logging/__init__.py", line 1104, in emit
    self.flush()
  File "/afs/crc.nd.edu/user/p/psoga/.conda/envs/gnn/lib/python3.10/logging/__init__.py", line 1084, in flush
    self.stream.flush()
OSError: [Errno 5] Input/output error
Call stack:
  File "/afs/crc.nd.edu/user/p/psoga/benchmarking-gnns/main_SBMs_node_classification.py", line 382, in <module>
    net_params['in_dim'] = torch.unique(dataset.train[0][0].ndata['feat'],dim=0).size(0) # node_dim (feat is an integer)
  File "/afs/crc.nd.edu/user/p/psoga/benchmarking-gnns/main_SBMs_node_classification.py", line 380, in main
    dataset.test.spatial_pos_lists = []
  File "/afs/crc.nd.edu/user/p/psoga/benchmarking-gnns/main_SBMs_node_classification.py", line 189, in train_val_pipeline
    else:
Message: 'Epoch 213/1000'
Arguments: ()
--- Logging error ---
Traceback (most recent call last):
  File "/afs/crc.nd.edu/user/p/psoga/.conda/envs/gnn/lib/python3.10/logging/__init__.py", line 1104, in emit
    self.flush()
  File "/afs/crc.nd.edu/user/p/psoga/.conda/envs/gnn/lib/python3.10/logging/__init__.py", line 1084, in flush
    self.stream.flush()
OSError: [Errno 5] Input/output error
Call stack:
  File "/afs/crc.nd.edu/user/p/psoga/benchmarking-gnns/main_SBMs_node_classification.py", line 382, in <module>
    net_params['in_dim'] = torch.unique(dataset.train[0][0].ndata['feat'],dim=0).size(0) # node_dim (feat is an integer)
  File "/afs/crc.nd.edu/user/p/psoga/benchmarking-gnns/main_SBMs_node_classification.py", line 380, in main
    dataset.test.spatial_pos_lists = []
  File "/afs/crc.nd.edu/user/p/psoga/benchmarking-gnns/main_SBMs_node_classification.py", line 231, in train_val_pipeline
    # writer.add_scalar('train/_loss', epoch_train_loss, epoch)
Message: '\tTime: 140.00s, LR: 0.00000, Train Loss: 0.3533, Train Acc: 84.2162,\n                            Val Loss: 0.3489, Val Acc: 84.4103, Test Acc: 84.4930'
Arguments: ()
--- Logging error ---
Traceback (most recent call last):
  File "/afs/crc.nd.edu/user/p/psoga/.conda/envs/gnn/lib/python3.10/logging/__init__.py", line 1104, in emit
    self.flush()
  File "/afs/crc.nd.edu/user/p/psoga/.conda/envs/gnn/lib/python3.10/logging/__init__.py", line 1084, in flush
    self.stream.flush()
OSError: [Errno 5] Input/output error
Call stack:
  File "/afs/crc.nd.edu/user/p/psoga/benchmarking-gnns/main_SBMs_node_classification.py", line 382, in <module>
    net_params['in_dim'] = torch.unique(dataset.train[0][0].ndata['feat'],dim=0).size(0) # node_dim (feat is an integer)
  File "/afs/crc.nd.edu/user/p/psoga/benchmarking-gnns/main_SBMs_node_classification.py", line 380, in main
    dataset.test.spatial_pos_lists = []
  File "/afs/crc.nd.edu/user/p/psoga/benchmarking-gnns/main_SBMs_node_classification.py", line 189, in train_val_pipeline
    else:
Message: 'Epoch 214/1000'
Arguments: ()
--- Logging error ---
Traceback (most recent call last):
  File "/afs/crc.nd.edu/user/p/psoga/.conda/envs/gnn/lib/python3.10/logging/__init__.py", line 1104, in emit
    self.flush()
  File "/afs/crc.nd.edu/user/p/psoga/.conda/envs/gnn/lib/python3.10/logging/__init__.py", line 1084, in flush
    self.stream.flush()
OSError: [Errno 5] Input/output error
Call stack:
  File "/afs/crc.nd.edu/user/p/psoga/benchmarking-gnns/main_SBMs_node_classification.py", line 382, in <module>
    net_params['in_dim'] = torch.unique(dataset.train[0][0].ndata['feat'],dim=0).size(0) # node_dim (feat is an integer)
  File "/afs/crc.nd.edu/user/p/psoga/benchmarking-gnns/main_SBMs_node_classification.py", line 380, in main
    dataset.test.spatial_pos_lists = []
  File "/afs/crc.nd.edu/user/p/psoga/benchmarking-gnns/main_SBMs_node_classification.py", line 231, in train_val_pipeline
    # writer.add_scalar('train/_loss', epoch_train_loss, epoch)
Message: '\tTime: 139.67s, LR: 0.00000, Train Loss: 0.3538, Train Acc: 84.1661,\n                            Val Loss: 0.3499, Val Acc: 84.4083, Test Acc: 84.4423'
Arguments: ()
--- Logging error ---
Traceback (most recent call last):
  File "/afs/crc.nd.edu/user/p/psoga/.conda/envs/gnn/lib/python3.10/logging/__init__.py", line 1104, in emit
    self.flush()
  File "/afs/crc.nd.edu/user/p/psoga/.conda/envs/gnn/lib/python3.10/logging/__init__.py", line 1084, in flush
    self.stream.flush()
OSError: [Errno 5] Input/output error
Call stack:
  File "/afs/crc.nd.edu/user/p/psoga/benchmarking-gnns/main_SBMs_node_classification.py", line 382, in <module>
    net_params['in_dim'] = torch.unique(dataset.train[0][0].ndata['feat'],dim=0).size(0) # node_dim (feat is an integer)
  File "/afs/crc.nd.edu/user/p/psoga/benchmarking-gnns/main_SBMs_node_classification.py", line 380, in main
    dataset.test.spatial_pos_lists = []
  File "/afs/crc.nd.edu/user/p/psoga/benchmarking-gnns/main_SBMs_node_classification.py", line 189, in train_val_pipeline
    else:
Message: 'Epoch 215/1000'
Arguments: ()
--- Logging error ---
Traceback (most recent call last):
  File "/afs/crc.nd.edu/user/p/psoga/.conda/envs/gnn/lib/python3.10/logging/__init__.py", line 1104, in emit
    self.flush()
  File "/afs/crc.nd.edu/user/p/psoga/.conda/envs/gnn/lib/python3.10/logging/__init__.py", line 1084, in flush
    self.stream.flush()
OSError: [Errno 5] Input/output error
Call stack:
  File "/afs/crc.nd.edu/user/p/psoga/benchmarking-gnns/main_SBMs_node_classification.py", line 382, in <module>
    net_params['in_dim'] = torch.unique(dataset.train[0][0].ndata['feat'],dim=0).size(0) # node_dim (feat is an integer)
  File "/afs/crc.nd.edu/user/p/psoga/benchmarking-gnns/main_SBMs_node_classification.py", line 380, in main
    dataset.test.spatial_pos_lists = []
  File "/afs/crc.nd.edu/user/p/psoga/benchmarking-gnns/main_SBMs_node_classification.py", line 231, in train_val_pipeline
    # writer.add_scalar('train/_loss', epoch_train_loss, epoch)
Message: '\tTime: 140.00s, LR: 0.00000, Train Loss: 0.3531, Train Acc: 84.1861,\n                            Val Loss: 0.3497, Val Acc: 84.4123, Test Acc: 84.5522'
Arguments: ()
--- Logging error ---
Traceback (most recent call last):
  File "/afs/crc.nd.edu/user/p/psoga/.conda/envs/gnn/lib/python3.10/logging/__init__.py", line 1104, in emit
    self.flush()
  File "/afs/crc.nd.edu/user/p/psoga/.conda/envs/gnn/lib/python3.10/logging/__init__.py", line 1084, in flush
    self.stream.flush()
OSError: [Errno 5] Input/output error
Call stack:
  File "/afs/crc.nd.edu/user/p/psoga/benchmarking-gnns/main_SBMs_node_classification.py", line 382, in <module>
    net_params['in_dim'] = torch.unique(dataset.train[0][0].ndata['feat'],dim=0).size(0) # node_dim (feat is an integer)
  File "/afs/crc.nd.edu/user/p/psoga/benchmarking-gnns/main_SBMs_node_classification.py", line 380, in main
    dataset.test.spatial_pos_lists = []
  File "/afs/crc.nd.edu/user/p/psoga/benchmarking-gnns/main_SBMs_node_classification.py", line 189, in train_val_pipeline
    else:
Message: 'Epoch 216/1000'
Arguments: ()
--- Logging error ---
Traceback (most recent call last):
  File "/afs/crc.nd.edu/user/p/psoga/.conda/envs/gnn/lib/python3.10/logging/__init__.py", line 1104, in emit
    self.flush()
  File "/afs/crc.nd.edu/user/p/psoga/.conda/envs/gnn/lib/python3.10/logging/__init__.py", line 1084, in flush
    self.stream.flush()
OSError: [Errno 5] Input/output error
Call stack:
  File "/afs/crc.nd.edu/user/p/psoga/benchmarking-gnns/main_SBMs_node_classification.py", line 382, in <module>
    net_params['in_dim'] = torch.unique(dataset.train[0][0].ndata['feat'],dim=0).size(0) # node_dim (feat is an integer)
  File "/afs/crc.nd.edu/user/p/psoga/benchmarking-gnns/main_SBMs_node_classification.py", line 380, in main
    dataset.test.spatial_pos_lists = []
  File "/afs/crc.nd.edu/user/p/psoga/benchmarking-gnns/main_SBMs_node_classification.py", line 231, in train_val_pipeline
    # writer.add_scalar('train/_loss', epoch_train_loss, epoch)
Message: '\tTime: 139.63s, LR: 0.00000, Train Loss: 0.3527, Train Acc: 84.2599,\n                            Val Loss: 0.3496, Val Acc: 84.4265, Test Acc: 84.4946'
Arguments: ()
--- Logging error ---
Traceback (most recent call last):
  File "/afs/crc.nd.edu/user/p/psoga/.conda/envs/gnn/lib/python3.10/logging/__init__.py", line 1104, in emit
    self.flush()
  File "/afs/crc.nd.edu/user/p/psoga/.conda/envs/gnn/lib/python3.10/logging/__init__.py", line 1084, in flush
    self.stream.flush()
OSError: [Errno 5] Input/output error
Call stack:
  File "/afs/crc.nd.edu/user/p/psoga/benchmarking-gnns/main_SBMs_node_classification.py", line 382, in <module>
    net_params['in_dim'] = torch.unique(dataset.train[0][0].ndata['feat'],dim=0).size(0) # node_dim (feat is an integer)
  File "/afs/crc.nd.edu/user/p/psoga/benchmarking-gnns/main_SBMs_node_classification.py", line 380, in main
    dataset.test.spatial_pos_lists = []
  File "/afs/crc.nd.edu/user/p/psoga/benchmarking-gnns/main_SBMs_node_classification.py", line 189, in train_val_pipeline
    else:
Message: 'Epoch 217/1000'
Arguments: ()
--- Logging error ---
Traceback (most recent call last):
  File "/afs/crc.nd.edu/user/p/psoga/.conda/envs/gnn/lib/python3.10/logging/__init__.py", line 1104, in emit
    self.flush()
  File "/afs/crc.nd.edu/user/p/psoga/.conda/envs/gnn/lib/python3.10/logging/__init__.py", line 1084, in flush
    self.stream.flush()
OSError: [Errno 5] Input/output error
Call stack:
  File "/afs/crc.nd.edu/user/p/psoga/benchmarking-gnns/main_SBMs_node_classification.py", line 382, in <module>
    net_params['in_dim'] = torch.unique(dataset.train[0][0].ndata['feat'],dim=0).size(0) # node_dim (feat is an integer)
  File "/afs/crc.nd.edu/user/p/psoga/benchmarking-gnns/main_SBMs_node_classification.py", line 380, in main
    dataset.test.spatial_pos_lists = []
  File "/afs/crc.nd.edu/user/p/psoga/benchmarking-gnns/main_SBMs_node_classification.py", line 231, in train_val_pipeline
    # writer.add_scalar('train/_loss', epoch_train_loss, epoch)
Message: '\tTime: 139.67s, LR: 0.00000, Train Loss: 0.3524, Train Acc: 84.2831,\n                            Val Loss: 0.3501, Val Acc: 84.3340, Test Acc: 84.4949'
Arguments: ()
--- Logging error ---
Traceback (most recent call last):
  File "/afs/crc.nd.edu/user/p/psoga/.conda/envs/gnn/lib/python3.10/logging/__init__.py", line 1104, in emit
    self.flush()
  File "/afs/crc.nd.edu/user/p/psoga/.conda/envs/gnn/lib/python3.10/logging/__init__.py", line 1084, in flush
    self.stream.flush()
OSError: [Errno 5] Input/output error
Call stack:
  File "/afs/crc.nd.edu/user/p/psoga/benchmarking-gnns/main_SBMs_node_classification.py", line 382, in <module>
    net_params['in_dim'] = torch.unique(dataset.train[0][0].ndata['feat'],dim=0).size(0) # node_dim (feat is an integer)
  File "/afs/crc.nd.edu/user/p/psoga/benchmarking-gnns/main_SBMs_node_classification.py", line 380, in main
    dataset.test.spatial_pos_lists = []
  File "/afs/crc.nd.edu/user/p/psoga/benchmarking-gnns/main_SBMs_node_classification.py", line 189, in train_val_pipeline
    else:
Message: 'Epoch 218/1000'
Arguments: ()
--- Logging error ---
Traceback (most recent call last):
  File "/afs/crc.nd.edu/user/p/psoga/.conda/envs/gnn/lib/python3.10/logging/__init__.py", line 1104, in emit
    self.flush()
  File "/afs/crc.nd.edu/user/p/psoga/.conda/envs/gnn/lib/python3.10/logging/__init__.py", line 1084, in flush
    self.stream.flush()
OSError: [Errno 5] Input/output error
Call stack:
  File "/afs/crc.nd.edu/user/p/psoga/benchmarking-gnns/main_SBMs_node_classification.py", line 382, in <module>
    net_params['in_dim'] = torch.unique(dataset.train[0][0].ndata['feat'],dim=0).size(0) # node_dim (feat is an integer)
  File "/afs/crc.nd.edu/user/p/psoga/benchmarking-gnns/main_SBMs_node_classification.py", line 380, in main
    dataset.test.spatial_pos_lists = []
  File "/afs/crc.nd.edu/user/p/psoga/benchmarking-gnns/main_SBMs_node_classification.py", line 231, in train_val_pipeline
    # writer.add_scalar('train/_loss', epoch_train_loss, epoch)
Message: '\tTime: 139.82s, LR: 0.00000, Train Loss: 0.3531, Train Acc: 84.2067,\n                            Val Loss: 0.3494, Val Acc: 84.4365, Test Acc: 84.4902'
Arguments: ()
--- Logging error ---
Traceback (most recent call last):
  File "/afs/crc.nd.edu/user/p/psoga/.conda/envs/gnn/lib/python3.10/logging/__init__.py", line 1104, in emit
    self.flush()
  File "/afs/crc.nd.edu/user/p/psoga/.conda/envs/gnn/lib/python3.10/logging/__init__.py", line 1084, in flush
    self.stream.flush()
OSError: [Errno 5] Input/output error
Call stack:
  File "/afs/crc.nd.edu/user/p/psoga/benchmarking-gnns/main_SBMs_node_classification.py", line 382, in <module>
    net_params['in_dim'] = torch.unique(dataset.train[0][0].ndata['feat'],dim=0).size(0) # node_dim (feat is an integer)
  File "/afs/crc.nd.edu/user/p/psoga/benchmarking-gnns/main_SBMs_node_classification.py", line 380, in main
    dataset.test.spatial_pos_lists = []
  File "/afs/crc.nd.edu/user/p/psoga/benchmarking-gnns/main_SBMs_node_classification.py", line 189, in train_val_pipeline
    else:
Message: 'Epoch 219/1000'
Arguments: ()
--- Logging error ---
Traceback (most recent call last):
  File "/afs/crc.nd.edu/user/p/psoga/.conda/envs/gnn/lib/python3.10/logging/__init__.py", line 1104, in emit
    self.flush()
  File "/afs/crc.nd.edu/user/p/psoga/.conda/envs/gnn/lib/python3.10/logging/__init__.py", line 1084, in flush
    self.stream.flush()
OSError: [Errno 5] Input/output error
Call stack:
  File "/afs/crc.nd.edu/user/p/psoga/benchmarking-gnns/main_SBMs_node_classification.py", line 382, in <module>
    net_params['in_dim'] = torch.unique(dataset.train[0][0].ndata['feat'],dim=0).size(0) # node_dim (feat is an integer)
  File "/afs/crc.nd.edu/user/p/psoga/benchmarking-gnns/main_SBMs_node_classification.py", line 380, in main
    dataset.test.spatial_pos_lists = []
  File "/afs/crc.nd.edu/user/p/psoga/benchmarking-gnns/main_SBMs_node_classification.py", line 231, in train_val_pipeline
    # writer.add_scalar('train/_loss', epoch_train_loss, epoch)
Message: '\tTime: 139.89s, LR: 0.00000, Train Loss: 0.3529, Train Acc: 84.1995,\n                            Val Loss: 0.3500, Val Acc: 84.3561, Test Acc: 84.3820'
Arguments: ()
--- Logging error ---
Traceback (most recent call last):
  File "/afs/crc.nd.edu/user/p/psoga/.conda/envs/gnn/lib/python3.10/logging/__init__.py", line 1104, in emit
    self.flush()
  File "/afs/crc.nd.edu/user/p/psoga/.conda/envs/gnn/lib/python3.10/logging/__init__.py", line 1084, in flush
    self.stream.flush()
OSError: [Errno 5] Input/output error
Call stack:
  File "/afs/crc.nd.edu/user/p/psoga/benchmarking-gnns/main_SBMs_node_classification.py", line 382, in <module>
    net_params['in_dim'] = torch.unique(dataset.train[0][0].ndata['feat'],dim=0).size(0) # node_dim (feat is an integer)
  File "/afs/crc.nd.edu/user/p/psoga/benchmarking-gnns/main_SBMs_node_classification.py", line 380, in main
    dataset.test.spatial_pos_lists = []
  File "/afs/crc.nd.edu/user/p/psoga/benchmarking-gnns/main_SBMs_node_classification.py", line 189, in train_val_pipeline
    else:
Message: 'Epoch 220/1000'
Arguments: ()
--- Logging error ---
Traceback (most recent call last):
  File "/afs/crc.nd.edu/user/p/psoga/.conda/envs/gnn/lib/python3.10/logging/__init__.py", line 1104, in emit
    self.flush()
  File "/afs/crc.nd.edu/user/p/psoga/.conda/envs/gnn/lib/python3.10/logging/__init__.py", line 1084, in flush
    self.stream.flush()
OSError: [Errno 5] Input/output error
Call stack:
  File "/afs/crc.nd.edu/user/p/psoga/benchmarking-gnns/main_SBMs_node_classification.py", line 382, in <module>
    net_params['in_dim'] = torch.unique(dataset.train[0][0].ndata['feat'],dim=0).size(0) # node_dim (feat is an integer)
  File "/afs/crc.nd.edu/user/p/psoga/benchmarking-gnns/main_SBMs_node_classification.py", line 380, in main
    dataset.test.spatial_pos_lists = []
  File "/afs/crc.nd.edu/user/p/psoga/benchmarking-gnns/main_SBMs_node_classification.py", line 231, in train_val_pipeline
    # writer.add_scalar('train/_loss', epoch_train_loss, epoch)
Message: '\tTime: 140.02s, LR: 0.00000, Train Loss: 0.3526, Train Acc: 84.2520,\n                            Val Loss: 0.3500, Val Acc: 84.3609, Test Acc: 84.3635'
Arguments: ()
--- Logging error ---
Traceback (most recent call last):
  File "/afs/crc.nd.edu/user/p/psoga/.conda/envs/gnn/lib/python3.10/logging/__init__.py", line 1104, in emit
    self.flush()
  File "/afs/crc.nd.edu/user/p/psoga/.conda/envs/gnn/lib/python3.10/logging/__init__.py", line 1084, in flush
    self.stream.flush()
OSError: [Errno 5] Input/output error
Call stack:
  File "/afs/crc.nd.edu/user/p/psoga/benchmarking-gnns/main_SBMs_node_classification.py", line 382, in <module>
    net_params['in_dim'] = torch.unique(dataset.train[0][0].ndata['feat'],dim=0).size(0) # node_dim (feat is an integer)
  File "/afs/crc.nd.edu/user/p/psoga/benchmarking-gnns/main_SBMs_node_classification.py", line 380, in main
    dataset.test.spatial_pos_lists = []
  File "/afs/crc.nd.edu/user/p/psoga/benchmarking-gnns/main_SBMs_node_classification.py", line 189, in train_val_pipeline
    else:
Message: 'Epoch 221/1000'
Arguments: ()
--- Logging error ---
Traceback (most recent call last):
  File "/afs/crc.nd.edu/user/p/psoga/.conda/envs/gnn/lib/python3.10/logging/__init__.py", line 1104, in emit
    self.flush()
  File "/afs/crc.nd.edu/user/p/psoga/.conda/envs/gnn/lib/python3.10/logging/__init__.py", line 1084, in flush
    self.stream.flush()
OSError: [Errno 5] Input/output error
Call stack:
  File "/afs/crc.nd.edu/user/p/psoga/benchmarking-gnns/main_SBMs_node_classification.py", line 382, in <module>
    net_params['in_dim'] = torch.unique(dataset.train[0][0].ndata['feat'],dim=0).size(0) # node_dim (feat is an integer)
  File "/afs/crc.nd.edu/user/p/psoga/benchmarking-gnns/main_SBMs_node_classification.py", line 380, in main
    dataset.test.spatial_pos_lists = []
  File "/afs/crc.nd.edu/user/p/psoga/benchmarking-gnns/main_SBMs_node_classification.py", line 231, in train_val_pipeline
    # writer.add_scalar('train/_loss', epoch_train_loss, epoch)
Message: '\tTime: 139.99s, LR: 0.00000, Train Loss: 0.3526, Train Acc: 84.2525,\n                            Val Loss: 0.3506, Val Acc: 84.3616, Test Acc: 84.4077'
Arguments: ()
--- Logging error ---
Traceback (most recent call last):
  File "/afs/crc.nd.edu/user/p/psoga/.conda/envs/gnn/lib/python3.10/logging/__init__.py", line 1104, in emit
    self.flush()
  File "/afs/crc.nd.edu/user/p/psoga/.conda/envs/gnn/lib/python3.10/logging/__init__.py", line 1084, in flush
    self.stream.flush()
OSError: [Errno 5] Input/output error
Call stack:
  File "/afs/crc.nd.edu/user/p/psoga/benchmarking-gnns/main_SBMs_node_classification.py", line 382, in <module>
    net_params['in_dim'] = torch.unique(dataset.train[0][0].ndata['feat'],dim=0).size(0) # node_dim (feat is an integer)
  File "/afs/crc.nd.edu/user/p/psoga/benchmarking-gnns/main_SBMs_node_classification.py", line 380, in main
    dataset.test.spatial_pos_lists = []
  File "/afs/crc.nd.edu/user/p/psoga/benchmarking-gnns/main_SBMs_node_classification.py", line 189, in train_val_pipeline
    else:
Message: 'Epoch 222/1000'
Arguments: ()
--- Logging error ---
Traceback (most recent call last):
  File "/afs/crc.nd.edu/user/p/psoga/.conda/envs/gnn/lib/python3.10/logging/__init__.py", line 1104, in emit
    self.flush()
  File "/afs/crc.nd.edu/user/p/psoga/.conda/envs/gnn/lib/python3.10/logging/__init__.py", line 1084, in flush
    self.stream.flush()
OSError: [Errno 5] Input/output error
Call stack:
  File "/afs/crc.nd.edu/user/p/psoga/benchmarking-gnns/main_SBMs_node_classification.py", line 382, in <module>
    net_params['in_dim'] = torch.unique(dataset.train[0][0].ndata['feat'],dim=0).size(0) # node_dim (feat is an integer)
  File "/afs/crc.nd.edu/user/p/psoga/benchmarking-gnns/main_SBMs_node_classification.py", line 380, in main
    dataset.test.spatial_pos_lists = []
  File "/afs/crc.nd.edu/user/p/psoga/benchmarking-gnns/main_SBMs_node_classification.py", line 231, in train_val_pipeline
    # writer.add_scalar('train/_loss', epoch_train_loss, epoch)
Message: '\tTime: 140.06s, LR: 0.00000, Train Loss: 0.3529, Train Acc: 84.2185,\n                            Val Loss: 0.3492, Val Acc: 84.3779, Test Acc: 84.4842'
Arguments: ()
--- Logging error ---
Traceback (most recent call last):
  File "/afs/crc.nd.edu/user/p/psoga/.conda/envs/gnn/lib/python3.10/logging/__init__.py", line 1104, in emit
    self.flush()
  File "/afs/crc.nd.edu/user/p/psoga/.conda/envs/gnn/lib/python3.10/logging/__init__.py", line 1084, in flush
    self.stream.flush()
OSError: [Errno 5] Input/output error
Call stack:
  File "/afs/crc.nd.edu/user/p/psoga/benchmarking-gnns/main_SBMs_node_classification.py", line 382, in <module>
    net_params['in_dim'] = torch.unique(dataset.train[0][0].ndata['feat'],dim=0).size(0) # node_dim (feat is an integer)
  File "/afs/crc.nd.edu/user/p/psoga/benchmarking-gnns/main_SBMs_node_classification.py", line 380, in main
    dataset.test.spatial_pos_lists = []
  File "/afs/crc.nd.edu/user/p/psoga/benchmarking-gnns/main_SBMs_node_classification.py", line 189, in train_val_pipeline
    else:
Message: 'Epoch 223/1000'
Arguments: ()
--- Logging error ---
Traceback (most recent call last):
  File "/afs/crc.nd.edu/user/p/psoga/.conda/envs/gnn/lib/python3.10/logging/__init__.py", line 1104, in emit
    self.flush()
  File "/afs/crc.nd.edu/user/p/psoga/.conda/envs/gnn/lib/python3.10/logging/__init__.py", line 1084, in flush
    self.stream.flush()
OSError: [Errno 5] Input/output error
Call stack:
  File "/afs/crc.nd.edu/user/p/psoga/benchmarking-gnns/main_SBMs_node_classification.py", line 382, in <module>
    net_params['in_dim'] = torch.unique(dataset.train[0][0].ndata['feat'],dim=0).size(0) # node_dim (feat is an integer)
  File "/afs/crc.nd.edu/user/p/psoga/benchmarking-gnns/main_SBMs_node_classification.py", line 380, in main
    dataset.test.spatial_pos_lists = []
  File "/afs/crc.nd.edu/user/p/psoga/benchmarking-gnns/main_SBMs_node_classification.py", line 231, in train_val_pipeline
    # writer.add_scalar('train/_loss', epoch_train_loss, epoch)
Message: '\tTime: 139.62s, LR: 0.00000, Train Loss: 0.3528, Train Acc: 84.2417,\n                            Val Loss: 0.3497, Val Acc: 84.3372, Test Acc: 84.4655'
Arguments: ()
--- Logging error ---
Traceback (most recent call last):
  File "/afs/crc.nd.edu/user/p/psoga/.conda/envs/gnn/lib/python3.10/logging/__init__.py", line 1104, in emit
    self.flush()
  File "/afs/crc.nd.edu/user/p/psoga/.conda/envs/gnn/lib/python3.10/logging/__init__.py", line 1084, in flush
    self.stream.flush()
OSError: [Errno 5] Input/output error
Call stack:
  File "/afs/crc.nd.edu/user/p/psoga/benchmarking-gnns/main_SBMs_node_classification.py", line 382, in <module>
    net_params['in_dim'] = torch.unique(dataset.train[0][0].ndata['feat'],dim=0).size(0) # node_dim (feat is an integer)
  File "/afs/crc.nd.edu/user/p/psoga/benchmarking-gnns/main_SBMs_node_classification.py", line 380, in main
    dataset.test.spatial_pos_lists = []
  File "/afs/crc.nd.edu/user/p/psoga/benchmarking-gnns/main_SBMs_node_classification.py", line 189, in train_val_pipeline
    else:
Message: 'Epoch 224/1000'
Arguments: ()
--- Logging error ---
Traceback (most recent call last):
  File "/afs/crc.nd.edu/user/p/psoga/.conda/envs/gnn/lib/python3.10/logging/__init__.py", line 1104, in emit
    self.flush()
  File "/afs/crc.nd.edu/user/p/psoga/.conda/envs/gnn/lib/python3.10/logging/__init__.py", line 1084, in flush
    self.stream.flush()
OSError: [Errno 5] Input/output error
Call stack:
  File "/afs/crc.nd.edu/user/p/psoga/benchmarking-gnns/main_SBMs_node_classification.py", line 382, in <module>
    net_params['in_dim'] = torch.unique(dataset.train[0][0].ndata['feat'],dim=0).size(0) # node_dim (feat is an integer)
  File "/afs/crc.nd.edu/user/p/psoga/benchmarking-gnns/main_SBMs_node_classification.py", line 380, in main
    dataset.test.spatial_pos_lists = []
  File "/afs/crc.nd.edu/user/p/psoga/benchmarking-gnns/main_SBMs_node_classification.py", line 231, in train_val_pipeline
    # writer.add_scalar('train/_loss', epoch_train_loss, epoch)
Message: '\tTime: 137.62s, LR: 0.00000, Train Loss: 0.3528, Train Acc: 84.2295,\n                            Val Loss: 0.3496, Val Acc: 84.3270, Test Acc: 84.4491'
Arguments: ()
--- Logging error ---
Traceback (most recent call last):
  File "/afs/crc.nd.edu/user/p/psoga/.conda/envs/gnn/lib/python3.10/logging/__init__.py", line 1104, in emit
    self.flush()
  File "/afs/crc.nd.edu/user/p/psoga/.conda/envs/gnn/lib/python3.10/logging/__init__.py", line 1084, in flush
    self.stream.flush()
OSError: [Errno 5] Input/output error
Call stack:
  File "/afs/crc.nd.edu/user/p/psoga/benchmarking-gnns/main_SBMs_node_classification.py", line 382, in <module>
    net_params['in_dim'] = torch.unique(dataset.train[0][0].ndata['feat'],dim=0).size(0) # node_dim (feat is an integer)
  File "/afs/crc.nd.edu/user/p/psoga/benchmarking-gnns/main_SBMs_node_classification.py", line 380, in main
    dataset.test.spatial_pos_lists = []
  File "/afs/crc.nd.edu/user/p/psoga/benchmarking-gnns/main_SBMs_node_classification.py", line 189, in train_val_pipeline
    else:
Message: 'Epoch 225/1000'
Arguments: ()
--- Logging error ---
Traceback (most recent call last):
  File "/afs/crc.nd.edu/user/p/psoga/.conda/envs/gnn/lib/python3.10/logging/__init__.py", line 1104, in emit
    self.flush()
  File "/afs/crc.nd.edu/user/p/psoga/.conda/envs/gnn/lib/python3.10/logging/__init__.py", line 1084, in flush
    self.stream.flush()
OSError: [Errno 5] Input/output error
Call stack:
  File "/afs/crc.nd.edu/user/p/psoga/benchmarking-gnns/main_SBMs_node_classification.py", line 382, in <module>
    net_params['in_dim'] = torch.unique(dataset.train[0][0].ndata['feat'],dim=0).size(0) # node_dim (feat is an integer)
  File "/afs/crc.nd.edu/user/p/psoga/benchmarking-gnns/main_SBMs_node_classification.py", line 380, in main
    dataset.test.spatial_pos_lists = []
  File "/afs/crc.nd.edu/user/p/psoga/benchmarking-gnns/main_SBMs_node_classification.py", line 231, in train_val_pipeline
    # writer.add_scalar('train/_loss', epoch_train_loss, epoch)
Message: '\tTime: 137.40s, LR: 0.00000, Train Loss: 0.3522, Train Acc: 84.2704,\n                            Val Loss: 0.3496, Val Acc: 84.3273, Test Acc: 84.4918'
Arguments: ()
--- Logging error ---
Traceback (most recent call last):
  File "/afs/crc.nd.edu/user/p/psoga/.conda/envs/gnn/lib/python3.10/logging/__init__.py", line 1104, in emit
    self.flush()
  File "/afs/crc.nd.edu/user/p/psoga/.conda/envs/gnn/lib/python3.10/logging/__init__.py", line 1084, in flush
    self.stream.flush()
OSError: [Errno 5] Input/output error
Call stack:
  File "/afs/crc.nd.edu/user/p/psoga/benchmarking-gnns/main_SBMs_node_classification.py", line 382, in <module>
    net_params['in_dim'] = torch.unique(dataset.train[0][0].ndata['feat'],dim=0).size(0) # node_dim (feat is an integer)
  File "/afs/crc.nd.edu/user/p/psoga/benchmarking-gnns/main_SBMs_node_classification.py", line 380, in main
    dataset.test.spatial_pos_lists = []
  File "/afs/crc.nd.edu/user/p/psoga/benchmarking-gnns/main_SBMs_node_classification.py", line 189, in train_val_pipeline
    else:
Message: 'Epoch 226/1000'
Arguments: ()
--- Logging error ---
Traceback (most recent call last):
  File "/afs/crc.nd.edu/user/p/psoga/.conda/envs/gnn/lib/python3.10/logging/__init__.py", line 1104, in emit
    self.flush()
  File "/afs/crc.nd.edu/user/p/psoga/.conda/envs/gnn/lib/python3.10/logging/__init__.py", line 1084, in flush
    self.stream.flush()
OSError: [Errno 5] Input/output error
Call stack:
  File "/afs/crc.nd.edu/user/p/psoga/benchmarking-gnns/main_SBMs_node_classification.py", line 382, in <module>
    net_params['in_dim'] = torch.unique(dataset.train[0][0].ndata['feat'],dim=0).size(0) # node_dim (feat is an integer)
  File "/afs/crc.nd.edu/user/p/psoga/benchmarking-gnns/main_SBMs_node_classification.py", line 380, in main
    dataset.test.spatial_pos_lists = []
  File "/afs/crc.nd.edu/user/p/psoga/benchmarking-gnns/main_SBMs_node_classification.py", line 231, in train_val_pipeline
    # writer.add_scalar('train/_loss', epoch_train_loss, epoch)
Message: '\tTime: 136.86s, LR: 0.00000, Train Loss: 0.3522, Train Acc: 84.2783,\n                            Val Loss: 0.3505, Val Acc: 84.3347, Test Acc: 84.4862'
Arguments: ()
--- Logging error ---
Traceback (most recent call last):
  File "/afs/crc.nd.edu/user/p/psoga/.conda/envs/gnn/lib/python3.10/logging/__init__.py", line 1104, in emit
    self.flush()
  File "/afs/crc.nd.edu/user/p/psoga/.conda/envs/gnn/lib/python3.10/logging/__init__.py", line 1084, in flush
    self.stream.flush()
OSError: [Errno 5] Input/output error
Call stack:
  File "/afs/crc.nd.edu/user/p/psoga/benchmarking-gnns/main_SBMs_node_classification.py", line 382, in <module>
    net_params['in_dim'] = torch.unique(dataset.train[0][0].ndata['feat'],dim=0).size(0) # node_dim (feat is an integer)
  File "/afs/crc.nd.edu/user/p/psoga/benchmarking-gnns/main_SBMs_node_classification.py", line 380, in main
    dataset.test.spatial_pos_lists = []
  File "/afs/crc.nd.edu/user/p/psoga/benchmarking-gnns/main_SBMs_node_classification.py", line 189, in train_val_pipeline
    else:
Message: 'Epoch 227/1000'
Arguments: ()
--- Logging error ---
Traceback (most recent call last):
  File "/afs/crc.nd.edu/user/p/psoga/.conda/envs/gnn/lib/python3.10/logging/__init__.py", line 1104, in emit
    self.flush()
  File "/afs/crc.nd.edu/user/p/psoga/.conda/envs/gnn/lib/python3.10/logging/__init__.py", line 1084, in flush
    self.stream.flush()
OSError: [Errno 5] Input/output error
Call stack:
  File "/afs/crc.nd.edu/user/p/psoga/benchmarking-gnns/main_SBMs_node_classification.py", line 382, in <module>
    net_params['in_dim'] = torch.unique(dataset.train[0][0].ndata['feat'],dim=0).size(0) # node_dim (feat is an integer)
  File "/afs/crc.nd.edu/user/p/psoga/benchmarking-gnns/main_SBMs_node_classification.py", line 380, in main
    dataset.test.spatial_pos_lists = []
  File "/afs/crc.nd.edu/user/p/psoga/benchmarking-gnns/main_SBMs_node_classification.py", line 231, in train_val_pipeline
    # writer.add_scalar('train/_loss', epoch_train_loss, epoch)
Message: '\tTime: 136.90s, LR: 0.00000, Train Loss: 0.3527, Train Acc: 84.2404,\n                            Val Loss: 0.3498, Val Acc: 84.3672, Test Acc: 84.5018'
Arguments: ()
--- Logging error ---
Traceback (most recent call last):
  File "/afs/crc.nd.edu/user/p/psoga/.conda/envs/gnn/lib/python3.10/logging/__init__.py", line 1104, in emit
    self.flush()
  File "/afs/crc.nd.edu/user/p/psoga/.conda/envs/gnn/lib/python3.10/logging/__init__.py", line 1084, in flush
    self.stream.flush()
OSError: [Errno 5] Input/output error
Call stack:
  File "/afs/crc.nd.edu/user/p/psoga/benchmarking-gnns/main_SBMs_node_classification.py", line 382, in <module>
    net_params['in_dim'] = torch.unique(dataset.train[0][0].ndata['feat'],dim=0).size(0) # node_dim (feat is an integer)
  File "/afs/crc.nd.edu/user/p/psoga/benchmarking-gnns/main_SBMs_node_classification.py", line 380, in main
    dataset.test.spatial_pos_lists = []
  File "/afs/crc.nd.edu/user/p/psoga/benchmarking-gnns/main_SBMs_node_classification.py", line 189, in train_val_pipeline
    else:
Message: 'Epoch 228/1000'
Arguments: ()
--- Logging error ---
Traceback (most recent call last):
  File "/afs/crc.nd.edu/user/p/psoga/.conda/envs/gnn/lib/python3.10/logging/__init__.py", line 1104, in emit
    self.flush()
  File "/afs/crc.nd.edu/user/p/psoga/.conda/envs/gnn/lib/python3.10/logging/__init__.py", line 1084, in flush
    self.stream.flush()
OSError: [Errno 5] Input/output error
Call stack:
  File "/afs/crc.nd.edu/user/p/psoga/benchmarking-gnns/main_SBMs_node_classification.py", line 382, in <module>
    net_params['in_dim'] = torch.unique(dataset.train[0][0].ndata['feat'],dim=0).size(0) # node_dim (feat is an integer)
  File "/afs/crc.nd.edu/user/p/psoga/benchmarking-gnns/main_SBMs_node_classification.py", line 380, in main
    dataset.test.spatial_pos_lists = []
  File "/afs/crc.nd.edu/user/p/psoga/benchmarking-gnns/main_SBMs_node_classification.py", line 231, in train_val_pipeline
    # writer.add_scalar('train/_loss', epoch_train_loss, epoch)
Message: '\tTime: 136.89s, LR: 0.00000, Train Loss: 0.3524, Train Acc: 84.2724,\n                            Val Loss: 0.3498, Val Acc: 84.3804, Test Acc: 84.4771'
Arguments: ()
--- Logging error ---
Traceback (most recent call last):
  File "/afs/crc.nd.edu/user/p/psoga/.conda/envs/gnn/lib/python3.10/logging/__init__.py", line 1104, in emit
    self.flush()
  File "/afs/crc.nd.edu/user/p/psoga/.conda/envs/gnn/lib/python3.10/logging/__init__.py", line 1084, in flush
    self.stream.flush()
OSError: [Errno 5] Input/output error
Call stack:
  File "/afs/crc.nd.edu/user/p/psoga/benchmarking-gnns/main_SBMs_node_classification.py", line 382, in <module>
    net_params['in_dim'] = torch.unique(dataset.train[0][0].ndata['feat'],dim=0).size(0) # node_dim (feat is an integer)
  File "/afs/crc.nd.edu/user/p/psoga/benchmarking-gnns/main_SBMs_node_classification.py", line 380, in main
    dataset.test.spatial_pos_lists = []
  File "/afs/crc.nd.edu/user/p/psoga/benchmarking-gnns/main_SBMs_node_classification.py", line 189, in train_val_pipeline
    else:
Message: 'Epoch 229/1000'
Arguments: ()
--- Logging error ---
Traceback (most recent call last):
  File "/afs/crc.nd.edu/user/p/psoga/.conda/envs/gnn/lib/python3.10/logging/__init__.py", line 1104, in emit
    self.flush()
  File "/afs/crc.nd.edu/user/p/psoga/.conda/envs/gnn/lib/python3.10/logging/__init__.py", line 1084, in flush
    self.stream.flush()
OSError: [Errno 5] Input/output error
Call stack:
  File "/afs/crc.nd.edu/user/p/psoga/benchmarking-gnns/main_SBMs_node_classification.py", line 382, in <module>
    net_params['in_dim'] = torch.unique(dataset.train[0][0].ndata['feat'],dim=0).size(0) # node_dim (feat is an integer)
  File "/afs/crc.nd.edu/user/p/psoga/benchmarking-gnns/main_SBMs_node_classification.py", line 380, in main
    dataset.test.spatial_pos_lists = []
  File "/afs/crc.nd.edu/user/p/psoga/benchmarking-gnns/main_SBMs_node_classification.py", line 231, in train_val_pipeline
    # writer.add_scalar('train/_loss', epoch_train_loss, epoch)
Message: '\tTime: 136.93s, LR: 0.00000, Train Loss: 0.3519, Train Acc: 84.2898,\n                            Val Loss: 0.3505, Val Acc: 84.3785, Test Acc: 84.5146'
Arguments: ()
--- Logging error ---
Traceback (most recent call last):
  File "/afs/crc.nd.edu/user/p/psoga/.conda/envs/gnn/lib/python3.10/logging/__init__.py", line 1104, in emit
    self.flush()
  File "/afs/crc.nd.edu/user/p/psoga/.conda/envs/gnn/lib/python3.10/logging/__init__.py", line 1084, in flush
    self.stream.flush()
OSError: [Errno 5] Input/output error
Call stack:
  File "/afs/crc.nd.edu/user/p/psoga/benchmarking-gnns/main_SBMs_node_classification.py", line 382, in <module>
    net_params['in_dim'] = torch.unique(dataset.train[0][0].ndata['feat'],dim=0).size(0) # node_dim (feat is an integer)
  File "/afs/crc.nd.edu/user/p/psoga/benchmarking-gnns/main_SBMs_node_classification.py", line 380, in main
    dataset.test.spatial_pos_lists = []
  File "/afs/crc.nd.edu/user/p/psoga/benchmarking-gnns/main_SBMs_node_classification.py", line 189, in train_val_pipeline
    else:
Message: 'Epoch 230/1000'
Arguments: ()
--- Logging error ---
Traceback (most recent call last):
  File "/afs/crc.nd.edu/user/p/psoga/.conda/envs/gnn/lib/python3.10/logging/__init__.py", line 1104, in emit
    self.flush()
  File "/afs/crc.nd.edu/user/p/psoga/.conda/envs/gnn/lib/python3.10/logging/__init__.py", line 1084, in flush
    self.stream.flush()
OSError: [Errno 5] Input/output error
Call stack:
  File "/afs/crc.nd.edu/user/p/psoga/benchmarking-gnns/main_SBMs_node_classification.py", line 382, in <module>
    net_params['in_dim'] = torch.unique(dataset.train[0][0].ndata['feat'],dim=0).size(0) # node_dim (feat is an integer)
  File "/afs/crc.nd.edu/user/p/psoga/benchmarking-gnns/main_SBMs_node_classification.py", line 380, in main
    dataset.test.spatial_pos_lists = []
  File "/afs/crc.nd.edu/user/p/psoga/benchmarking-gnns/main_SBMs_node_classification.py", line 231, in train_val_pipeline
    # writer.add_scalar('train/_loss', epoch_train_loss, epoch)
Message: '\tTime: 137.19s, LR: 0.00000, Train Loss: 0.3532, Train Acc: 84.2088,\n                            Val Loss: 0.3491, Val Acc: 84.4411, Test Acc: 84.5182'
Arguments: ()
--- Logging error ---
Traceback (most recent call last):
  File "/afs/crc.nd.edu/user/p/psoga/.conda/envs/gnn/lib/python3.10/logging/__init__.py", line 1104, in emit
    self.flush()
  File "/afs/crc.nd.edu/user/p/psoga/.conda/envs/gnn/lib/python3.10/logging/__init__.py", line 1084, in flush
    self.stream.flush()
OSError: [Errno 5] Input/output error
Call stack:
  File "/afs/crc.nd.edu/user/p/psoga/benchmarking-gnns/main_SBMs_node_classification.py", line 382, in <module>
    net_params['in_dim'] = torch.unique(dataset.train[0][0].ndata['feat'],dim=0).size(0) # node_dim (feat is an integer)
  File "/afs/crc.nd.edu/user/p/psoga/benchmarking-gnns/main_SBMs_node_classification.py", line 380, in main
    dataset.test.spatial_pos_lists = []
  File "/afs/crc.nd.edu/user/p/psoga/benchmarking-gnns/main_SBMs_node_classification.py", line 189, in train_val_pipeline
    else:
Message: 'Epoch 231/1000'
Arguments: ()
--- Logging error ---
Traceback (most recent call last):
  File "/afs/crc.nd.edu/user/p/psoga/.conda/envs/gnn/lib/python3.10/logging/__init__.py", line 1104, in emit
    self.flush()
  File "/afs/crc.nd.edu/user/p/psoga/.conda/envs/gnn/lib/python3.10/logging/__init__.py", line 1084, in flush
    self.stream.flush()
OSError: [Errno 5] Input/output error
Call stack:
  File "/afs/crc.nd.edu/user/p/psoga/benchmarking-gnns/main_SBMs_node_classification.py", line 382, in <module>
    net_params['in_dim'] = torch.unique(dataset.train[0][0].ndata['feat'],dim=0).size(0) # node_dim (feat is an integer)
  File "/afs/crc.nd.edu/user/p/psoga/benchmarking-gnns/main_SBMs_node_classification.py", line 380, in main
    dataset.test.spatial_pos_lists = []
  File "/afs/crc.nd.edu/user/p/psoga/benchmarking-gnns/main_SBMs_node_classification.py", line 231, in train_val_pipeline
    # writer.add_scalar('train/_loss', epoch_train_loss, epoch)
Message: '\tTime: 136.87s, LR: 0.00000, Train Loss: 0.3525, Train Acc: 84.2741,\n                            Val Loss: 0.3500, Val Acc: 84.3490, Test Acc: 84.4137'
Arguments: ()
--- Logging error ---
Traceback (most recent call last):
  File "/afs/crc.nd.edu/user/p/psoga/.conda/envs/gnn/lib/python3.10/logging/__init__.py", line 1104, in emit
    self.flush()
  File "/afs/crc.nd.edu/user/p/psoga/.conda/envs/gnn/lib/python3.10/logging/__init__.py", line 1084, in flush
    self.stream.flush()
OSError: [Errno 5] Input/output error
Call stack:
  File "/afs/crc.nd.edu/user/p/psoga/benchmarking-gnns/main_SBMs_node_classification.py", line 382, in <module>
    net_params['in_dim'] = torch.unique(dataset.train[0][0].ndata['feat'],dim=0).size(0) # node_dim (feat is an integer)
  File "/afs/crc.nd.edu/user/p/psoga/benchmarking-gnns/main_SBMs_node_classification.py", line 380, in main
    dataset.test.spatial_pos_lists = []
  File "/afs/crc.nd.edu/user/p/psoga/benchmarking-gnns/main_SBMs_node_classification.py", line 189, in train_val_pipeline
    else:
Message: 'Epoch 232/1000'
Arguments: ()
--- Logging error ---
Traceback (most recent call last):
  File "/afs/crc.nd.edu/user/p/psoga/.conda/envs/gnn/lib/python3.10/logging/__init__.py", line 1104, in emit
    self.flush()
  File "/afs/crc.nd.edu/user/p/psoga/.conda/envs/gnn/lib/python3.10/logging/__init__.py", line 1084, in flush
    self.stream.flush()
OSError: [Errno 5] Input/output error
Call stack:
  File "/afs/crc.nd.edu/user/p/psoga/benchmarking-gnns/main_SBMs_node_classification.py", line 382, in <module>
    net_params['in_dim'] = torch.unique(dataset.train[0][0].ndata['feat'],dim=0).size(0) # node_dim (feat is an integer)
  File "/afs/crc.nd.edu/user/p/psoga/benchmarking-gnns/main_SBMs_node_classification.py", line 380, in main
    dataset.test.spatial_pos_lists = []
  File "/afs/crc.nd.edu/user/p/psoga/benchmarking-gnns/main_SBMs_node_classification.py", line 231, in train_val_pipeline
    # writer.add_scalar('train/_loss', epoch_train_loss, epoch)
Message: '\tTime: 136.63s, LR: 0.00000, Train Loss: 0.3525, Train Acc: 84.2645,\n                            Val Loss: 0.3496, Val Acc: 84.3449, Test Acc: 84.5033'
Arguments: ()
--- Logging error ---
Traceback (most recent call last):
  File "/afs/crc.nd.edu/user/p/psoga/.conda/envs/gnn/lib/python3.10/logging/__init__.py", line 1104, in emit
    self.flush()
  File "/afs/crc.nd.edu/user/p/psoga/.conda/envs/gnn/lib/python3.10/logging/__init__.py", line 1084, in flush
    self.stream.flush()
OSError: [Errno 5] Input/output error
Call stack:
  File "/afs/crc.nd.edu/user/p/psoga/benchmarking-gnns/main_SBMs_node_classification.py", line 382, in <module>
    net_params['in_dim'] = torch.unique(dataset.train[0][0].ndata['feat'],dim=0).size(0) # node_dim (feat is an integer)
  File "/afs/crc.nd.edu/user/p/psoga/benchmarking-gnns/main_SBMs_node_classification.py", line 380, in main
    dataset.test.spatial_pos_lists = []
  File "/afs/crc.nd.edu/user/p/psoga/benchmarking-gnns/main_SBMs_node_classification.py", line 189, in train_val_pipeline
    else:
Message: 'Epoch 233/1000'
Arguments: ()
--- Logging error ---
Traceback (most recent call last):
  File "/afs/crc.nd.edu/user/p/psoga/.conda/envs/gnn/lib/python3.10/logging/__init__.py", line 1104, in emit
    self.flush()
  File "/afs/crc.nd.edu/user/p/psoga/.conda/envs/gnn/lib/python3.10/logging/__init__.py", line 1084, in flush
    self.stream.flush()
OSError: [Errno 5] Input/output error
Call stack:
  File "/afs/crc.nd.edu/user/p/psoga/benchmarking-gnns/main_SBMs_node_classification.py", line 382, in <module>
    net_params['in_dim'] = torch.unique(dataset.train[0][0].ndata['feat'],dim=0).size(0) # node_dim (feat is an integer)
  File "/afs/crc.nd.edu/user/p/psoga/benchmarking-gnns/main_SBMs_node_classification.py", line 380, in main
    dataset.test.spatial_pos_lists = []
  File "/afs/crc.nd.edu/user/p/psoga/benchmarking-gnns/main_SBMs_node_classification.py", line 231, in train_val_pipeline
    # writer.add_scalar('train/_loss', epoch_train_loss, epoch)
Message: '\tTime: 137.14s, LR: 0.00000, Train Loss: 0.3525, Train Acc: 84.2368,\n                            Val Loss: 0.3502, Val Acc: 84.3448, Test Acc: 84.4758'
Arguments: ()
--- Logging error ---
Traceback (most recent call last):
  File "/afs/crc.nd.edu/user/p/psoga/.conda/envs/gnn/lib/python3.10/logging/__init__.py", line 1104, in emit
    self.flush()
  File "/afs/crc.nd.edu/user/p/psoga/.conda/envs/gnn/lib/python3.10/logging/__init__.py", line 1084, in flush
    self.stream.flush()
OSError: [Errno 5] Input/output error
Call stack:
  File "/afs/crc.nd.edu/user/p/psoga/benchmarking-gnns/main_SBMs_node_classification.py", line 382, in <module>
    net_params['in_dim'] = torch.unique(dataset.train[0][0].ndata['feat'],dim=0).size(0) # node_dim (feat is an integer)
  File "/afs/crc.nd.edu/user/p/psoga/benchmarking-gnns/main_SBMs_node_classification.py", line 380, in main
    dataset.test.spatial_pos_lists = []
  File "/afs/crc.nd.edu/user/p/psoga/benchmarking-gnns/main_SBMs_node_classification.py", line 189, in train_val_pipeline
    else:
Message: 'Epoch 234/1000'
Arguments: ()
--- Logging error ---
Traceback (most recent call last):
  File "/afs/crc.nd.edu/user/p/psoga/.conda/envs/gnn/lib/python3.10/logging/__init__.py", line 1104, in emit
    self.flush()
  File "/afs/crc.nd.edu/user/p/psoga/.conda/envs/gnn/lib/python3.10/logging/__init__.py", line 1084, in flush
    self.stream.flush()
OSError: [Errno 5] Input/output error
Call stack:
  File "/afs/crc.nd.edu/user/p/psoga/benchmarking-gnns/main_SBMs_node_classification.py", line 382, in <module>
    net_params['in_dim'] = torch.unique(dataset.train[0][0].ndata['feat'],dim=0).size(0) # node_dim (feat is an integer)
  File "/afs/crc.nd.edu/user/p/psoga/benchmarking-gnns/main_SBMs_node_classification.py", line 380, in main
    dataset.test.spatial_pos_lists = []
  File "/afs/crc.nd.edu/user/p/psoga/benchmarking-gnns/main_SBMs_node_classification.py", line 231, in train_val_pipeline
    # writer.add_scalar('train/_loss', epoch_train_loss, epoch)
Message: '\tTime: 136.93s, LR: 0.00000, Train Loss: 0.3529, Train Acc: 84.2090,\n                            Val Loss: 0.3490, Val Acc: 84.4535, Test Acc: 84.5268'
Arguments: ()
--- Logging error ---
Traceback (most recent call last):
  File "/afs/crc.nd.edu/user/p/psoga/.conda/envs/gnn/lib/python3.10/logging/__init__.py", line 1104, in emit
    self.flush()
  File "/afs/crc.nd.edu/user/p/psoga/.conda/envs/gnn/lib/python3.10/logging/__init__.py", line 1084, in flush
    self.stream.flush()
OSError: [Errno 5] Input/output error
Call stack:
  File "/afs/crc.nd.edu/user/p/psoga/benchmarking-gnns/main_SBMs_node_classification.py", line 382, in <module>
    net_params['in_dim'] = torch.unique(dataset.train[0][0].ndata['feat'],dim=0).size(0) # node_dim (feat is an integer)
  File "/afs/crc.nd.edu/user/p/psoga/benchmarking-gnns/main_SBMs_node_classification.py", line 380, in main
    dataset.test.spatial_pos_lists = []
  File "/afs/crc.nd.edu/user/p/psoga/benchmarking-gnns/main_SBMs_node_classification.py", line 189, in train_val_pipeline
    else:
Message: 'Epoch 235/1000'
Arguments: ()
--- Logging error ---
Traceback (most recent call last):
  File "/afs/crc.nd.edu/user/p/psoga/.conda/envs/gnn/lib/python3.10/logging/__init__.py", line 1104, in emit
    self.flush()
  File "/afs/crc.nd.edu/user/p/psoga/.conda/envs/gnn/lib/python3.10/logging/__init__.py", line 1084, in flush
    self.stream.flush()
OSError: [Errno 5] Input/output error
Call stack:
  File "/afs/crc.nd.edu/user/p/psoga/benchmarking-gnns/main_SBMs_node_classification.py", line 382, in <module>
    net_params['in_dim'] = torch.unique(dataset.train[0][0].ndata['feat'],dim=0).size(0) # node_dim (feat is an integer)
  File "/afs/crc.nd.edu/user/p/psoga/benchmarking-gnns/main_SBMs_node_classification.py", line 380, in main
    dataset.test.spatial_pos_lists = []
  File "/afs/crc.nd.edu/user/p/psoga/benchmarking-gnns/main_SBMs_node_classification.py", line 231, in train_val_pipeline
    # writer.add_scalar('train/_loss', epoch_train_loss, epoch)
Message: '\tTime: 136.83s, LR: 0.00000, Train Loss: 0.3521, Train Acc: 84.2598,\n                            Val Loss: 0.3500, Val Acc: 84.3892, Test Acc: 84.5689'
Arguments: ()
--- Logging error ---
Traceback (most recent call last):
  File "/afs/crc.nd.edu/user/p/psoga/.conda/envs/gnn/lib/python3.10/logging/__init__.py", line 1104, in emit
    self.flush()
  File "/afs/crc.nd.edu/user/p/psoga/.conda/envs/gnn/lib/python3.10/logging/__init__.py", line 1084, in flush
    self.stream.flush()
OSError: [Errno 5] Input/output error
Call stack:
  File "/afs/crc.nd.edu/user/p/psoga/benchmarking-gnns/main_SBMs_node_classification.py", line 382, in <module>
    net_params['in_dim'] = torch.unique(dataset.train[0][0].ndata['feat'],dim=0).size(0) # node_dim (feat is an integer)
  File "/afs/crc.nd.edu/user/p/psoga/benchmarking-gnns/main_SBMs_node_classification.py", line 380, in main
    dataset.test.spatial_pos_lists = []
  File "/afs/crc.nd.edu/user/p/psoga/benchmarking-gnns/main_SBMs_node_classification.py", line 252, in train_val_pipeline
    # ckpt_dir = os.path.join(root_ckpt_dir, "RUN_")
Message: '\n!! LR SMALLER OR EQUAL TO MIN LR THRESHOLD.'
Arguments: ()
--- Logging error ---
Traceback (most recent call last):
  File "/afs/crc.nd.edu/user/p/psoga/.conda/envs/gnn/lib/python3.10/logging/__init__.py", line 1104, in emit
    self.flush()
  File "/afs/crc.nd.edu/user/p/psoga/.conda/envs/gnn/lib/python3.10/logging/__init__.py", line 1084, in flush
    self.stream.flush()
OSError: [Errno 5] Input/output error
Call stack:
  File "/afs/crc.nd.edu/user/p/psoga/benchmarking-gnns/main_SBMs_node_classification.py", line 382, in <module>
    net_params['in_dim'] = torch.unique(dataset.train[0][0].ndata['feat'],dim=0).size(0) # node_dim (feat is an integer)
  File "/afs/crc.nd.edu/user/p/psoga/benchmarking-gnns/main_SBMs_node_classification.py", line 380, in main
    dataset.test.spatial_pos_lists = []
  File "/afs/crc.nd.edu/user/p/psoga/benchmarking-gnns/main_SBMs_node_classification.py", line 271, in train_val_pipeline
    if time.time()-start0 > params['max_time']*3600:
Message: 'Test Accuracy: 84.5689'
Arguments: ()
--- Logging error ---
Traceback (most recent call last):
  File "/afs/crc.nd.edu/user/p/psoga/.conda/envs/gnn/lib/python3.10/logging/__init__.py", line 1104, in emit
    self.flush()
  File "/afs/crc.nd.edu/user/p/psoga/.conda/envs/gnn/lib/python3.10/logging/__init__.py", line 1084, in flush
    self.stream.flush()
OSError: [Errno 5] Input/output error
Call stack:
  File "/afs/crc.nd.edu/user/p/psoga/benchmarking-gnns/main_SBMs_node_classification.py", line 382, in <module>
    net_params['in_dim'] = torch.unique(dataset.train[0][0].ndata['feat'],dim=0).size(0) # node_dim (feat is an integer)
  File "/afs/crc.nd.edu/user/p/psoga/benchmarking-gnns/main_SBMs_node_classification.py", line 380, in main
    dataset.test.spatial_pos_lists = []
  File "/afs/crc.nd.edu/user/p/psoga/benchmarking-gnns/main_SBMs_node_classification.py", line 272, in train_val_pipeline
    logger.info('-' * 89)
Message: 'Best Test Accuracy: 84.6051'
Arguments: ()
--- Logging error ---
Traceback (most recent call last):
  File "/afs/crc.nd.edu/user/p/psoga/.conda/envs/gnn/lib/python3.10/logging/__init__.py", line 1104, in emit
    self.flush()
  File "/afs/crc.nd.edu/user/p/psoga/.conda/envs/gnn/lib/python3.10/logging/__init__.py", line 1084, in flush
    self.stream.flush()
OSError: [Errno 5] Input/output error
Call stack:
  File "/afs/crc.nd.edu/user/p/psoga/benchmarking-gnns/main_SBMs_node_classification.py", line 382, in <module>
    net_params['in_dim'] = torch.unique(dataset.train[0][0].ndata['feat'],dim=0).size(0) # node_dim (feat is an integer)
  File "/afs/crc.nd.edu/user/p/psoga/benchmarking-gnns/main_SBMs_node_classification.py", line 380, in main
    dataset.test.spatial_pos_lists = []
  File "/afs/crc.nd.edu/user/p/psoga/benchmarking-gnns/main_SBMs_node_classification.py", line 273, in train_val_pipeline
    logger.info("Max_time for training elapsed {:.2f} hours, so stopping".format(params['max_time']))
Message: 'Train Accuracy: 84.3236'
Arguments: ()
--- Logging error ---
Traceback (most recent call last):
  File "/afs/crc.nd.edu/user/p/psoga/.conda/envs/gnn/lib/python3.10/logging/__init__.py", line 1104, in emit
    self.flush()
  File "/afs/crc.nd.edu/user/p/psoga/.conda/envs/gnn/lib/python3.10/logging/__init__.py", line 1084, in flush
    self.stream.flush()
OSError: [Errno 5] Input/output error
Call stack:
  File "/afs/crc.nd.edu/user/p/psoga/benchmarking-gnns/main_SBMs_node_classification.py", line 382, in <module>
    net_params['in_dim'] = torch.unique(dataset.train[0][0].ndata['feat'],dim=0).size(0) # node_dim (feat is an integer)
  File "/afs/crc.nd.edu/user/p/psoga/benchmarking-gnns/main_SBMs_node_classification.py", line 380, in main
    dataset.test.spatial_pos_lists = []
  File "/afs/crc.nd.edu/user/p/psoga/benchmarking-gnns/main_SBMs_node_classification.py", line 274, in train_val_pipeline
    break
Message: 'Best Train Accuracy Corresponding to Best Test Accuracy: 84.2378'
Arguments: ()
--- Logging error ---
Traceback (most recent call last):
  File "/afs/crc.nd.edu/user/p/psoga/.conda/envs/gnn/lib/python3.10/logging/__init__.py", line 1104, in emit
    self.flush()
  File "/afs/crc.nd.edu/user/p/psoga/.conda/envs/gnn/lib/python3.10/logging/__init__.py", line 1084, in flush
    self.stream.flush()
OSError: [Errno 5] Input/output error
Call stack:
  File "/afs/crc.nd.edu/user/p/psoga/benchmarking-gnns/main_SBMs_node_classification.py", line 382, in <module>
    net_params['in_dim'] = torch.unique(dataset.train[0][0].ndata['feat'],dim=0).size(0) # node_dim (feat is an integer)
  File "/afs/crc.nd.edu/user/p/psoga/benchmarking-gnns/main_SBMs_node_classification.py", line 380, in main
    dataset.test.spatial_pos_lists = []
  File "/afs/crc.nd.edu/user/p/psoga/benchmarking-gnns/main_SBMs_node_classification.py", line 275, in train_val_pipeline
Message: 'Convergence Time (Epochs): 234.0000'
Arguments: ()
--- Logging error ---
Traceback (most recent call last):
  File "/afs/crc.nd.edu/user/p/psoga/.conda/envs/gnn/lib/python3.10/logging/__init__.py", line 1104, in emit
    self.flush()
  File "/afs/crc.nd.edu/user/p/psoga/.conda/envs/gnn/lib/python3.10/logging/__init__.py", line 1084, in flush
    self.stream.flush()
OSError: [Errno 5] Input/output error
Call stack:
  File "/afs/crc.nd.edu/user/p/psoga/benchmarking-gnns/main_SBMs_node_classification.py", line 382, in <module>
    net_params['in_dim'] = torch.unique(dataset.train[0][0].ndata['feat'],dim=0).size(0) # node_dim (feat is an integer)
  File "/afs/crc.nd.edu/user/p/psoga/benchmarking-gnns/main_SBMs_node_classification.py", line 380, in main
    dataset.test.spatial_pos_lists = []
  File "/afs/crc.nd.edu/user/p/psoga/benchmarking-gnns/main_SBMs_node_classification.py", line 276, in train_val_pipeline
    except KeyboardInterrupt:
Message: 'TOTAL TIME TAKEN: 32599.3230s'
Arguments: ()
--- Logging error ---
Traceback (most recent call last):
  File "/afs/crc.nd.edu/user/p/psoga/.conda/envs/gnn/lib/python3.10/logging/__init__.py", line 1104, in emit
    self.flush()
  File "/afs/crc.nd.edu/user/p/psoga/.conda/envs/gnn/lib/python3.10/logging/__init__.py", line 1084, in flush
    self.stream.flush()
OSError: [Errno 5] Input/output error
Call stack:
  File "/afs/crc.nd.edu/user/p/psoga/benchmarking-gnns/main_SBMs_node_classification.py", line 382, in <module>
    net_params['in_dim'] = torch.unique(dataset.train[0][0].ndata['feat'],dim=0).size(0) # node_dim (feat is an integer)
  File "/afs/crc.nd.edu/user/p/psoga/benchmarking-gnns/main_SBMs_node_classification.py", line 380, in main
    dataset.test.spatial_pos_lists = []
  File "/afs/crc.nd.edu/user/p/psoga/benchmarking-gnns/main_SBMs_node_classification.py", line 277, in train_val_pipeline
    logger.info('-' * 89)
Message: 'AVG TIME PER EPOCH: 138.3686s'
Arguments: ()
--- Logging error ---
Traceback (most recent call last):
  File "/afs/crc.nd.edu/user/p/psoga/.conda/envs/gnn/lib/python3.10/logging/__init__.py", line 1104, in emit
    self.flush()
  File "/afs/crc.nd.edu/user/p/psoga/.conda/envs/gnn/lib/python3.10/logging/__init__.py", line 1084, in flush
    self.stream.flush()
OSError: [Errno 5] Input/output error
Call stack:
  File "/afs/crc.nd.edu/user/p/psoga/benchmarking-gnns/main_SBMs_node_classification.py", line 382, in <module>
    net_params['in_dim'] = torch.unique(dataset.train[0][0].ndata['feat'],dim=0).size(0) # node_dim (feat is an integer)
  File "/afs/crc.nd.edu/user/p/psoga/benchmarking-gnns/main_SBMs_node_classification.py", line 380, in main
    dataset.test.spatial_pos_lists = []
  File "/afs/crc.nd.edu/user/p/psoga/benchmarking-gnns/main_SBMs_node_classification.py", line 279, in train_val_pipeline
Message: {'seed': 41, 'epochs': 1000, 'batch_size': 26, 'init_lr': 0.0005, 'lr_reduce_factor': 0.5, 'lr_schedule_patience': 10, 'min_lr': 1e-06, 'weight_decay': 0.0, 'print_epoch_interval': 5, 'max_time': 24, 'seed_array': [35], 'job_num': 2}
Arguments: ()
--- Logging error ---
Traceback (most recent call last):
  File "/afs/crc.nd.edu/user/p/psoga/.conda/envs/gnn/lib/python3.10/logging/__init__.py", line 1104, in emit
    self.flush()
  File "/afs/crc.nd.edu/user/p/psoga/.conda/envs/gnn/lib/python3.10/logging/__init__.py", line 1084, in flush
    self.stream.flush()
OSError: [Errno 5] Input/output error
Call stack:
  File "/afs/crc.nd.edu/user/p/psoga/benchmarking-gnns/main_SBMs_node_classification.py", line 382, in <module>
    net_params['in_dim'] = torch.unique(dataset.train[0][0].ndata['feat'],dim=0).size(0) # node_dim (feat is an integer)
  File "/afs/crc.nd.edu/user/p/psoga/benchmarking-gnns/main_SBMs_node_classification.py", line 380, in main
    dataset.test.spatial_pos_lists = []
  File "/afs/crc.nd.edu/user/p/psoga/benchmarking-gnns/main_SBMs_node_classification.py", line 280, in train_val_pipeline
    test_history.append(test_acc)
Message: 'train history: [84.25975370639462]'
Arguments: ()
--- Logging error ---
Traceback (most recent call last):
  File "/afs/crc.nd.edu/user/p/psoga/.conda/envs/gnn/lib/python3.10/logging/__init__.py", line 1104, in emit
    self.flush()
  File "/afs/crc.nd.edu/user/p/psoga/.conda/envs/gnn/lib/python3.10/logging/__init__.py", line 1084, in flush
    self.stream.flush()
OSError: [Errno 5] Input/output error
Call stack:
  File "/afs/crc.nd.edu/user/p/psoga/benchmarking-gnns/main_SBMs_node_classification.py", line 382, in <module>
    net_params['in_dim'] = torch.unique(dataset.train[0][0].ndata['feat'],dim=0).size(0) # node_dim (feat is an integer)
  File "/afs/crc.nd.edu/user/p/psoga/benchmarking-gnns/main_SBMs_node_classification.py", line 380, in main
    dataset.test.spatial_pos_lists = []
  File "/afs/crc.nd.edu/user/p/psoga/benchmarking-gnns/main_SBMs_node_classification.py", line 281, in train_val_pipeline
    val_history.append(val_acc)
Message: 'test history: [84.56891719791555]'
Arguments: ()
--- Logging error ---
Traceback (most recent call last):
  File "/afs/crc.nd.edu/user/p/psoga/.conda/envs/gnn/lib/python3.10/logging/__init__.py", line 1104, in emit
    self.flush()
  File "/afs/crc.nd.edu/user/p/psoga/.conda/envs/gnn/lib/python3.10/logging/__init__.py", line 1084, in flush
    self.stream.flush()
OSError: [Errno 5] Input/output error
Call stack:
  File "/afs/crc.nd.edu/user/p/psoga/benchmarking-gnns/main_SBMs_node_classification.py", line 382, in <module>
    net_params['in_dim'] = torch.unique(dataset.train[0][0].ndata['feat'],dim=0).size(0) # node_dim (feat is an integer)
  File "/afs/crc.nd.edu/user/p/psoga/benchmarking-gnns/main_SBMs_node_classification.py", line 380, in main
    dataset.test.spatial_pos_lists = []
  File "/afs/crc.nd.edu/user/p/psoga/benchmarking-gnns/main_SBMs_node_classification.py", line 282, in train_val_pipeline
    train_history.append(train_acc)
Message: 'val history: [84.38924688163259]'
Arguments: ()
[I] Loading dataset SBM_PATTERN...
train, test, val sizes : 10000 2000 2000
[I] Finished loading.
[I] Data load time: 16.0683s
Epoch 00041: reducing learning rate of group 0 to 2.5000e-04.
Epoch 00083: reducing learning rate of group 0 to 1.2500e-04.
Epoch 00102: reducing learning rate of group 0 to 6.2500e-05.
Epoch 00115: reducing learning rate of group 0 to 3.1250e-05.
Epoch 00126: reducing learning rate of group 0 to 1.5625e-05.
Epoch 00156: reducing learning rate of group 0 to 7.8125e-06.
Epoch 00171: reducing learning rate of group 0 to 3.9063e-06.
Epoch 00224: reducing learning rate of group 0 to 1.9531e-06.
Epoch 00235: reducing learning rate of group 0 to 9.7656e-07.
