--- Logging error ---
Traceback (most recent call last):
  File "/afs/crc.nd.edu/user/p/psoga/.conda/envs/gnn/lib/python3.10/logging/__init__.py", line 1104, in emit
    self.flush()
  File "/afs/crc.nd.edu/user/p/psoga/.conda/envs/gnn/lib/python3.10/logging/__init__.py", line 1084, in flush
    self.stream.flush()
OSError: [Errno 5] Input/output error
Call stack:
  File "/afs/crc.nd.edu/user/p/psoga/benchmarking-gnns/main_SBMs_node_classification.py", line 382, in <module>
    net_params['in_dim'] = torch.unique(dataset.train[0][0].ndata['feat'],dim=0).size(0) # node_dim (feat is an integer)
  File "/afs/crc.nd.edu/user/p/psoga/benchmarking-gnns/main_SBMs_node_classification.py", line 380, in main
    dataset.test.spatial_pos_lists = []
  File "/afs/crc.nd.edu/user/p/psoga/benchmarking-gnns/main_SBMs_node_classification.py", line 231, in train_val_pipeline
    # writer.add_scalar('train/_loss', epoch_train_loss, epoch)
Message: '\tTime: 142.97s, LR: 0.00002, Train Loss: 0.3646, Train Acc: 83.4844,\n                            Val Loss: 0.3666, Val Acc: 83.2913, Test Acc: 83.4408'
Arguments: ()
--- Logging error ---
Traceback (most recent call last):
  File "/afs/crc.nd.edu/user/p/psoga/.conda/envs/gnn/lib/python3.10/logging/__init__.py", line 1104, in emit
    self.flush()
  File "/afs/crc.nd.edu/user/p/psoga/.conda/envs/gnn/lib/python3.10/logging/__init__.py", line 1084, in flush
    self.stream.flush()
OSError: [Errno 5] Input/output error
Call stack:
  File "/afs/crc.nd.edu/user/p/psoga/benchmarking-gnns/main_SBMs_node_classification.py", line 382, in <module>
    net_params['in_dim'] = torch.unique(dataset.train[0][0].ndata['feat'],dim=0).size(0) # node_dim (feat is an integer)
  File "/afs/crc.nd.edu/user/p/psoga/benchmarking-gnns/main_SBMs_node_classification.py", line 380, in main
    dataset.test.spatial_pos_lists = []
  File "/afs/crc.nd.edu/user/p/psoga/benchmarking-gnns/main_SBMs_node_classification.py", line 189, in train_val_pipeline
    else:
Message: 'Epoch 205/1000'
Arguments: ()
--- Logging error ---
Traceback (most recent call last):
  File "/afs/crc.nd.edu/user/p/psoga/.conda/envs/gnn/lib/python3.10/logging/__init__.py", line 1104, in emit
    self.flush()
  File "/afs/crc.nd.edu/user/p/psoga/.conda/envs/gnn/lib/python3.10/logging/__init__.py", line 1084, in flush
    self.stream.flush()
OSError: [Errno 5] Input/output error
Call stack:
  File "/afs/crc.nd.edu/user/p/psoga/benchmarking-gnns/main_SBMs_node_classification.py", line 382, in <module>
    net_params['in_dim'] = torch.unique(dataset.train[0][0].ndata['feat'],dim=0).size(0) # node_dim (feat is an integer)
  File "/afs/crc.nd.edu/user/p/psoga/benchmarking-gnns/main_SBMs_node_classification.py", line 380, in main
    dataset.test.spatial_pos_lists = []
  File "/afs/crc.nd.edu/user/p/psoga/benchmarking-gnns/main_SBMs_node_classification.py", line 231, in train_val_pipeline
    # writer.add_scalar('train/_loss', epoch_train_loss, epoch)
Message: '\tTime: 142.93s, LR: 0.00002, Train Loss: 0.3654, Train Acc: 83.4398,\n                            Val Loss: 0.3644, Val Acc: 83.4823, Test Acc: 83.5332'
Arguments: ()
--- Logging error ---
Traceback (most recent call last):
  File "/afs/crc.nd.edu/user/p/psoga/.conda/envs/gnn/lib/python3.10/logging/__init__.py", line 1104, in emit
    self.flush()
  File "/afs/crc.nd.edu/user/p/psoga/.conda/envs/gnn/lib/python3.10/logging/__init__.py", line 1084, in flush
    self.stream.flush()
OSError: [Errno 5] Input/output error
Call stack:
  File "/afs/crc.nd.edu/user/p/psoga/benchmarking-gnns/main_SBMs_node_classification.py", line 382, in <module>
    net_params['in_dim'] = torch.unique(dataset.train[0][0].ndata['feat'],dim=0).size(0) # node_dim (feat is an integer)
  File "/afs/crc.nd.edu/user/p/psoga/benchmarking-gnns/main_SBMs_node_classification.py", line 380, in main
    dataset.test.spatial_pos_lists = []
  File "/afs/crc.nd.edu/user/p/psoga/benchmarking-gnns/main_SBMs_node_classification.py", line 189, in train_val_pipeline
    else:
Message: 'Epoch 206/1000'
Arguments: ()
--- Logging error ---
Traceback (most recent call last):
  File "/afs/crc.nd.edu/user/p/psoga/.conda/envs/gnn/lib/python3.10/logging/__init__.py", line 1104, in emit
    self.flush()
  File "/afs/crc.nd.edu/user/p/psoga/.conda/envs/gnn/lib/python3.10/logging/__init__.py", line 1084, in flush
    self.stream.flush()
OSError: [Errno 5] Input/output error
Call stack:
  File "/afs/crc.nd.edu/user/p/psoga/benchmarking-gnns/main_SBMs_node_classification.py", line 382, in <module>
    net_params['in_dim'] = torch.unique(dataset.train[0][0].ndata['feat'],dim=0).size(0) # node_dim (feat is an integer)
  File "/afs/crc.nd.edu/user/p/psoga/benchmarking-gnns/main_SBMs_node_classification.py", line 380, in main
    dataset.test.spatial_pos_lists = []
  File "/afs/crc.nd.edu/user/p/psoga/benchmarking-gnns/main_SBMs_node_classification.py", line 231, in train_val_pipeline
    # writer.add_scalar('train/_loss', epoch_train_loss, epoch)
Message: '\tTime: 142.01s, LR: 0.00002, Train Loss: 0.3649, Train Acc: 83.4715,\n                            Val Loss: 0.3639, Val Acc: 83.4331, Test Acc: 83.6018'
Arguments: ()
--- Logging error ---
Traceback (most recent call last):
  File "/afs/crc.nd.edu/user/p/psoga/.conda/envs/gnn/lib/python3.10/logging/__init__.py", line 1104, in emit
    self.flush()
  File "/afs/crc.nd.edu/user/p/psoga/.conda/envs/gnn/lib/python3.10/logging/__init__.py", line 1084, in flush
    self.stream.flush()
OSError: [Errno 5] Input/output error
Call stack:
  File "/afs/crc.nd.edu/user/p/psoga/benchmarking-gnns/main_SBMs_node_classification.py", line 382, in <module>
    net_params['in_dim'] = torch.unique(dataset.train[0][0].ndata['feat'],dim=0).size(0) # node_dim (feat is an integer)
  File "/afs/crc.nd.edu/user/p/psoga/benchmarking-gnns/main_SBMs_node_classification.py", line 380, in main
    dataset.test.spatial_pos_lists = []
  File "/afs/crc.nd.edu/user/p/psoga/benchmarking-gnns/main_SBMs_node_classification.py", line 189, in train_val_pipeline
    else:
Message: 'Epoch 207/1000'
Arguments: ()
--- Logging error ---
Traceback (most recent call last):
  File "/afs/crc.nd.edu/user/p/psoga/.conda/envs/gnn/lib/python3.10/logging/__init__.py", line 1104, in emit
    self.flush()
  File "/afs/crc.nd.edu/user/p/psoga/.conda/envs/gnn/lib/python3.10/logging/__init__.py", line 1084, in flush
    self.stream.flush()
OSError: [Errno 5] Input/output error
Call stack:
  File "/afs/crc.nd.edu/user/p/psoga/benchmarking-gnns/main_SBMs_node_classification.py", line 382, in <module>
    net_params['in_dim'] = torch.unique(dataset.train[0][0].ndata['feat'],dim=0).size(0) # node_dim (feat is an integer)
  File "/afs/crc.nd.edu/user/p/psoga/benchmarking-gnns/main_SBMs_node_classification.py", line 380, in main
    dataset.test.spatial_pos_lists = []
  File "/afs/crc.nd.edu/user/p/psoga/benchmarking-gnns/main_SBMs_node_classification.py", line 231, in train_val_pipeline
    # writer.add_scalar('train/_loss', epoch_train_loss, epoch)
Message: '\tTime: 141.79s, LR: 0.00002, Train Loss: 0.3640, Train Acc: 83.5264,\n                            Val Loss: 0.3645, Val Acc: 83.4231, Test Acc: 83.6705'
Arguments: ()
--- Logging error ---
Traceback (most recent call last):
  File "/afs/crc.nd.edu/user/p/psoga/.conda/envs/gnn/lib/python3.10/logging/__init__.py", line 1104, in emit
    self.flush()
  File "/afs/crc.nd.edu/user/p/psoga/.conda/envs/gnn/lib/python3.10/logging/__init__.py", line 1084, in flush
    self.stream.flush()
OSError: [Errno 5] Input/output error
Call stack:
  File "/afs/crc.nd.edu/user/p/psoga/benchmarking-gnns/main_SBMs_node_classification.py", line 382, in <module>
    net_params['in_dim'] = torch.unique(dataset.train[0][0].ndata['feat'],dim=0).size(0) # node_dim (feat is an integer)
  File "/afs/crc.nd.edu/user/p/psoga/benchmarking-gnns/main_SBMs_node_classification.py", line 380, in main
    dataset.test.spatial_pos_lists = []
  File "/afs/crc.nd.edu/user/p/psoga/benchmarking-gnns/main_SBMs_node_classification.py", line 189, in train_val_pipeline
    else:
Message: 'Epoch 208/1000'
Arguments: ()
--- Logging error ---
Traceback (most recent call last):
  File "/afs/crc.nd.edu/user/p/psoga/.conda/envs/gnn/lib/python3.10/logging/__init__.py", line 1104, in emit
    self.flush()
  File "/afs/crc.nd.edu/user/p/psoga/.conda/envs/gnn/lib/python3.10/logging/__init__.py", line 1084, in flush
    self.stream.flush()
OSError: [Errno 5] Input/output error
Call stack:
  File "/afs/crc.nd.edu/user/p/psoga/benchmarking-gnns/main_SBMs_node_classification.py", line 382, in <module>
    net_params['in_dim'] = torch.unique(dataset.train[0][0].ndata['feat'],dim=0).size(0) # node_dim (feat is an integer)
  File "/afs/crc.nd.edu/user/p/psoga/benchmarking-gnns/main_SBMs_node_classification.py", line 380, in main
    dataset.test.spatial_pos_lists = []
  File "/afs/crc.nd.edu/user/p/psoga/benchmarking-gnns/main_SBMs_node_classification.py", line 231, in train_val_pipeline
    # writer.add_scalar('train/_loss', epoch_train_loss, epoch)
Message: '\tTime: 142.26s, LR: 0.00002, Train Loss: 0.3644, Train Acc: 83.5282,\n                            Val Loss: 0.3649, Val Acc: 83.4635, Test Acc: 83.6497'
Arguments: ()
--- Logging error ---
Traceback (most recent call last):
  File "/afs/crc.nd.edu/user/p/psoga/.conda/envs/gnn/lib/python3.10/logging/__init__.py", line 1104, in emit
    self.flush()
  File "/afs/crc.nd.edu/user/p/psoga/.conda/envs/gnn/lib/python3.10/logging/__init__.py", line 1084, in flush
    self.stream.flush()
OSError: [Errno 5] Input/output error
Call stack:
  File "/afs/crc.nd.edu/user/p/psoga/benchmarking-gnns/main_SBMs_node_classification.py", line 382, in <module>
    net_params['in_dim'] = torch.unique(dataset.train[0][0].ndata['feat'],dim=0).size(0) # node_dim (feat is an integer)
  File "/afs/crc.nd.edu/user/p/psoga/benchmarking-gnns/main_SBMs_node_classification.py", line 380, in main
    dataset.test.spatial_pos_lists = []
  File "/afs/crc.nd.edu/user/p/psoga/benchmarking-gnns/main_SBMs_node_classification.py", line 189, in train_val_pipeline
    else:
Message: 'Epoch 209/1000'
Arguments: ()
--- Logging error ---
Traceback (most recent call last):
  File "/afs/crc.nd.edu/user/p/psoga/.conda/envs/gnn/lib/python3.10/logging/__init__.py", line 1104, in emit
    self.flush()
  File "/afs/crc.nd.edu/user/p/psoga/.conda/envs/gnn/lib/python3.10/logging/__init__.py", line 1084, in flush
    self.stream.flush()
OSError: [Errno 5] Input/output error
Call stack:
  File "/afs/crc.nd.edu/user/p/psoga/benchmarking-gnns/main_SBMs_node_classification.py", line 382, in <module>
    net_params['in_dim'] = torch.unique(dataset.train[0][0].ndata['feat'],dim=0).size(0) # node_dim (feat is an integer)
  File "/afs/crc.nd.edu/user/p/psoga/benchmarking-gnns/main_SBMs_node_classification.py", line 380, in main
    dataset.test.spatial_pos_lists = []
  File "/afs/crc.nd.edu/user/p/psoga/benchmarking-gnns/main_SBMs_node_classification.py", line 231, in train_val_pipeline
    # writer.add_scalar('train/_loss', epoch_train_loss, epoch)
Message: '\tTime: 141.87s, LR: 0.00002, Train Loss: 0.3631, Train Acc: 83.5698,\n                            Val Loss: 0.3634, Val Acc: 83.5465, Test Acc: 83.7161'
Arguments: ()
--- Logging error ---
Traceback (most recent call last):
  File "/afs/crc.nd.edu/user/p/psoga/.conda/envs/gnn/lib/python3.10/logging/__init__.py", line 1104, in emit
    self.flush()
  File "/afs/crc.nd.edu/user/p/psoga/.conda/envs/gnn/lib/python3.10/logging/__init__.py", line 1084, in flush
    self.stream.flush()
OSError: [Errno 5] Input/output error
Call stack:
  File "/afs/crc.nd.edu/user/p/psoga/benchmarking-gnns/main_SBMs_node_classification.py", line 382, in <module>
    net_params['in_dim'] = torch.unique(dataset.train[0][0].ndata['feat'],dim=0).size(0) # node_dim (feat is an integer)
  File "/afs/crc.nd.edu/user/p/psoga/benchmarking-gnns/main_SBMs_node_classification.py", line 380, in main
    dataset.test.spatial_pos_lists = []
  File "/afs/crc.nd.edu/user/p/psoga/benchmarking-gnns/main_SBMs_node_classification.py", line 189, in train_val_pipeline
    else:
Message: 'Epoch 210/1000'
Arguments: ()
--- Logging error ---
Traceback (most recent call last):
  File "/afs/crc.nd.edu/user/p/psoga/.conda/envs/gnn/lib/python3.10/logging/__init__.py", line 1104, in emit
    self.flush()
  File "/afs/crc.nd.edu/user/p/psoga/.conda/envs/gnn/lib/python3.10/logging/__init__.py", line 1084, in flush
    self.stream.flush()
OSError: [Errno 5] Input/output error
Call stack:
  File "/afs/crc.nd.edu/user/p/psoga/benchmarking-gnns/main_SBMs_node_classification.py", line 382, in <module>
    net_params['in_dim'] = torch.unique(dataset.train[0][0].ndata['feat'],dim=0).size(0) # node_dim (feat is an integer)
  File "/afs/crc.nd.edu/user/p/psoga/benchmarking-gnns/main_SBMs_node_classification.py", line 380, in main
    dataset.test.spatial_pos_lists = []
  File "/afs/crc.nd.edu/user/p/psoga/benchmarking-gnns/main_SBMs_node_classification.py", line 231, in train_val_pipeline
    # writer.add_scalar('train/_loss', epoch_train_loss, epoch)
Message: '\tTime: 141.82s, LR: 0.00002, Train Loss: 0.3635, Train Acc: 83.5823,\n                            Val Loss: 0.3635, Val Acc: 83.4920, Test Acc: 83.7048'
Arguments: ()
--- Logging error ---
Traceback (most recent call last):
  File "/afs/crc.nd.edu/user/p/psoga/.conda/envs/gnn/lib/python3.10/logging/__init__.py", line 1104, in emit
    self.flush()
  File "/afs/crc.nd.edu/user/p/psoga/.conda/envs/gnn/lib/python3.10/logging/__init__.py", line 1084, in flush
    self.stream.flush()
OSError: [Errno 5] Input/output error
Call stack:
  File "/afs/crc.nd.edu/user/p/psoga/benchmarking-gnns/main_SBMs_node_classification.py", line 382, in <module>
    net_params['in_dim'] = torch.unique(dataset.train[0][0].ndata['feat'],dim=0).size(0) # node_dim (feat is an integer)
  File "/afs/crc.nd.edu/user/p/psoga/benchmarking-gnns/main_SBMs_node_classification.py", line 380, in main
    dataset.test.spatial_pos_lists = []
  File "/afs/crc.nd.edu/user/p/psoga/benchmarking-gnns/main_SBMs_node_classification.py", line 189, in train_val_pipeline
    else:
Message: 'Epoch 211/1000'
Arguments: ()
--- Logging error ---
Traceback (most recent call last):
  File "/afs/crc.nd.edu/user/p/psoga/.conda/envs/gnn/lib/python3.10/logging/__init__.py", line 1104, in emit
    self.flush()
  File "/afs/crc.nd.edu/user/p/psoga/.conda/envs/gnn/lib/python3.10/logging/__init__.py", line 1084, in flush
    self.stream.flush()
OSError: [Errno 5] Input/output error
Call stack:
  File "/afs/crc.nd.edu/user/p/psoga/benchmarking-gnns/main_SBMs_node_classification.py", line 382, in <module>
    net_params['in_dim'] = torch.unique(dataset.train[0][0].ndata['feat'],dim=0).size(0) # node_dim (feat is an integer)
  File "/afs/crc.nd.edu/user/p/psoga/benchmarking-gnns/main_SBMs_node_classification.py", line 380, in main
    dataset.test.spatial_pos_lists = []
  File "/afs/crc.nd.edu/user/p/psoga/benchmarking-gnns/main_SBMs_node_classification.py", line 231, in train_val_pipeline
    # writer.add_scalar('train/_loss', epoch_train_loss, epoch)
Message: '\tTime: 142.30s, LR: 0.00002, Train Loss: 0.3637, Train Acc: 83.5438,\n                            Val Loss: 0.3649, Val Acc: 83.4924, Test Acc: 83.7141'
Arguments: ()
--- Logging error ---
Traceback (most recent call last):
  File "/afs/crc.nd.edu/user/p/psoga/.conda/envs/gnn/lib/python3.10/logging/__init__.py", line 1104, in emit
    self.flush()
  File "/afs/crc.nd.edu/user/p/psoga/.conda/envs/gnn/lib/python3.10/logging/__init__.py", line 1084, in flush
    self.stream.flush()
OSError: [Errno 5] Input/output error
Call stack:
  File "/afs/crc.nd.edu/user/p/psoga/benchmarking-gnns/main_SBMs_node_classification.py", line 382, in <module>
    net_params['in_dim'] = torch.unique(dataset.train[0][0].ndata['feat'],dim=0).size(0) # node_dim (feat is an integer)
  File "/afs/crc.nd.edu/user/p/psoga/benchmarking-gnns/main_SBMs_node_classification.py", line 380, in main
    dataset.test.spatial_pos_lists = []
  File "/afs/crc.nd.edu/user/p/psoga/benchmarking-gnns/main_SBMs_node_classification.py", line 189, in train_val_pipeline
    else:
Message: 'Epoch 212/1000'
Arguments: ()
--- Logging error ---
Traceback (most recent call last):
  File "/afs/crc.nd.edu/user/p/psoga/.conda/envs/gnn/lib/python3.10/logging/__init__.py", line 1104, in emit
    self.flush()
  File "/afs/crc.nd.edu/user/p/psoga/.conda/envs/gnn/lib/python3.10/logging/__init__.py", line 1084, in flush
    self.stream.flush()
OSError: [Errno 5] Input/output error
Call stack:
  File "/afs/crc.nd.edu/user/p/psoga/benchmarking-gnns/main_SBMs_node_classification.py", line 382, in <module>
    net_params['in_dim'] = torch.unique(dataset.train[0][0].ndata['feat'],dim=0).size(0) # node_dim (feat is an integer)
  File "/afs/crc.nd.edu/user/p/psoga/benchmarking-gnns/main_SBMs_node_classification.py", line 380, in main
    dataset.test.spatial_pos_lists = []
  File "/afs/crc.nd.edu/user/p/psoga/benchmarking-gnns/main_SBMs_node_classification.py", line 231, in train_val_pipeline
    # writer.add_scalar('train/_loss', epoch_train_loss, epoch)
Message: '\tTime: 142.31s, LR: 0.00001, Train Loss: 0.3629, Train Acc: 83.5787,\n                            Val Loss: 0.3639, Val Acc: 83.5160, Test Acc: 83.6614'
Arguments: ()
--- Logging error ---
Traceback (most recent call last):
  File "/afs/crc.nd.edu/user/p/psoga/.conda/envs/gnn/lib/python3.10/logging/__init__.py", line 1104, in emit
    self.flush()
  File "/afs/crc.nd.edu/user/p/psoga/.conda/envs/gnn/lib/python3.10/logging/__init__.py", line 1084, in flush
    self.stream.flush()
OSError: [Errno 5] Input/output error
Call stack:
  File "/afs/crc.nd.edu/user/p/psoga/benchmarking-gnns/main_SBMs_node_classification.py", line 382, in <module>
    net_params['in_dim'] = torch.unique(dataset.train[0][0].ndata['feat'],dim=0).size(0) # node_dim (feat is an integer)
  File "/afs/crc.nd.edu/user/p/psoga/benchmarking-gnns/main_SBMs_node_classification.py", line 380, in main
    dataset.test.spatial_pos_lists = []
  File "/afs/crc.nd.edu/user/p/psoga/benchmarking-gnns/main_SBMs_node_classification.py", line 189, in train_val_pipeline
    else:
Message: 'Epoch 213/1000'
Arguments: ()
--- Logging error ---
Traceback (most recent call last):
  File "/afs/crc.nd.edu/user/p/psoga/.conda/envs/gnn/lib/python3.10/logging/__init__.py", line 1104, in emit
    self.flush()
  File "/afs/crc.nd.edu/user/p/psoga/.conda/envs/gnn/lib/python3.10/logging/__init__.py", line 1084, in flush
    self.stream.flush()
OSError: [Errno 5] Input/output error
Call stack:
  File "/afs/crc.nd.edu/user/p/psoga/benchmarking-gnns/main_SBMs_node_classification.py", line 382, in <module>
    net_params['in_dim'] = torch.unique(dataset.train[0][0].ndata['feat'],dim=0).size(0) # node_dim (feat is an integer)
  File "/afs/crc.nd.edu/user/p/psoga/benchmarking-gnns/main_SBMs_node_classification.py", line 380, in main
    dataset.test.spatial_pos_lists = []
  File "/afs/crc.nd.edu/user/p/psoga/benchmarking-gnns/main_SBMs_node_classification.py", line 231, in train_val_pipeline
    # writer.add_scalar('train/_loss', epoch_train_loss, epoch)
Message: '\tTime: 141.61s, LR: 0.00001, Train Loss: 0.3624, Train Acc: 83.6209,\n                            Val Loss: 0.3636, Val Acc: 83.5104, Test Acc: 83.7195'
Arguments: ()
--- Logging error ---
Traceback (most recent call last):
  File "/afs/crc.nd.edu/user/p/psoga/.conda/envs/gnn/lib/python3.10/logging/__init__.py", line 1104, in emit
    self.flush()
  File "/afs/crc.nd.edu/user/p/psoga/.conda/envs/gnn/lib/python3.10/logging/__init__.py", line 1084, in flush
    self.stream.flush()
OSError: [Errno 5] Input/output error
Call stack:
  File "/afs/crc.nd.edu/user/p/psoga/benchmarking-gnns/main_SBMs_node_classification.py", line 382, in <module>
    net_params['in_dim'] = torch.unique(dataset.train[0][0].ndata['feat'],dim=0).size(0) # node_dim (feat is an integer)
  File "/afs/crc.nd.edu/user/p/psoga/benchmarking-gnns/main_SBMs_node_classification.py", line 380, in main
    dataset.test.spatial_pos_lists = []
  File "/afs/crc.nd.edu/user/p/psoga/benchmarking-gnns/main_SBMs_node_classification.py", line 189, in train_val_pipeline
    else:
Message: 'Epoch 214/1000'
Arguments: ()
--- Logging error ---
Traceback (most recent call last):
  File "/afs/crc.nd.edu/user/p/psoga/.conda/envs/gnn/lib/python3.10/logging/__init__.py", line 1104, in emit
    self.flush()
  File "/afs/crc.nd.edu/user/p/psoga/.conda/envs/gnn/lib/python3.10/logging/__init__.py", line 1084, in flush
    self.stream.flush()
OSError: [Errno 5] Input/output error
Call stack:
  File "/afs/crc.nd.edu/user/p/psoga/benchmarking-gnns/main_SBMs_node_classification.py", line 382, in <module>
    net_params['in_dim'] = torch.unique(dataset.train[0][0].ndata['feat'],dim=0).size(0) # node_dim (feat is an integer)
  File "/afs/crc.nd.edu/user/p/psoga/benchmarking-gnns/main_SBMs_node_classification.py", line 380, in main
    dataset.test.spatial_pos_lists = []
  File "/afs/crc.nd.edu/user/p/psoga/benchmarking-gnns/main_SBMs_node_classification.py", line 231, in train_val_pipeline
    # writer.add_scalar('train/_loss', epoch_train_loss, epoch)
Message: '\tTime: 142.04s, LR: 0.00001, Train Loss: 0.3629, Train Acc: 83.5851,\n                            Val Loss: 0.3650, Val Acc: 83.4161, Test Acc: 83.6147'
Arguments: ()
--- Logging error ---
Traceback (most recent call last):
  File "/afs/crc.nd.edu/user/p/psoga/.conda/envs/gnn/lib/python3.10/logging/__init__.py", line 1104, in emit
    self.flush()
  File "/afs/crc.nd.edu/user/p/psoga/.conda/envs/gnn/lib/python3.10/logging/__init__.py", line 1084, in flush
    self.stream.flush()
OSError: [Errno 5] Input/output error
Call stack:
  File "/afs/crc.nd.edu/user/p/psoga/benchmarking-gnns/main_SBMs_node_classification.py", line 382, in <module>
    net_params['in_dim'] = torch.unique(dataset.train[0][0].ndata['feat'],dim=0).size(0) # node_dim (feat is an integer)
  File "/afs/crc.nd.edu/user/p/psoga/benchmarking-gnns/main_SBMs_node_classification.py", line 380, in main
    dataset.test.spatial_pos_lists = []
  File "/afs/crc.nd.edu/user/p/psoga/benchmarking-gnns/main_SBMs_node_classification.py", line 189, in train_val_pipeline
    else:
Message: 'Epoch 215/1000'
Arguments: ()
--- Logging error ---
Traceback (most recent call last):
  File "/afs/crc.nd.edu/user/p/psoga/.conda/envs/gnn/lib/python3.10/logging/__init__.py", line 1104, in emit
    self.flush()
  File "/afs/crc.nd.edu/user/p/psoga/.conda/envs/gnn/lib/python3.10/logging/__init__.py", line 1084, in flush
    self.stream.flush()
OSError: [Errno 5] Input/output error
Call stack:
  File "/afs/crc.nd.edu/user/p/psoga/benchmarking-gnns/main_SBMs_node_classification.py", line 382, in <module>
    net_params['in_dim'] = torch.unique(dataset.train[0][0].ndata['feat'],dim=0).size(0) # node_dim (feat is an integer)
  File "/afs/crc.nd.edu/user/p/psoga/benchmarking-gnns/main_SBMs_node_classification.py", line 380, in main
    dataset.test.spatial_pos_lists = []
  File "/afs/crc.nd.edu/user/p/psoga/benchmarking-gnns/main_SBMs_node_classification.py", line 231, in train_val_pipeline
    # writer.add_scalar('train/_loss', epoch_train_loss, epoch)
Message: '\tTime: 142.15s, LR: 0.00001, Train Loss: 0.3635, Train Acc: 83.5707,\n                            Val Loss: 0.3644, Val Acc: 83.4495, Test Acc: 83.7064'
Arguments: ()
--- Logging error ---
Traceback (most recent call last):
  File "/afs/crc.nd.edu/user/p/psoga/.conda/envs/gnn/lib/python3.10/logging/__init__.py", line 1104, in emit
    self.flush()
  File "/afs/crc.nd.edu/user/p/psoga/.conda/envs/gnn/lib/python3.10/logging/__init__.py", line 1084, in flush
    self.stream.flush()
OSError: [Errno 5] Input/output error
Call stack:
  File "/afs/crc.nd.edu/user/p/psoga/benchmarking-gnns/main_SBMs_node_classification.py", line 382, in <module>
    net_params['in_dim'] = torch.unique(dataset.train[0][0].ndata['feat'],dim=0).size(0) # node_dim (feat is an integer)
  File "/afs/crc.nd.edu/user/p/psoga/benchmarking-gnns/main_SBMs_node_classification.py", line 380, in main
    dataset.test.spatial_pos_lists = []
  File "/afs/crc.nd.edu/user/p/psoga/benchmarking-gnns/main_SBMs_node_classification.py", line 189, in train_val_pipeline
    else:
Message: 'Epoch 216/1000'
Arguments: ()
--- Logging error ---
Traceback (most recent call last):
  File "/afs/crc.nd.edu/user/p/psoga/.conda/envs/gnn/lib/python3.10/logging/__init__.py", line 1104, in emit
    self.flush()
  File "/afs/crc.nd.edu/user/p/psoga/.conda/envs/gnn/lib/python3.10/logging/__init__.py", line 1084, in flush
    self.stream.flush()
OSError: [Errno 5] Input/output error
Call stack:
  File "/afs/crc.nd.edu/user/p/psoga/benchmarking-gnns/main_SBMs_node_classification.py", line 382, in <module>
    net_params['in_dim'] = torch.unique(dataset.train[0][0].ndata['feat'],dim=0).size(0) # node_dim (feat is an integer)
  File "/afs/crc.nd.edu/user/p/psoga/benchmarking-gnns/main_SBMs_node_classification.py", line 380, in main
    dataset.test.spatial_pos_lists = []
  File "/afs/crc.nd.edu/user/p/psoga/benchmarking-gnns/main_SBMs_node_classification.py", line 231, in train_val_pipeline
    # writer.add_scalar('train/_loss', epoch_train_loss, epoch)
Message: '\tTime: 142.64s, LR: 0.00001, Train Loss: 0.3627, Train Acc: 83.6138,\n                            Val Loss: 0.3641, Val Acc: 83.5450, Test Acc: 83.6920'
Arguments: ()
--- Logging error ---
Traceback (most recent call last):
  File "/afs/crc.nd.edu/user/p/psoga/.conda/envs/gnn/lib/python3.10/logging/__init__.py", line 1104, in emit
    self.flush()
  File "/afs/crc.nd.edu/user/p/psoga/.conda/envs/gnn/lib/python3.10/logging/__init__.py", line 1084, in flush
    self.stream.flush()
OSError: [Errno 5] Input/output error
Call stack:
  File "/afs/crc.nd.edu/user/p/psoga/benchmarking-gnns/main_SBMs_node_classification.py", line 382, in <module>
    net_params['in_dim'] = torch.unique(dataset.train[0][0].ndata['feat'],dim=0).size(0) # node_dim (feat is an integer)
  File "/afs/crc.nd.edu/user/p/psoga/benchmarking-gnns/main_SBMs_node_classification.py", line 380, in main
    dataset.test.spatial_pos_lists = []
  File "/afs/crc.nd.edu/user/p/psoga/benchmarking-gnns/main_SBMs_node_classification.py", line 189, in train_val_pipeline
    else:
Message: 'Epoch 217/1000'
Arguments: ()
--- Logging error ---
Traceback (most recent call last):
  File "/afs/crc.nd.edu/user/p/psoga/.conda/envs/gnn/lib/python3.10/logging/__init__.py", line 1104, in emit
    self.flush()
  File "/afs/crc.nd.edu/user/p/psoga/.conda/envs/gnn/lib/python3.10/logging/__init__.py", line 1084, in flush
    self.stream.flush()
OSError: [Errno 5] Input/output error
Call stack:
  File "/afs/crc.nd.edu/user/p/psoga/benchmarking-gnns/main_SBMs_node_classification.py", line 382, in <module>
    net_params['in_dim'] = torch.unique(dataset.train[0][0].ndata['feat'],dim=0).size(0) # node_dim (feat is an integer)
  File "/afs/crc.nd.edu/user/p/psoga/benchmarking-gnns/main_SBMs_node_classification.py", line 380, in main
    dataset.test.spatial_pos_lists = []
  File "/afs/crc.nd.edu/user/p/psoga/benchmarking-gnns/main_SBMs_node_classification.py", line 231, in train_val_pipeline
    # writer.add_scalar('train/_loss', epoch_train_loss, epoch)
Message: '\tTime: 141.78s, LR: 0.00001, Train Loss: 0.3629, Train Acc: 83.5825,\n                            Val Loss: 0.3637, Val Acc: 83.4499, Test Acc: 83.6758'
Arguments: ()
--- Logging error ---
Traceback (most recent call last):
  File "/afs/crc.nd.edu/user/p/psoga/.conda/envs/gnn/lib/python3.10/logging/__init__.py", line 1104, in emit
    self.flush()
  File "/afs/crc.nd.edu/user/p/psoga/.conda/envs/gnn/lib/python3.10/logging/__init__.py", line 1084, in flush
    self.stream.flush()
OSError: [Errno 5] Input/output error
Call stack:
  File "/afs/crc.nd.edu/user/p/psoga/benchmarking-gnns/main_SBMs_node_classification.py", line 382, in <module>
    net_params['in_dim'] = torch.unique(dataset.train[0][0].ndata['feat'],dim=0).size(0) # node_dim (feat is an integer)
  File "/afs/crc.nd.edu/user/p/psoga/benchmarking-gnns/main_SBMs_node_classification.py", line 380, in main
    dataset.test.spatial_pos_lists = []
  File "/afs/crc.nd.edu/user/p/psoga/benchmarking-gnns/main_SBMs_node_classification.py", line 189, in train_val_pipeline
    else:
Message: 'Epoch 218/1000'
Arguments: ()
--- Logging error ---
Traceback (most recent call last):
  File "/afs/crc.nd.edu/user/p/psoga/.conda/envs/gnn/lib/python3.10/logging/__init__.py", line 1104, in emit
    self.flush()
  File "/afs/crc.nd.edu/user/p/psoga/.conda/envs/gnn/lib/python3.10/logging/__init__.py", line 1084, in flush
    self.stream.flush()
OSError: [Errno 5] Input/output error
Call stack:
  File "/afs/crc.nd.edu/user/p/psoga/benchmarking-gnns/main_SBMs_node_classification.py", line 382, in <module>
    net_params['in_dim'] = torch.unique(dataset.train[0][0].ndata['feat'],dim=0).size(0) # node_dim (feat is an integer)
  File "/afs/crc.nd.edu/user/p/psoga/benchmarking-gnns/main_SBMs_node_classification.py", line 380, in main
    dataset.test.spatial_pos_lists = []
  File "/afs/crc.nd.edu/user/p/psoga/benchmarking-gnns/main_SBMs_node_classification.py", line 231, in train_val_pipeline
    # writer.add_scalar('train/_loss', epoch_train_loss, epoch)
Message: '\tTime: 142.05s, LR: 0.00001, Train Loss: 0.3626, Train Acc: 83.6218,\n                            Val Loss: 0.3637, Val Acc: 83.5276, Test Acc: 83.6907'
Arguments: ()
--- Logging error ---
Traceback (most recent call last):
  File "/afs/crc.nd.edu/user/p/psoga/.conda/envs/gnn/lib/python3.10/logging/__init__.py", line 1104, in emit
    self.flush()
  File "/afs/crc.nd.edu/user/p/psoga/.conda/envs/gnn/lib/python3.10/logging/__init__.py", line 1084, in flush
    self.stream.flush()
OSError: [Errno 5] Input/output error
Call stack:
  File "/afs/crc.nd.edu/user/p/psoga/benchmarking-gnns/main_SBMs_node_classification.py", line 382, in <module>
    net_params['in_dim'] = torch.unique(dataset.train[0][0].ndata['feat'],dim=0).size(0) # node_dim (feat is an integer)
  File "/afs/crc.nd.edu/user/p/psoga/benchmarking-gnns/main_SBMs_node_classification.py", line 380, in main
    dataset.test.spatial_pos_lists = []
  File "/afs/crc.nd.edu/user/p/psoga/benchmarking-gnns/main_SBMs_node_classification.py", line 189, in train_val_pipeline
    else:
Message: 'Epoch 219/1000'
Arguments: ()
--- Logging error ---
Traceback (most recent call last):
  File "/afs/crc.nd.edu/user/p/psoga/.conda/envs/gnn/lib/python3.10/logging/__init__.py", line 1104, in emit
    self.flush()
  File "/afs/crc.nd.edu/user/p/psoga/.conda/envs/gnn/lib/python3.10/logging/__init__.py", line 1084, in flush
    self.stream.flush()
OSError: [Errno 5] Input/output error
Call stack:
  File "/afs/crc.nd.edu/user/p/psoga/benchmarking-gnns/main_SBMs_node_classification.py", line 382, in <module>
    net_params['in_dim'] = torch.unique(dataset.train[0][0].ndata['feat'],dim=0).size(0) # node_dim (feat is an integer)
  File "/afs/crc.nd.edu/user/p/psoga/benchmarking-gnns/main_SBMs_node_classification.py", line 380, in main
    dataset.test.spatial_pos_lists = []
  File "/afs/crc.nd.edu/user/p/psoga/benchmarking-gnns/main_SBMs_node_classification.py", line 231, in train_val_pipeline
    # writer.add_scalar('train/_loss', epoch_train_loss, epoch)
Message: '\tTime: 142.22s, LR: 0.00001, Train Loss: 0.3626, Train Acc: 83.6384,\n                            Val Loss: 0.3634, Val Acc: 83.5757, Test Acc: 83.7074'
Arguments: ()
--- Logging error ---
Traceback (most recent call last):
  File "/afs/crc.nd.edu/user/p/psoga/.conda/envs/gnn/lib/python3.10/logging/__init__.py", line 1104, in emit
    self.flush()
  File "/afs/crc.nd.edu/user/p/psoga/.conda/envs/gnn/lib/python3.10/logging/__init__.py", line 1084, in flush
    self.stream.flush()
OSError: [Errno 5] Input/output error
Call stack:
  File "/afs/crc.nd.edu/user/p/psoga/benchmarking-gnns/main_SBMs_node_classification.py", line 382, in <module>
    net_params['in_dim'] = torch.unique(dataset.train[0][0].ndata['feat'],dim=0).size(0) # node_dim (feat is an integer)
  File "/afs/crc.nd.edu/user/p/psoga/benchmarking-gnns/main_SBMs_node_classification.py", line 380, in main
    dataset.test.spatial_pos_lists = []
  File "/afs/crc.nd.edu/user/p/psoga/benchmarking-gnns/main_SBMs_node_classification.py", line 189, in train_val_pipeline
    else:
Message: 'Epoch 220/1000'
Arguments: ()
--- Logging error ---
Traceback (most recent call last):
  File "/afs/crc.nd.edu/user/p/psoga/.conda/envs/gnn/lib/python3.10/logging/__init__.py", line 1104, in emit
    self.flush()
  File "/afs/crc.nd.edu/user/p/psoga/.conda/envs/gnn/lib/python3.10/logging/__init__.py", line 1084, in flush
    self.stream.flush()
OSError: [Errno 5] Input/output error
Call stack:
  File "/afs/crc.nd.edu/user/p/psoga/benchmarking-gnns/main_SBMs_node_classification.py", line 382, in <module>
    net_params['in_dim'] = torch.unique(dataset.train[0][0].ndata['feat'],dim=0).size(0) # node_dim (feat is an integer)
  File "/afs/crc.nd.edu/user/p/psoga/benchmarking-gnns/main_SBMs_node_classification.py", line 380, in main
    dataset.test.spatial_pos_lists = []
  File "/afs/crc.nd.edu/user/p/psoga/benchmarking-gnns/main_SBMs_node_classification.py", line 231, in train_val_pipeline
    # writer.add_scalar('train/_loss', epoch_train_loss, epoch)
Message: '\tTime: 142.00s, LR: 0.00001, Train Loss: 0.3623, Train Acc: 83.6576,\n                            Val Loss: 0.3636, Val Acc: 83.5681, Test Acc: 83.6659'
Arguments: ()
--- Logging error ---
Traceback (most recent call last):
  File "/afs/crc.nd.edu/user/p/psoga/.conda/envs/gnn/lib/python3.10/logging/__init__.py", line 1104, in emit
    self.flush()
  File "/afs/crc.nd.edu/user/p/psoga/.conda/envs/gnn/lib/python3.10/logging/__init__.py", line 1084, in flush
    self.stream.flush()
OSError: [Errno 5] Input/output error
Call stack:
  File "/afs/crc.nd.edu/user/p/psoga/benchmarking-gnns/main_SBMs_node_classification.py", line 382, in <module>
    net_params['in_dim'] = torch.unique(dataset.train[0][0].ndata['feat'],dim=0).size(0) # node_dim (feat is an integer)
  File "/afs/crc.nd.edu/user/p/psoga/benchmarking-gnns/main_SBMs_node_classification.py", line 380, in main
    dataset.test.spatial_pos_lists = []
  File "/afs/crc.nd.edu/user/p/psoga/benchmarking-gnns/main_SBMs_node_classification.py", line 189, in train_val_pipeline
    else:
Message: 'Epoch 221/1000'
Arguments: ()
--- Logging error ---
Traceback (most recent call last):
  File "/afs/crc.nd.edu/user/p/psoga/.conda/envs/gnn/lib/python3.10/logging/__init__.py", line 1104, in emit
    self.flush()
  File "/afs/crc.nd.edu/user/p/psoga/.conda/envs/gnn/lib/python3.10/logging/__init__.py", line 1084, in flush
    self.stream.flush()
OSError: [Errno 5] Input/output error
Call stack:
  File "/afs/crc.nd.edu/user/p/psoga/benchmarking-gnns/main_SBMs_node_classification.py", line 382, in <module>
    net_params['in_dim'] = torch.unique(dataset.train[0][0].ndata['feat'],dim=0).size(0) # node_dim (feat is an integer)
  File "/afs/crc.nd.edu/user/p/psoga/benchmarking-gnns/main_SBMs_node_classification.py", line 380, in main
    dataset.test.spatial_pos_lists = []
  File "/afs/crc.nd.edu/user/p/psoga/benchmarking-gnns/main_SBMs_node_classification.py", line 231, in train_val_pipeline
    # writer.add_scalar('train/_loss', epoch_train_loss, epoch)
Message: '\tTime: 141.81s, LR: 0.00001, Train Loss: 0.3623, Train Acc: 83.6397,\n                            Val Loss: 0.3630, Val Acc: 83.6503, Test Acc: 83.7074'
Arguments: ()
--- Logging error ---
Traceback (most recent call last):
  File "/afs/crc.nd.edu/user/p/psoga/.conda/envs/gnn/lib/python3.10/logging/__init__.py", line 1104, in emit
    self.flush()
  File "/afs/crc.nd.edu/user/p/psoga/.conda/envs/gnn/lib/python3.10/logging/__init__.py", line 1084, in flush
    self.stream.flush()
OSError: [Errno 5] Input/output error
Call stack:
  File "/afs/crc.nd.edu/user/p/psoga/benchmarking-gnns/main_SBMs_node_classification.py", line 382, in <module>
    net_params['in_dim'] = torch.unique(dataset.train[0][0].ndata['feat'],dim=0).size(0) # node_dim (feat is an integer)
  File "/afs/crc.nd.edu/user/p/psoga/benchmarking-gnns/main_SBMs_node_classification.py", line 380, in main
    dataset.test.spatial_pos_lists = []
  File "/afs/crc.nd.edu/user/p/psoga/benchmarking-gnns/main_SBMs_node_classification.py", line 189, in train_val_pipeline
    else:
Message: 'Epoch 222/1000'
Arguments: ()
--- Logging error ---
Traceback (most recent call last):
  File "/afs/crc.nd.edu/user/p/psoga/.conda/envs/gnn/lib/python3.10/logging/__init__.py", line 1104, in emit
    self.flush()
  File "/afs/crc.nd.edu/user/p/psoga/.conda/envs/gnn/lib/python3.10/logging/__init__.py", line 1084, in flush
    self.stream.flush()
OSError: [Errno 5] Input/output error
Call stack:
  File "/afs/crc.nd.edu/user/p/psoga/benchmarking-gnns/main_SBMs_node_classification.py", line 382, in <module>
    net_params['in_dim'] = torch.unique(dataset.train[0][0].ndata['feat'],dim=0).size(0) # node_dim (feat is an integer)
  File "/afs/crc.nd.edu/user/p/psoga/benchmarking-gnns/main_SBMs_node_classification.py", line 380, in main
    dataset.test.spatial_pos_lists = []
  File "/afs/crc.nd.edu/user/p/psoga/benchmarking-gnns/main_SBMs_node_classification.py", line 231, in train_val_pipeline
    # writer.add_scalar('train/_loss', epoch_train_loss, epoch)
Message: '\tTime: 142.13s, LR: 0.00001, Train Loss: 0.3622, Train Acc: 83.6403,\n                            Val Loss: 0.3638, Val Acc: 83.5805, Test Acc: 83.6275'
Arguments: ()
--- Logging error ---
Traceback (most recent call last):
  File "/afs/crc.nd.edu/user/p/psoga/.conda/envs/gnn/lib/python3.10/logging/__init__.py", line 1104, in emit
    self.flush()
  File "/afs/crc.nd.edu/user/p/psoga/.conda/envs/gnn/lib/python3.10/logging/__init__.py", line 1084, in flush
    self.stream.flush()
OSError: [Errno 5] Input/output error
Call stack:
  File "/afs/crc.nd.edu/user/p/psoga/benchmarking-gnns/main_SBMs_node_classification.py", line 382, in <module>
    net_params['in_dim'] = torch.unique(dataset.train[0][0].ndata['feat'],dim=0).size(0) # node_dim (feat is an integer)
  File "/afs/crc.nd.edu/user/p/psoga/benchmarking-gnns/main_SBMs_node_classification.py", line 380, in main
    dataset.test.spatial_pos_lists = []
  File "/afs/crc.nd.edu/user/p/psoga/benchmarking-gnns/main_SBMs_node_classification.py", line 189, in train_val_pipeline
    else:
Message: 'Epoch 223/1000'
Arguments: ()
--- Logging error ---
Traceback (most recent call last):
  File "/afs/crc.nd.edu/user/p/psoga/.conda/envs/gnn/lib/python3.10/logging/__init__.py", line 1104, in emit
    self.flush()
  File "/afs/crc.nd.edu/user/p/psoga/.conda/envs/gnn/lib/python3.10/logging/__init__.py", line 1084, in flush
    self.stream.flush()
OSError: [Errno 5] Input/output error
Call stack:
  File "/afs/crc.nd.edu/user/p/psoga/benchmarking-gnns/main_SBMs_node_classification.py", line 382, in <module>
    net_params['in_dim'] = torch.unique(dataset.train[0][0].ndata['feat'],dim=0).size(0) # node_dim (feat is an integer)
  File "/afs/crc.nd.edu/user/p/psoga/benchmarking-gnns/main_SBMs_node_classification.py", line 380, in main
    dataset.test.spatial_pos_lists = []
  File "/afs/crc.nd.edu/user/p/psoga/benchmarking-gnns/main_SBMs_node_classification.py", line 231, in train_val_pipeline
    # writer.add_scalar('train/_loss', epoch_train_loss, epoch)
Message: '\tTime: 141.67s, LR: 0.00001, Train Loss: 0.3622, Train Acc: 83.6342,\n                            Val Loss: 0.3635, Val Acc: 83.5862, Test Acc: 83.6687'
Arguments: ()
--- Logging error ---
Traceback (most recent call last):
  File "/afs/crc.nd.edu/user/p/psoga/.conda/envs/gnn/lib/python3.10/logging/__init__.py", line 1104, in emit
    self.flush()
  File "/afs/crc.nd.edu/user/p/psoga/.conda/envs/gnn/lib/python3.10/logging/__init__.py", line 1084, in flush
    self.stream.flush()
OSError: [Errno 5] Input/output error
Call stack:
  File "/afs/crc.nd.edu/user/p/psoga/benchmarking-gnns/main_SBMs_node_classification.py", line 382, in <module>
    net_params['in_dim'] = torch.unique(dataset.train[0][0].ndata['feat'],dim=0).size(0) # node_dim (feat is an integer)
  File "/afs/crc.nd.edu/user/p/psoga/benchmarking-gnns/main_SBMs_node_classification.py", line 380, in main
    dataset.test.spatial_pos_lists = []
  File "/afs/crc.nd.edu/user/p/psoga/benchmarking-gnns/main_SBMs_node_classification.py", line 189, in train_val_pipeline
    else:
Message: 'Epoch 224/1000'
Arguments: ()
--- Logging error ---
Traceback (most recent call last):
  File "/afs/crc.nd.edu/user/p/psoga/.conda/envs/gnn/lib/python3.10/logging/__init__.py", line 1104, in emit
    self.flush()
  File "/afs/crc.nd.edu/user/p/psoga/.conda/envs/gnn/lib/python3.10/logging/__init__.py", line 1084, in flush
    self.stream.flush()
OSError: [Errno 5] Input/output error
Call stack:
  File "/afs/crc.nd.edu/user/p/psoga/benchmarking-gnns/main_SBMs_node_classification.py", line 382, in <module>
    net_params['in_dim'] = torch.unique(dataset.train[0][0].ndata['feat'],dim=0).size(0) # node_dim (feat is an integer)
  File "/afs/crc.nd.edu/user/p/psoga/benchmarking-gnns/main_SBMs_node_classification.py", line 380, in main
    dataset.test.spatial_pos_lists = []
  File "/afs/crc.nd.edu/user/p/psoga/benchmarking-gnns/main_SBMs_node_classification.py", line 231, in train_val_pipeline
    # writer.add_scalar('train/_loss', epoch_train_loss, epoch)
Message: '\tTime: 141.90s, LR: 0.00001, Train Loss: 0.3620, Train Acc: 83.6502,\n                            Val Loss: 0.3625, Val Acc: 83.6293, Test Acc: 83.6905'
Arguments: ()
--- Logging error ---
Traceback (most recent call last):
  File "/afs/crc.nd.edu/user/p/psoga/.conda/envs/gnn/lib/python3.10/logging/__init__.py", line 1104, in emit
    self.flush()
  File "/afs/crc.nd.edu/user/p/psoga/.conda/envs/gnn/lib/python3.10/logging/__init__.py", line 1084, in flush
    self.stream.flush()
OSError: [Errno 5] Input/output error
Call stack:
  File "/afs/crc.nd.edu/user/p/psoga/benchmarking-gnns/main_SBMs_node_classification.py", line 382, in <module>
    net_params['in_dim'] = torch.unique(dataset.train[0][0].ndata['feat'],dim=0).size(0) # node_dim (feat is an integer)
  File "/afs/crc.nd.edu/user/p/psoga/benchmarking-gnns/main_SBMs_node_classification.py", line 380, in main
    dataset.test.spatial_pos_lists = []
  File "/afs/crc.nd.edu/user/p/psoga/benchmarking-gnns/main_SBMs_node_classification.py", line 189, in train_val_pipeline
    else:
Message: 'Epoch 225/1000'
Arguments: ()
--- Logging error ---
Traceback (most recent call last):
  File "/afs/crc.nd.edu/user/p/psoga/.conda/envs/gnn/lib/python3.10/logging/__init__.py", line 1104, in emit
    self.flush()
  File "/afs/crc.nd.edu/user/p/psoga/.conda/envs/gnn/lib/python3.10/logging/__init__.py", line 1084, in flush
    self.stream.flush()
OSError: [Errno 5] Input/output error
Call stack:
  File "/afs/crc.nd.edu/user/p/psoga/benchmarking-gnns/main_SBMs_node_classification.py", line 382, in <module>
    net_params['in_dim'] = torch.unique(dataset.train[0][0].ndata['feat'],dim=0).size(0) # node_dim (feat is an integer)
  File "/afs/crc.nd.edu/user/p/psoga/benchmarking-gnns/main_SBMs_node_classification.py", line 380, in main
    dataset.test.spatial_pos_lists = []
  File "/afs/crc.nd.edu/user/p/psoga/benchmarking-gnns/main_SBMs_node_classification.py", line 231, in train_val_pipeline
    # writer.add_scalar('train/_loss', epoch_train_loss, epoch)
Message: '\tTime: 142.21s, LR: 0.00001, Train Loss: 0.3620, Train Acc: 83.6386,\n                            Val Loss: 0.3630, Val Acc: 83.5984, Test Acc: 83.6817'
Arguments: ()
--- Logging error ---
Traceback (most recent call last):
  File "/afs/crc.nd.edu/user/p/psoga/.conda/envs/gnn/lib/python3.10/logging/__init__.py", line 1104, in emit
    self.flush()
  File "/afs/crc.nd.edu/user/p/psoga/.conda/envs/gnn/lib/python3.10/logging/__init__.py", line 1084, in flush
    self.stream.flush()
OSError: [Errno 5] Input/output error
Call stack:
  File "/afs/crc.nd.edu/user/p/psoga/benchmarking-gnns/main_SBMs_node_classification.py", line 382, in <module>
    net_params['in_dim'] = torch.unique(dataset.train[0][0].ndata['feat'],dim=0).size(0) # node_dim (feat is an integer)
  File "/afs/crc.nd.edu/user/p/psoga/benchmarking-gnns/main_SBMs_node_classification.py", line 380, in main
    dataset.test.spatial_pos_lists = []
  File "/afs/crc.nd.edu/user/p/psoga/benchmarking-gnns/main_SBMs_node_classification.py", line 189, in train_val_pipeline
    else:
Message: 'Epoch 226/1000'
Arguments: ()
--- Logging error ---
Traceback (most recent call last):
  File "/afs/crc.nd.edu/user/p/psoga/.conda/envs/gnn/lib/python3.10/logging/__init__.py", line 1104, in emit
    self.flush()
  File "/afs/crc.nd.edu/user/p/psoga/.conda/envs/gnn/lib/python3.10/logging/__init__.py", line 1084, in flush
    self.stream.flush()
OSError: [Errno 5] Input/output error
Call stack:
  File "/afs/crc.nd.edu/user/p/psoga/benchmarking-gnns/main_SBMs_node_classification.py", line 382, in <module>
    net_params['in_dim'] = torch.unique(dataset.train[0][0].ndata['feat'],dim=0).size(0) # node_dim (feat is an integer)
  File "/afs/crc.nd.edu/user/p/psoga/benchmarking-gnns/main_SBMs_node_classification.py", line 380, in main
    dataset.test.spatial_pos_lists = []
  File "/afs/crc.nd.edu/user/p/psoga/benchmarking-gnns/main_SBMs_node_classification.py", line 231, in train_val_pipeline
    # writer.add_scalar('train/_loss', epoch_train_loss, epoch)
Message: '\tTime: 142.22s, LR: 0.00001, Train Loss: 0.3622, Train Acc: 83.6574,\n                            Val Loss: 0.3632, Val Acc: 83.5379, Test Acc: 83.7222'
Arguments: ()
--- Logging error ---
Traceback (most recent call last):
  File "/afs/crc.nd.edu/user/p/psoga/.conda/envs/gnn/lib/python3.10/logging/__init__.py", line 1104, in emit
    self.flush()
  File "/afs/crc.nd.edu/user/p/psoga/.conda/envs/gnn/lib/python3.10/logging/__init__.py", line 1084, in flush
    self.stream.flush()
OSError: [Errno 5] Input/output error
Call stack:
  File "/afs/crc.nd.edu/user/p/psoga/benchmarking-gnns/main_SBMs_node_classification.py", line 382, in <module>
    net_params['in_dim'] = torch.unique(dataset.train[0][0].ndata['feat'],dim=0).size(0) # node_dim (feat is an integer)
  File "/afs/crc.nd.edu/user/p/psoga/benchmarking-gnns/main_SBMs_node_classification.py", line 380, in main
    dataset.test.spatial_pos_lists = []
  File "/afs/crc.nd.edu/user/p/psoga/benchmarking-gnns/main_SBMs_node_classification.py", line 189, in train_val_pipeline
    else:
Message: 'Epoch 227/1000'
Arguments: ()
--- Logging error ---
Traceback (most recent call last):
  File "/afs/crc.nd.edu/user/p/psoga/.conda/envs/gnn/lib/python3.10/logging/__init__.py", line 1104, in emit
    self.flush()
  File "/afs/crc.nd.edu/user/p/psoga/.conda/envs/gnn/lib/python3.10/logging/__init__.py", line 1084, in flush
    self.stream.flush()
OSError: [Errno 5] Input/output error
Call stack:
  File "/afs/crc.nd.edu/user/p/psoga/benchmarking-gnns/main_SBMs_node_classification.py", line 382, in <module>
    net_params['in_dim'] = torch.unique(dataset.train[0][0].ndata['feat'],dim=0).size(0) # node_dim (feat is an integer)
  File "/afs/crc.nd.edu/user/p/psoga/benchmarking-gnns/main_SBMs_node_classification.py", line 380, in main
    dataset.test.spatial_pos_lists = []
  File "/afs/crc.nd.edu/user/p/psoga/benchmarking-gnns/main_SBMs_node_classification.py", line 231, in train_val_pipeline
    # writer.add_scalar('train/_loss', epoch_train_loss, epoch)
Message: '\tTime: 141.73s, LR: 0.00001, Train Loss: 0.3622, Train Acc: 83.6575,\n                            Val Loss: 0.3631, Val Acc: 83.5623, Test Acc: 83.7525'
Arguments: ()
--- Logging error ---
Traceback (most recent call last):
  File "/afs/crc.nd.edu/user/p/psoga/.conda/envs/gnn/lib/python3.10/logging/__init__.py", line 1104, in emit
    self.flush()
  File "/afs/crc.nd.edu/user/p/psoga/.conda/envs/gnn/lib/python3.10/logging/__init__.py", line 1084, in flush
    self.stream.flush()
OSError: [Errno 5] Input/output error
Call stack:
  File "/afs/crc.nd.edu/user/p/psoga/benchmarking-gnns/main_SBMs_node_classification.py", line 382, in <module>
    net_params['in_dim'] = torch.unique(dataset.train[0][0].ndata['feat'],dim=0).size(0) # node_dim (feat is an integer)
  File "/afs/crc.nd.edu/user/p/psoga/benchmarking-gnns/main_SBMs_node_classification.py", line 380, in main
    dataset.test.spatial_pos_lists = []
  File "/afs/crc.nd.edu/user/p/psoga/benchmarking-gnns/main_SBMs_node_classification.py", line 189, in train_val_pipeline
    else:
Message: 'Epoch 228/1000'
Arguments: ()
--- Logging error ---
Traceback (most recent call last):
  File "/afs/crc.nd.edu/user/p/psoga/.conda/envs/gnn/lib/python3.10/logging/__init__.py", line 1104, in emit
    self.flush()
  File "/afs/crc.nd.edu/user/p/psoga/.conda/envs/gnn/lib/python3.10/logging/__init__.py", line 1084, in flush
    self.stream.flush()
OSError: [Errno 5] Input/output error
Call stack:
  File "/afs/crc.nd.edu/user/p/psoga/benchmarking-gnns/main_SBMs_node_classification.py", line 382, in <module>
    net_params['in_dim'] = torch.unique(dataset.train[0][0].ndata['feat'],dim=0).size(0) # node_dim (feat is an integer)
  File "/afs/crc.nd.edu/user/p/psoga/benchmarking-gnns/main_SBMs_node_classification.py", line 380, in main
    dataset.test.spatial_pos_lists = []
  File "/afs/crc.nd.edu/user/p/psoga/benchmarking-gnns/main_SBMs_node_classification.py", line 231, in train_val_pipeline
    # writer.add_scalar('train/_loss', epoch_train_loss, epoch)
Message: '\tTime: 142.39s, LR: 0.00001, Train Loss: 0.3616, Train Acc: 83.6615,\n                            Val Loss: 0.3643, Val Acc: 83.4356, Test Acc: 83.6499'
Arguments: ()
--- Logging error ---
Traceback (most recent call last):
  File "/afs/crc.nd.edu/user/p/psoga/.conda/envs/gnn/lib/python3.10/logging/__init__.py", line 1104, in emit
    self.flush()
  File "/afs/crc.nd.edu/user/p/psoga/.conda/envs/gnn/lib/python3.10/logging/__init__.py", line 1084, in flush
    self.stream.flush()
OSError: [Errno 5] Input/output error
Call stack:
  File "/afs/crc.nd.edu/user/p/psoga/benchmarking-gnns/main_SBMs_node_classification.py", line 382, in <module>
    net_params['in_dim'] = torch.unique(dataset.train[0][0].ndata['feat'],dim=0).size(0) # node_dim (feat is an integer)
  File "/afs/crc.nd.edu/user/p/psoga/benchmarking-gnns/main_SBMs_node_classification.py", line 380, in main
    dataset.test.spatial_pos_lists = []
  File "/afs/crc.nd.edu/user/p/psoga/benchmarking-gnns/main_SBMs_node_classification.py", line 189, in train_val_pipeline
    else:
Message: 'Epoch 229/1000'
Arguments: ()
--- Logging error ---
Traceback (most recent call last):
  File "/afs/crc.nd.edu/user/p/psoga/.conda/envs/gnn/lib/python3.10/logging/__init__.py", line 1104, in emit
    self.flush()
  File "/afs/crc.nd.edu/user/p/psoga/.conda/envs/gnn/lib/python3.10/logging/__init__.py", line 1084, in flush
    self.stream.flush()
OSError: [Errno 5] Input/output error
Call stack:
  File "/afs/crc.nd.edu/user/p/psoga/benchmarking-gnns/main_SBMs_node_classification.py", line 382, in <module>
    net_params['in_dim'] = torch.unique(dataset.train[0][0].ndata['feat'],dim=0).size(0) # node_dim (feat is an integer)
  File "/afs/crc.nd.edu/user/p/psoga/benchmarking-gnns/main_SBMs_node_classification.py", line 380, in main
    dataset.test.spatial_pos_lists = []
  File "/afs/crc.nd.edu/user/p/psoga/benchmarking-gnns/main_SBMs_node_classification.py", line 231, in train_val_pipeline
    # writer.add_scalar('train/_loss', epoch_train_loss, epoch)
Message: '\tTime: 140.37s, LR: 0.00001, Train Loss: 0.3620, Train Acc: 83.6377,\n                            Val Loss: 0.3639, Val Acc: 83.5027, Test Acc: 83.6489'
Arguments: ()
--- Logging error ---
Traceback (most recent call last):
  File "/afs/crc.nd.edu/user/p/psoga/.conda/envs/gnn/lib/python3.10/logging/__init__.py", line 1104, in emit
    self.flush()
  File "/afs/crc.nd.edu/user/p/psoga/.conda/envs/gnn/lib/python3.10/logging/__init__.py", line 1084, in flush
    self.stream.flush()
OSError: [Errno 5] Input/output error
Call stack:
  File "/afs/crc.nd.edu/user/p/psoga/benchmarking-gnns/main_SBMs_node_classification.py", line 382, in <module>
    net_params['in_dim'] = torch.unique(dataset.train[0][0].ndata['feat'],dim=0).size(0) # node_dim (feat is an integer)
  File "/afs/crc.nd.edu/user/p/psoga/benchmarking-gnns/main_SBMs_node_classification.py", line 380, in main
    dataset.test.spatial_pos_lists = []
  File "/afs/crc.nd.edu/user/p/psoga/benchmarking-gnns/main_SBMs_node_classification.py", line 189, in train_val_pipeline
    else:
Message: 'Epoch 230/1000'
Arguments: ()
--- Logging error ---
Traceback (most recent call last):
  File "/afs/crc.nd.edu/user/p/psoga/.conda/envs/gnn/lib/python3.10/logging/__init__.py", line 1104, in emit
    self.flush()
  File "/afs/crc.nd.edu/user/p/psoga/.conda/envs/gnn/lib/python3.10/logging/__init__.py", line 1084, in flush
    self.stream.flush()
OSError: [Errno 5] Input/output error
Call stack:
  File "/afs/crc.nd.edu/user/p/psoga/benchmarking-gnns/main_SBMs_node_classification.py", line 382, in <module>
    net_params['in_dim'] = torch.unique(dataset.train[0][0].ndata['feat'],dim=0).size(0) # node_dim (feat is an integer)
  File "/afs/crc.nd.edu/user/p/psoga/benchmarking-gnns/main_SBMs_node_classification.py", line 380, in main
    dataset.test.spatial_pos_lists = []
  File "/afs/crc.nd.edu/user/p/psoga/benchmarking-gnns/main_SBMs_node_classification.py", line 231, in train_val_pipeline
    # writer.add_scalar('train/_loss', epoch_train_loss, epoch)
Message: '\tTime: 138.60s, LR: 0.00001, Train Loss: 0.3622, Train Acc: 83.6041,\n                            Val Loss: 0.3643, Val Acc: 83.3952, Test Acc: 83.5776'
Arguments: ()
--- Logging error ---
Traceback (most recent call last):
  File "/afs/crc.nd.edu/user/p/psoga/.conda/envs/gnn/lib/python3.10/logging/__init__.py", line 1104, in emit
    self.flush()
  File "/afs/crc.nd.edu/user/p/psoga/.conda/envs/gnn/lib/python3.10/logging/__init__.py", line 1084, in flush
    self.stream.flush()
OSError: [Errno 5] Input/output error
Call stack:
  File "/afs/crc.nd.edu/user/p/psoga/benchmarking-gnns/main_SBMs_node_classification.py", line 382, in <module>
    net_params['in_dim'] = torch.unique(dataset.train[0][0].ndata['feat'],dim=0).size(0) # node_dim (feat is an integer)
  File "/afs/crc.nd.edu/user/p/psoga/benchmarking-gnns/main_SBMs_node_classification.py", line 380, in main
    dataset.test.spatial_pos_lists = []
  File "/afs/crc.nd.edu/user/p/psoga/benchmarking-gnns/main_SBMs_node_classification.py", line 189, in train_val_pipeline
    else:
Message: 'Epoch 231/1000'
Arguments: ()
--- Logging error ---
Traceback (most recent call last):
  File "/afs/crc.nd.edu/user/p/psoga/.conda/envs/gnn/lib/python3.10/logging/__init__.py", line 1104, in emit
    self.flush()
  File "/afs/crc.nd.edu/user/p/psoga/.conda/envs/gnn/lib/python3.10/logging/__init__.py", line 1084, in flush
    self.stream.flush()
OSError: [Errno 5] Input/output error
Call stack:
  File "/afs/crc.nd.edu/user/p/psoga/benchmarking-gnns/main_SBMs_node_classification.py", line 382, in <module>
    net_params['in_dim'] = torch.unique(dataset.train[0][0].ndata['feat'],dim=0).size(0) # node_dim (feat is an integer)
  File "/afs/crc.nd.edu/user/p/psoga/benchmarking-gnns/main_SBMs_node_classification.py", line 380, in main
    dataset.test.spatial_pos_lists = []
  File "/afs/crc.nd.edu/user/p/psoga/benchmarking-gnns/main_SBMs_node_classification.py", line 231, in train_val_pipeline
    # writer.add_scalar('train/_loss', epoch_train_loss, epoch)
Message: '\tTime: 138.25s, LR: 0.00001, Train Loss: 0.3620, Train Acc: 83.6287,\n                            Val Loss: 0.3627, Val Acc: 83.6269, Test Acc: 83.6985'
Arguments: ()
--- Logging error ---
Traceback (most recent call last):
  File "/afs/crc.nd.edu/user/p/psoga/.conda/envs/gnn/lib/python3.10/logging/__init__.py", line 1104, in emit
    self.flush()
  File "/afs/crc.nd.edu/user/p/psoga/.conda/envs/gnn/lib/python3.10/logging/__init__.py", line 1084, in flush
    self.stream.flush()
OSError: [Errno 5] Input/output error
Call stack:
  File "/afs/crc.nd.edu/user/p/psoga/benchmarking-gnns/main_SBMs_node_classification.py", line 382, in <module>
    net_params['in_dim'] = torch.unique(dataset.train[0][0].ndata['feat'],dim=0).size(0) # node_dim (feat is an integer)
  File "/afs/crc.nd.edu/user/p/psoga/benchmarking-gnns/main_SBMs_node_classification.py", line 380, in main
    dataset.test.spatial_pos_lists = []
  File "/afs/crc.nd.edu/user/p/psoga/benchmarking-gnns/main_SBMs_node_classification.py", line 189, in train_val_pipeline
    else:
Message: 'Epoch 232/1000'
Arguments: ()
--- Logging error ---
Traceback (most recent call last):
  File "/afs/crc.nd.edu/user/p/psoga/.conda/envs/gnn/lib/python3.10/logging/__init__.py", line 1104, in emit
    self.flush()
  File "/afs/crc.nd.edu/user/p/psoga/.conda/envs/gnn/lib/python3.10/logging/__init__.py", line 1084, in flush
    self.stream.flush()
OSError: [Errno 5] Input/output error
Call stack:
  File "/afs/crc.nd.edu/user/p/psoga/benchmarking-gnns/main_SBMs_node_classification.py", line 382, in <module>
    net_params['in_dim'] = torch.unique(dataset.train[0][0].ndata['feat'],dim=0).size(0) # node_dim (feat is an integer)
  File "/afs/crc.nd.edu/user/p/psoga/benchmarking-gnns/main_SBMs_node_classification.py", line 380, in main
    dataset.test.spatial_pos_lists = []
  File "/afs/crc.nd.edu/user/p/psoga/benchmarking-gnns/main_SBMs_node_classification.py", line 231, in train_val_pipeline
    # writer.add_scalar('train/_loss', epoch_train_loss, epoch)
Message: '\tTime: 138.76s, LR: 0.00001, Train Loss: 0.3619, Train Acc: 83.6467,\n                            Val Loss: 0.3633, Val Acc: 83.5583, Test Acc: 83.6701'
Arguments: ()
--- Logging error ---
Traceback (most recent call last):
  File "/afs/crc.nd.edu/user/p/psoga/.conda/envs/gnn/lib/python3.10/logging/__init__.py", line 1104, in emit
    self.flush()
  File "/afs/crc.nd.edu/user/p/psoga/.conda/envs/gnn/lib/python3.10/logging/__init__.py", line 1084, in flush
    self.stream.flush()
OSError: [Errno 5] Input/output error
Call stack:
  File "/afs/crc.nd.edu/user/p/psoga/benchmarking-gnns/main_SBMs_node_classification.py", line 382, in <module>
    net_params['in_dim'] = torch.unique(dataset.train[0][0].ndata['feat'],dim=0).size(0) # node_dim (feat is an integer)
  File "/afs/crc.nd.edu/user/p/psoga/benchmarking-gnns/main_SBMs_node_classification.py", line 380, in main
    dataset.test.spatial_pos_lists = []
  File "/afs/crc.nd.edu/user/p/psoga/benchmarking-gnns/main_SBMs_node_classification.py", line 189, in train_val_pipeline
    else:
Message: 'Epoch 233/1000'
Arguments: ()
--- Logging error ---
Traceback (most recent call last):
  File "/afs/crc.nd.edu/user/p/psoga/.conda/envs/gnn/lib/python3.10/logging/__init__.py", line 1104, in emit
    self.flush()
  File "/afs/crc.nd.edu/user/p/psoga/.conda/envs/gnn/lib/python3.10/logging/__init__.py", line 1084, in flush
    self.stream.flush()
OSError: [Errno 5] Input/output error
Call stack:
  File "/afs/crc.nd.edu/user/p/psoga/benchmarking-gnns/main_SBMs_node_classification.py", line 382, in <module>
    net_params['in_dim'] = torch.unique(dataset.train[0][0].ndata['feat'],dim=0).size(0) # node_dim (feat is an integer)
  File "/afs/crc.nd.edu/user/p/psoga/benchmarking-gnns/main_SBMs_node_classification.py", line 380, in main
    dataset.test.spatial_pos_lists = []
  File "/afs/crc.nd.edu/user/p/psoga/benchmarking-gnns/main_SBMs_node_classification.py", line 209, in train_val_pipeline
    epoch_train_loss, epoch_train_acc, optimizer = train_epoch(model, optimizer, device, train_loader, epoch, params['batch_size'])
Message: 'Saving best model with test accuracy: 83.7665 to out/SBMs_node_classification_b26-500k-baseline-trialscheckpoints/GraphTransformer_SBM_PATTERN_GPU0_2_2_20h33m01s_on_Sep_20_2022/MODELS_'
Arguments: ()
--- Logging error ---
Traceback (most recent call last):
  File "/afs/crc.nd.edu/user/p/psoga/.conda/envs/gnn/lib/python3.10/logging/__init__.py", line 1104, in emit
    self.flush()
  File "/afs/crc.nd.edu/user/p/psoga/.conda/envs/gnn/lib/python3.10/logging/__init__.py", line 1084, in flush
    self.stream.flush()
OSError: [Errno 5] Input/output error
Call stack:
  File "/afs/crc.nd.edu/user/p/psoga/benchmarking-gnns/main_SBMs_node_classification.py", line 382, in <module>
    net_params['in_dim'] = torch.unique(dataset.train[0][0].ndata['feat'],dim=0).size(0) # node_dim (feat is an integer)
  File "/afs/crc.nd.edu/user/p/psoga/benchmarking-gnns/main_SBMs_node_classification.py", line 380, in main
    dataset.test.spatial_pos_lists = []
  File "/afs/crc.nd.edu/user/p/psoga/benchmarking-gnns/main_SBMs_node_classification.py", line 231, in train_val_pipeline
    # writer.add_scalar('train/_loss', epoch_train_loss, epoch)
Message: '\tTime: 138.27s, LR: 0.00001, Train Loss: 0.3618, Train Acc: 83.6868,\n                            Val Loss: 0.3630, Val Acc: 83.5250, Test Acc: 83.7665'
Arguments: ()
--- Logging error ---
Traceback (most recent call last):
  File "/afs/crc.nd.edu/user/p/psoga/.conda/envs/gnn/lib/python3.10/logging/__init__.py", line 1104, in emit
    self.flush()
  File "/afs/crc.nd.edu/user/p/psoga/.conda/envs/gnn/lib/python3.10/logging/__init__.py", line 1084, in flush
    self.stream.flush()
OSError: [Errno 5] Input/output error
Call stack:
  File "/afs/crc.nd.edu/user/p/psoga/benchmarking-gnns/main_SBMs_node_classification.py", line 382, in <module>
    net_params['in_dim'] = torch.unique(dataset.train[0][0].ndata['feat'],dim=0).size(0) # node_dim (feat is an integer)
  File "/afs/crc.nd.edu/user/p/psoga/benchmarking-gnns/main_SBMs_node_classification.py", line 380, in main
    dataset.test.spatial_pos_lists = []
  File "/afs/crc.nd.edu/user/p/psoga/benchmarking-gnns/main_SBMs_node_classification.py", line 189, in train_val_pipeline
    else:
Message: 'Epoch 234/1000'
Arguments: ()
--- Logging error ---
Traceback (most recent call last):
  File "/afs/crc.nd.edu/user/p/psoga/.conda/envs/gnn/lib/python3.10/logging/__init__.py", line 1104, in emit
    self.flush()
  File "/afs/crc.nd.edu/user/p/psoga/.conda/envs/gnn/lib/python3.10/logging/__init__.py", line 1084, in flush
    self.stream.flush()
OSError: [Errno 5] Input/output error
Call stack:
  File "/afs/crc.nd.edu/user/p/psoga/benchmarking-gnns/main_SBMs_node_classification.py", line 382, in <module>
    net_params['in_dim'] = torch.unique(dataset.train[0][0].ndata['feat'],dim=0).size(0) # node_dim (feat is an integer)
  File "/afs/crc.nd.edu/user/p/psoga/benchmarking-gnns/main_SBMs_node_classification.py", line 380, in main
    dataset.test.spatial_pos_lists = []
  File "/afs/crc.nd.edu/user/p/psoga/benchmarking-gnns/main_SBMs_node_classification.py", line 231, in train_val_pipeline
    # writer.add_scalar('train/_loss', epoch_train_loss, epoch)
Message: '\tTime: 138.22s, LR: 0.00001, Train Loss: 0.3615, Train Acc: 83.6857,\n                            Val Loss: 0.3631, Val Acc: 83.5741, Test Acc: 83.7397'
Arguments: ()
--- Logging error ---
Traceback (most recent call last):
  File "/afs/crc.nd.edu/user/p/psoga/.conda/envs/gnn/lib/python3.10/logging/__init__.py", line 1104, in emit
    self.flush()
  File "/afs/crc.nd.edu/user/p/psoga/.conda/envs/gnn/lib/python3.10/logging/__init__.py", line 1084, in flush
    self.stream.flush()
OSError: [Errno 5] Input/output error
Call stack:
  File "/afs/crc.nd.edu/user/p/psoga/benchmarking-gnns/main_SBMs_node_classification.py", line 382, in <module>
    net_params['in_dim'] = torch.unique(dataset.train[0][0].ndata['feat'],dim=0).size(0) # node_dim (feat is an integer)
  File "/afs/crc.nd.edu/user/p/psoga/benchmarking-gnns/main_SBMs_node_classification.py", line 380, in main
    dataset.test.spatial_pos_lists = []
  File "/afs/crc.nd.edu/user/p/psoga/benchmarking-gnns/main_SBMs_node_classification.py", line 189, in train_val_pipeline
    else:
Message: 'Epoch 235/1000'
Arguments: ()
--- Logging error ---
Traceback (most recent call last):
  File "/afs/crc.nd.edu/user/p/psoga/.conda/envs/gnn/lib/python3.10/logging/__init__.py", line 1104, in emit
    self.flush()
  File "/afs/crc.nd.edu/user/p/psoga/.conda/envs/gnn/lib/python3.10/logging/__init__.py", line 1084, in flush
    self.stream.flush()
OSError: [Errno 5] Input/output error
Call stack:
  File "/afs/crc.nd.edu/user/p/psoga/benchmarking-gnns/main_SBMs_node_classification.py", line 382, in <module>
    net_params['in_dim'] = torch.unique(dataset.train[0][0].ndata['feat'],dim=0).size(0) # node_dim (feat is an integer)
  File "/afs/crc.nd.edu/user/p/psoga/benchmarking-gnns/main_SBMs_node_classification.py", line 380, in main
    dataset.test.spatial_pos_lists = []
  File "/afs/crc.nd.edu/user/p/psoga/benchmarking-gnns/main_SBMs_node_classification.py", line 231, in train_val_pipeline
    # writer.add_scalar('train/_loss', epoch_train_loss, epoch)
Message: '\tTime: 138.18s, LR: 0.00001, Train Loss: 0.3624, Train Acc: 83.6335,\n                            Val Loss: 0.3633, Val Acc: 83.5770, Test Acc: 83.6764'
Arguments: ()
--- Logging error ---
Traceback (most recent call last):
  File "/afs/crc.nd.edu/user/p/psoga/.conda/envs/gnn/lib/python3.10/logging/__init__.py", line 1104, in emit
    self.flush()
  File "/afs/crc.nd.edu/user/p/psoga/.conda/envs/gnn/lib/python3.10/logging/__init__.py", line 1084, in flush
    self.stream.flush()
OSError: [Errno 5] Input/output error
Call stack:
  File "/afs/crc.nd.edu/user/p/psoga/benchmarking-gnns/main_SBMs_node_classification.py", line 382, in <module>
    net_params['in_dim'] = torch.unique(dataset.train[0][0].ndata['feat'],dim=0).size(0) # node_dim (feat is an integer)
  File "/afs/crc.nd.edu/user/p/psoga/benchmarking-gnns/main_SBMs_node_classification.py", line 380, in main
    dataset.test.spatial_pos_lists = []
  File "/afs/crc.nd.edu/user/p/psoga/benchmarking-gnns/main_SBMs_node_classification.py", line 189, in train_val_pipeline
    else:
Message: 'Epoch 236/1000'
Arguments: ()
--- Logging error ---
Traceback (most recent call last):
  File "/afs/crc.nd.edu/user/p/psoga/.conda/envs/gnn/lib/python3.10/logging/__init__.py", line 1104, in emit
    self.flush()
  File "/afs/crc.nd.edu/user/p/psoga/.conda/envs/gnn/lib/python3.10/logging/__init__.py", line 1084, in flush
    self.stream.flush()
OSError: [Errno 5] Input/output error
Call stack:
  File "/afs/crc.nd.edu/user/p/psoga/benchmarking-gnns/main_SBMs_node_classification.py", line 382, in <module>
    net_params['in_dim'] = torch.unique(dataset.train[0][0].ndata['feat'],dim=0).size(0) # node_dim (feat is an integer)
  File "/afs/crc.nd.edu/user/p/psoga/benchmarking-gnns/main_SBMs_node_classification.py", line 380, in main
    dataset.test.spatial_pos_lists = []
  File "/afs/crc.nd.edu/user/p/psoga/benchmarking-gnns/main_SBMs_node_classification.py", line 231, in train_val_pipeline
    # writer.add_scalar('train/_loss', epoch_train_loss, epoch)
Message: '\tTime: 138.28s, LR: 0.00000, Train Loss: 0.3623, Train Acc: 83.6241,\n                            Val Loss: 0.3628, Val Acc: 83.6165, Test Acc: 83.7029'
Arguments: ()
--- Logging error ---
Traceback (most recent call last):
  File "/afs/crc.nd.edu/user/p/psoga/.conda/envs/gnn/lib/python3.10/logging/__init__.py", line 1104, in emit
    self.flush()
  File "/afs/crc.nd.edu/user/p/psoga/.conda/envs/gnn/lib/python3.10/logging/__init__.py", line 1084, in flush
    self.stream.flush()
OSError: [Errno 5] Input/output error
Call stack:
  File "/afs/crc.nd.edu/user/p/psoga/benchmarking-gnns/main_SBMs_node_classification.py", line 382, in <module>
    net_params['in_dim'] = torch.unique(dataset.train[0][0].ndata['feat'],dim=0).size(0) # node_dim (feat is an integer)
  File "/afs/crc.nd.edu/user/p/psoga/benchmarking-gnns/main_SBMs_node_classification.py", line 380, in main
    dataset.test.spatial_pos_lists = []
  File "/afs/crc.nd.edu/user/p/psoga/benchmarking-gnns/main_SBMs_node_classification.py", line 189, in train_val_pipeline
    else:
Message: 'Epoch 237/1000'
Arguments: ()
--- Logging error ---
Traceback (most recent call last):
  File "/afs/crc.nd.edu/user/p/psoga/.conda/envs/gnn/lib/python3.10/logging/__init__.py", line 1104, in emit
    self.flush()
  File "/afs/crc.nd.edu/user/p/psoga/.conda/envs/gnn/lib/python3.10/logging/__init__.py", line 1084, in flush
    self.stream.flush()
OSError: [Errno 5] Input/output error
Call stack:
  File "/afs/crc.nd.edu/user/p/psoga/benchmarking-gnns/main_SBMs_node_classification.py", line 382, in <module>
    net_params['in_dim'] = torch.unique(dataset.train[0][0].ndata['feat'],dim=0).size(0) # node_dim (feat is an integer)
  File "/afs/crc.nd.edu/user/p/psoga/benchmarking-gnns/main_SBMs_node_classification.py", line 380, in main
    dataset.test.spatial_pos_lists = []
  File "/afs/crc.nd.edu/user/p/psoga/benchmarking-gnns/main_SBMs_node_classification.py", line 231, in train_val_pipeline
    # writer.add_scalar('train/_loss', epoch_train_loss, epoch)
Message: '\tTime: 138.05s, LR: 0.00000, Train Loss: 0.3622, Train Acc: 83.6332,\n                            Val Loss: 0.3628, Val Acc: 83.6156, Test Acc: 83.7063'
Arguments: ()
--- Logging error ---
Traceback (most recent call last):
  File "/afs/crc.nd.edu/user/p/psoga/.conda/envs/gnn/lib/python3.10/logging/__init__.py", line 1104, in emit
    self.flush()
  File "/afs/crc.nd.edu/user/p/psoga/.conda/envs/gnn/lib/python3.10/logging/__init__.py", line 1084, in flush
    self.stream.flush()
OSError: [Errno 5] Input/output error
Call stack:
  File "/afs/crc.nd.edu/user/p/psoga/benchmarking-gnns/main_SBMs_node_classification.py", line 382, in <module>
    net_params['in_dim'] = torch.unique(dataset.train[0][0].ndata['feat'],dim=0).size(0) # node_dim (feat is an integer)
  File "/afs/crc.nd.edu/user/p/psoga/benchmarking-gnns/main_SBMs_node_classification.py", line 380, in main
    dataset.test.spatial_pos_lists = []
  File "/afs/crc.nd.edu/user/p/psoga/benchmarking-gnns/main_SBMs_node_classification.py", line 189, in train_val_pipeline
    else:
Message: 'Epoch 238/1000'
Arguments: ()
--- Logging error ---
Traceback (most recent call last):
  File "/afs/crc.nd.edu/user/p/psoga/.conda/envs/gnn/lib/python3.10/logging/__init__.py", line 1104, in emit
    self.flush()
  File "/afs/crc.nd.edu/user/p/psoga/.conda/envs/gnn/lib/python3.10/logging/__init__.py", line 1084, in flush
    self.stream.flush()
OSError: [Errno 5] Input/output error
Call stack:
  File "/afs/crc.nd.edu/user/p/psoga/benchmarking-gnns/main_SBMs_node_classification.py", line 382, in <module>
    net_params['in_dim'] = torch.unique(dataset.train[0][0].ndata['feat'],dim=0).size(0) # node_dim (feat is an integer)
  File "/afs/crc.nd.edu/user/p/psoga/benchmarking-gnns/main_SBMs_node_classification.py", line 380, in main
    dataset.test.spatial_pos_lists = []
  File "/afs/crc.nd.edu/user/p/psoga/benchmarking-gnns/main_SBMs_node_classification.py", line 231, in train_val_pipeline
    # writer.add_scalar('train/_loss', epoch_train_loss, epoch)
Message: '\tTime: 138.31s, LR: 0.00000, Train Loss: 0.3621, Train Acc: 83.6603,\n                            Val Loss: 0.3628, Val Acc: 83.6106, Test Acc: 83.6792'
Arguments: ()
--- Logging error ---
Traceback (most recent call last):
  File "/afs/crc.nd.edu/user/p/psoga/.conda/envs/gnn/lib/python3.10/logging/__init__.py", line 1104, in emit
    self.flush()
  File "/afs/crc.nd.edu/user/p/psoga/.conda/envs/gnn/lib/python3.10/logging/__init__.py", line 1084, in flush
    self.stream.flush()
OSError: [Errno 5] Input/output error
Call stack:
  File "/afs/crc.nd.edu/user/p/psoga/benchmarking-gnns/main_SBMs_node_classification.py", line 382, in <module>
    net_params['in_dim'] = torch.unique(dataset.train[0][0].ndata['feat'],dim=0).size(0) # node_dim (feat is an integer)
  File "/afs/crc.nd.edu/user/p/psoga/benchmarking-gnns/main_SBMs_node_classification.py", line 380, in main
    dataset.test.spatial_pos_lists = []
  File "/afs/crc.nd.edu/user/p/psoga/benchmarking-gnns/main_SBMs_node_classification.py", line 189, in train_val_pipeline
    else:
Message: 'Epoch 239/1000'
Arguments: ()
--- Logging error ---
Traceback (most recent call last):
  File "/afs/crc.nd.edu/user/p/psoga/.conda/envs/gnn/lib/python3.10/logging/__init__.py", line 1104, in emit
    self.flush()
  File "/afs/crc.nd.edu/user/p/psoga/.conda/envs/gnn/lib/python3.10/logging/__init__.py", line 1084, in flush
    self.stream.flush()
OSError: [Errno 5] Input/output error
Call stack:
  File "/afs/crc.nd.edu/user/p/psoga/benchmarking-gnns/main_SBMs_node_classification.py", line 382, in <module>
    net_params['in_dim'] = torch.unique(dataset.train[0][0].ndata['feat'],dim=0).size(0) # node_dim (feat is an integer)
  File "/afs/crc.nd.edu/user/p/psoga/benchmarking-gnns/main_SBMs_node_classification.py", line 380, in main
    dataset.test.spatial_pos_lists = []
  File "/afs/crc.nd.edu/user/p/psoga/benchmarking-gnns/main_SBMs_node_classification.py", line 231, in train_val_pipeline
    # writer.add_scalar('train/_loss', epoch_train_loss, epoch)
Message: '\tTime: 137.97s, LR: 0.00000, Train Loss: 0.3616, Train Acc: 83.6648,\n                            Val Loss: 0.3623, Val Acc: 83.6596, Test Acc: 83.7296'
Arguments: ()
--- Logging error ---
Traceback (most recent call last):
  File "/afs/crc.nd.edu/user/p/psoga/.conda/envs/gnn/lib/python3.10/logging/__init__.py", line 1104, in emit
    self.flush()
  File "/afs/crc.nd.edu/user/p/psoga/.conda/envs/gnn/lib/python3.10/logging/__init__.py", line 1084, in flush
    self.stream.flush()
OSError: [Errno 5] Input/output error
Call stack:
  File "/afs/crc.nd.edu/user/p/psoga/benchmarking-gnns/main_SBMs_node_classification.py", line 382, in <module>
    net_params['in_dim'] = torch.unique(dataset.train[0][0].ndata['feat'],dim=0).size(0) # node_dim (feat is an integer)
  File "/afs/crc.nd.edu/user/p/psoga/benchmarking-gnns/main_SBMs_node_classification.py", line 380, in main
    dataset.test.spatial_pos_lists = []
  File "/afs/crc.nd.edu/user/p/psoga/benchmarking-gnns/main_SBMs_node_classification.py", line 189, in train_val_pipeline
    else:
Message: 'Epoch 240/1000'
Arguments: ()
--- Logging error ---
Traceback (most recent call last):
  File "/afs/crc.nd.edu/user/p/psoga/.conda/envs/gnn/lib/python3.10/logging/__init__.py", line 1104, in emit
    self.flush()
  File "/afs/crc.nd.edu/user/p/psoga/.conda/envs/gnn/lib/python3.10/logging/__init__.py", line 1084, in flush
    self.stream.flush()
OSError: [Errno 5] Input/output error
Call stack:
  File "/afs/crc.nd.edu/user/p/psoga/benchmarking-gnns/main_SBMs_node_classification.py", line 382, in <module>
    net_params['in_dim'] = torch.unique(dataset.train[0][0].ndata['feat'],dim=0).size(0) # node_dim (feat is an integer)
  File "/afs/crc.nd.edu/user/p/psoga/benchmarking-gnns/main_SBMs_node_classification.py", line 380, in main
    dataset.test.spatial_pos_lists = []
  File "/afs/crc.nd.edu/user/p/psoga/benchmarking-gnns/main_SBMs_node_classification.py", line 231, in train_val_pipeline
    # writer.add_scalar('train/_loss', epoch_train_loss, epoch)
Message: '\tTime: 138.11s, LR: 0.00000, Train Loss: 0.3616, Train Acc: 83.6800,\n                            Val Loss: 0.3623, Val Acc: 83.6826, Test Acc: 83.7508'
Arguments: ()
--- Logging error ---
Traceback (most recent call last):
  File "/afs/crc.nd.edu/user/p/psoga/.conda/envs/gnn/lib/python3.10/logging/__init__.py", line 1104, in emit
    self.flush()
  File "/afs/crc.nd.edu/user/p/psoga/.conda/envs/gnn/lib/python3.10/logging/__init__.py", line 1084, in flush
    self.stream.flush()
OSError: [Errno 5] Input/output error
Call stack:
  File "/afs/crc.nd.edu/user/p/psoga/benchmarking-gnns/main_SBMs_node_classification.py", line 382, in <module>
    net_params['in_dim'] = torch.unique(dataset.train[0][0].ndata['feat'],dim=0).size(0) # node_dim (feat is an integer)
  File "/afs/crc.nd.edu/user/p/psoga/benchmarking-gnns/main_SBMs_node_classification.py", line 380, in main
    dataset.test.spatial_pos_lists = []
  File "/afs/crc.nd.edu/user/p/psoga/benchmarking-gnns/main_SBMs_node_classification.py", line 189, in train_val_pipeline
    else:
Message: 'Epoch 241/1000'
Arguments: ()
--- Logging error ---
Traceback (most recent call last):
  File "/afs/crc.nd.edu/user/p/psoga/.conda/envs/gnn/lib/python3.10/logging/__init__.py", line 1104, in emit
    self.flush()
  File "/afs/crc.nd.edu/user/p/psoga/.conda/envs/gnn/lib/python3.10/logging/__init__.py", line 1084, in flush
    self.stream.flush()
OSError: [Errno 5] Input/output error
Call stack:
  File "/afs/crc.nd.edu/user/p/psoga/benchmarking-gnns/main_SBMs_node_classification.py", line 382, in <module>
    net_params['in_dim'] = torch.unique(dataset.train[0][0].ndata['feat'],dim=0).size(0) # node_dim (feat is an integer)
  File "/afs/crc.nd.edu/user/p/psoga/benchmarking-gnns/main_SBMs_node_classification.py", line 380, in main
    dataset.test.spatial_pos_lists = []
  File "/afs/crc.nd.edu/user/p/psoga/benchmarking-gnns/main_SBMs_node_classification.py", line 209, in train_val_pipeline
    epoch_train_loss, epoch_train_acc, optimizer = train_epoch(model, optimizer, device, train_loader, epoch, params['batch_size'])
Message: 'Saving best model with test accuracy: 83.7765 to out/SBMs_node_classification_b26-500k-baseline-trialscheckpoints/GraphTransformer_SBM_PATTERN_GPU0_2_2_20h33m01s_on_Sep_20_2022/MODELS_'
Arguments: ()
--- Logging error ---
Traceback (most recent call last):
  File "/afs/crc.nd.edu/user/p/psoga/.conda/envs/gnn/lib/python3.10/logging/__init__.py", line 1104, in emit
    self.flush()
  File "/afs/crc.nd.edu/user/p/psoga/.conda/envs/gnn/lib/python3.10/logging/__init__.py", line 1084, in flush
    self.stream.flush()
OSError: [Errno 5] Input/output error
Call stack:
  File "/afs/crc.nd.edu/user/p/psoga/benchmarking-gnns/main_SBMs_node_classification.py", line 382, in <module>
    net_params['in_dim'] = torch.unique(dataset.train[0][0].ndata['feat'],dim=0).size(0) # node_dim (feat is an integer)
  File "/afs/crc.nd.edu/user/p/psoga/benchmarking-gnns/main_SBMs_node_classification.py", line 380, in main
    dataset.test.spatial_pos_lists = []
  File "/afs/crc.nd.edu/user/p/psoga/benchmarking-gnns/main_SBMs_node_classification.py", line 231, in train_val_pipeline
    # writer.add_scalar('train/_loss', epoch_train_loss, epoch)
Message: '\tTime: 138.15s, LR: 0.00000, Train Loss: 0.3611, Train Acc: 83.6947,\n                            Val Loss: 0.3629, Val Acc: 83.5941, Test Acc: 83.7765'
Arguments: ()
--- Logging error ---
Traceback (most recent call last):
  File "/afs/crc.nd.edu/user/p/psoga/.conda/envs/gnn/lib/python3.10/logging/__init__.py", line 1104, in emit
    self.flush()
  File "/afs/crc.nd.edu/user/p/psoga/.conda/envs/gnn/lib/python3.10/logging/__init__.py", line 1084, in flush
    self.stream.flush()
OSError: [Errno 5] Input/output error
Call stack:
  File "/afs/crc.nd.edu/user/p/psoga/benchmarking-gnns/main_SBMs_node_classification.py", line 382, in <module>
    net_params['in_dim'] = torch.unique(dataset.train[0][0].ndata['feat'],dim=0).size(0) # node_dim (feat is an integer)
  File "/afs/crc.nd.edu/user/p/psoga/benchmarking-gnns/main_SBMs_node_classification.py", line 380, in main
    dataset.test.spatial_pos_lists = []
  File "/afs/crc.nd.edu/user/p/psoga/benchmarking-gnns/main_SBMs_node_classification.py", line 189, in train_val_pipeline
    else:
Message: 'Epoch 242/1000'
Arguments: ()
--- Logging error ---
Traceback (most recent call last):
  File "/afs/crc.nd.edu/user/p/psoga/.conda/envs/gnn/lib/python3.10/logging/__init__.py", line 1104, in emit
    self.flush()
  File "/afs/crc.nd.edu/user/p/psoga/.conda/envs/gnn/lib/python3.10/logging/__init__.py", line 1084, in flush
    self.stream.flush()
OSError: [Errno 5] Input/output error
Call stack:
  File "/afs/crc.nd.edu/user/p/psoga/benchmarking-gnns/main_SBMs_node_classification.py", line 382, in <module>
    net_params['in_dim'] = torch.unique(dataset.train[0][0].ndata['feat'],dim=0).size(0) # node_dim (feat is an integer)
  File "/afs/crc.nd.edu/user/p/psoga/benchmarking-gnns/main_SBMs_node_classification.py", line 380, in main
    dataset.test.spatial_pos_lists = []
  File "/afs/crc.nd.edu/user/p/psoga/benchmarking-gnns/main_SBMs_node_classification.py", line 231, in train_val_pipeline
    # writer.add_scalar('train/_loss', epoch_train_loss, epoch)
Message: '\tTime: 138.16s, LR: 0.00000, Train Loss: 0.3610, Train Acc: 83.7043,\n                            Val Loss: 0.3622, Val Acc: 83.5879, Test Acc: 83.7492'
Arguments: ()
--- Logging error ---
Traceback (most recent call last):
  File "/afs/crc.nd.edu/user/p/psoga/.conda/envs/gnn/lib/python3.10/logging/__init__.py", line 1104, in emit
    self.flush()
  File "/afs/crc.nd.edu/user/p/psoga/.conda/envs/gnn/lib/python3.10/logging/__init__.py", line 1084, in flush
    self.stream.flush()
OSError: [Errno 5] Input/output error
Call stack:
  File "/afs/crc.nd.edu/user/p/psoga/benchmarking-gnns/main_SBMs_node_classification.py", line 382, in <module>
    net_params['in_dim'] = torch.unique(dataset.train[0][0].ndata['feat'],dim=0).size(0) # node_dim (feat is an integer)
  File "/afs/crc.nd.edu/user/p/psoga/benchmarking-gnns/main_SBMs_node_classification.py", line 380, in main
    dataset.test.spatial_pos_lists = []
  File "/afs/crc.nd.edu/user/p/psoga/benchmarking-gnns/main_SBMs_node_classification.py", line 189, in train_val_pipeline
    else:
Message: 'Epoch 243/1000'
Arguments: ()
--- Logging error ---
Traceback (most recent call last):
  File "/afs/crc.nd.edu/user/p/psoga/.conda/envs/gnn/lib/python3.10/logging/__init__.py", line 1104, in emit
    self.flush()
  File "/afs/crc.nd.edu/user/p/psoga/.conda/envs/gnn/lib/python3.10/logging/__init__.py", line 1084, in flush
    self.stream.flush()
OSError: [Errno 5] Input/output error
Call stack:
  File "/afs/crc.nd.edu/user/p/psoga/benchmarking-gnns/main_SBMs_node_classification.py", line 382, in <module>
    net_params['in_dim'] = torch.unique(dataset.train[0][0].ndata['feat'],dim=0).size(0) # node_dim (feat is an integer)
  File "/afs/crc.nd.edu/user/p/psoga/benchmarking-gnns/main_SBMs_node_classification.py", line 380, in main
    dataset.test.spatial_pos_lists = []
  File "/afs/crc.nd.edu/user/p/psoga/benchmarking-gnns/main_SBMs_node_classification.py", line 209, in train_val_pipeline
    epoch_train_loss, epoch_train_acc, optimizer = train_epoch(model, optimizer, device, train_loader, epoch, params['batch_size'])
Message: 'Saving best model with test accuracy: 83.7818 to out/SBMs_node_classification_b26-500k-baseline-trialscheckpoints/GraphTransformer_SBM_PATTERN_GPU0_2_2_20h33m01s_on_Sep_20_2022/MODELS_'
Arguments: ()
--- Logging error ---
Traceback (most recent call last):
  File "/afs/crc.nd.edu/user/p/psoga/.conda/envs/gnn/lib/python3.10/logging/__init__.py", line 1104, in emit
    self.flush()
  File "/afs/crc.nd.edu/user/p/psoga/.conda/envs/gnn/lib/python3.10/logging/__init__.py", line 1084, in flush
    self.stream.flush()
OSError: [Errno 5] Input/output error
Call stack:
  File "/afs/crc.nd.edu/user/p/psoga/benchmarking-gnns/main_SBMs_node_classification.py", line 382, in <module>
    net_params['in_dim'] = torch.unique(dataset.train[0][0].ndata['feat'],dim=0).size(0) # node_dim (feat is an integer)
  File "/afs/crc.nd.edu/user/p/psoga/benchmarking-gnns/main_SBMs_node_classification.py", line 380, in main
    dataset.test.spatial_pos_lists = []
  File "/afs/crc.nd.edu/user/p/psoga/benchmarking-gnns/main_SBMs_node_classification.py", line 231, in train_val_pipeline
    # writer.add_scalar('train/_loss', epoch_train_loss, epoch)
Message: '\tTime: 138.07s, LR: 0.00000, Train Loss: 0.3612, Train Acc: 83.6840,\n                            Val Loss: 0.3619, Val Acc: 83.6044, Test Acc: 83.7818'
Arguments: ()
--- Logging error ---
Traceback (most recent call last):
  File "/afs/crc.nd.edu/user/p/psoga/.conda/envs/gnn/lib/python3.10/logging/__init__.py", line 1104, in emit
    self.flush()
  File "/afs/crc.nd.edu/user/p/psoga/.conda/envs/gnn/lib/python3.10/logging/__init__.py", line 1084, in flush
    self.stream.flush()
OSError: [Errno 5] Input/output error
Call stack:
  File "/afs/crc.nd.edu/user/p/psoga/benchmarking-gnns/main_SBMs_node_classification.py", line 382, in <module>
    net_params['in_dim'] = torch.unique(dataset.train[0][0].ndata['feat'],dim=0).size(0) # node_dim (feat is an integer)
  File "/afs/crc.nd.edu/user/p/psoga/benchmarking-gnns/main_SBMs_node_classification.py", line 380, in main
    dataset.test.spatial_pos_lists = []
  File "/afs/crc.nd.edu/user/p/psoga/benchmarking-gnns/main_SBMs_node_classification.py", line 189, in train_val_pipeline
    else:
Message: 'Epoch 244/1000'
Arguments: ()
--- Logging error ---
Traceback (most recent call last):
  File "/afs/crc.nd.edu/user/p/psoga/.conda/envs/gnn/lib/python3.10/logging/__init__.py", line 1104, in emit
    self.flush()
  File "/afs/crc.nd.edu/user/p/psoga/.conda/envs/gnn/lib/python3.10/logging/__init__.py", line 1084, in flush
    self.stream.flush()
OSError: [Errno 5] Input/output error
Call stack:
  File "/afs/crc.nd.edu/user/p/psoga/benchmarking-gnns/main_SBMs_node_classification.py", line 382, in <module>
    net_params['in_dim'] = torch.unique(dataset.train[0][0].ndata['feat'],dim=0).size(0) # node_dim (feat is an integer)
  File "/afs/crc.nd.edu/user/p/psoga/benchmarking-gnns/main_SBMs_node_classification.py", line 380, in main
    dataset.test.spatial_pos_lists = []
  File "/afs/crc.nd.edu/user/p/psoga/benchmarking-gnns/main_SBMs_node_classification.py", line 231, in train_val_pipeline
    # writer.add_scalar('train/_loss', epoch_train_loss, epoch)
Message: '\tTime: 138.38s, LR: 0.00000, Train Loss: 0.3611, Train Acc: 83.6850,\n                            Val Loss: 0.3625, Val Acc: 83.5997, Test Acc: 83.7372'
Arguments: ()
--- Logging error ---
Traceback (most recent call last):
  File "/afs/crc.nd.edu/user/p/psoga/.conda/envs/gnn/lib/python3.10/logging/__init__.py", line 1104, in emit
    self.flush()
  File "/afs/crc.nd.edu/user/p/psoga/.conda/envs/gnn/lib/python3.10/logging/__init__.py", line 1084, in flush
    self.stream.flush()
OSError: [Errno 5] Input/output error
Call stack:
  File "/afs/crc.nd.edu/user/p/psoga/benchmarking-gnns/main_SBMs_node_classification.py", line 382, in <module>
    net_params['in_dim'] = torch.unique(dataset.train[0][0].ndata['feat'],dim=0).size(0) # node_dim (feat is an integer)
  File "/afs/crc.nd.edu/user/p/psoga/benchmarking-gnns/main_SBMs_node_classification.py", line 380, in main
    dataset.test.spatial_pos_lists = []
  File "/afs/crc.nd.edu/user/p/psoga/benchmarking-gnns/main_SBMs_node_classification.py", line 189, in train_val_pipeline
    else:
Message: 'Epoch 245/1000'
Arguments: ()
--- Logging error ---
Traceback (most recent call last):
  File "/afs/crc.nd.edu/user/p/psoga/.conda/envs/gnn/lib/python3.10/logging/__init__.py", line 1104, in emit
    self.flush()
  File "/afs/crc.nd.edu/user/p/psoga/.conda/envs/gnn/lib/python3.10/logging/__init__.py", line 1084, in flush
    self.stream.flush()
OSError: [Errno 5] Input/output error
Call stack:
  File "/afs/crc.nd.edu/user/p/psoga/benchmarking-gnns/main_SBMs_node_classification.py", line 382, in <module>
    net_params['in_dim'] = torch.unique(dataset.train[0][0].ndata['feat'],dim=0).size(0) # node_dim (feat is an integer)
  File "/afs/crc.nd.edu/user/p/psoga/benchmarking-gnns/main_SBMs_node_classification.py", line 380, in main
    dataset.test.spatial_pos_lists = []
  File "/afs/crc.nd.edu/user/p/psoga/benchmarking-gnns/main_SBMs_node_classification.py", line 231, in train_val_pipeline
    # writer.add_scalar('train/_loss', epoch_train_loss, epoch)
Message: '\tTime: 138.34s, LR: 0.00000, Train Loss: 0.3609, Train Acc: 83.7077,\n                            Val Loss: 0.3624, Val Acc: 83.5750, Test Acc: 83.7567'
Arguments: ()
--- Logging error ---
Traceback (most recent call last):
  File "/afs/crc.nd.edu/user/p/psoga/.conda/envs/gnn/lib/python3.10/logging/__init__.py", line 1104, in emit
    self.flush()
  File "/afs/crc.nd.edu/user/p/psoga/.conda/envs/gnn/lib/python3.10/logging/__init__.py", line 1084, in flush
    self.stream.flush()
OSError: [Errno 5] Input/output error
Call stack:
  File "/afs/crc.nd.edu/user/p/psoga/benchmarking-gnns/main_SBMs_node_classification.py", line 382, in <module>
    net_params['in_dim'] = torch.unique(dataset.train[0][0].ndata['feat'],dim=0).size(0) # node_dim (feat is an integer)
  File "/afs/crc.nd.edu/user/p/psoga/benchmarking-gnns/main_SBMs_node_classification.py", line 380, in main
    dataset.test.spatial_pos_lists = []
  File "/afs/crc.nd.edu/user/p/psoga/benchmarking-gnns/main_SBMs_node_classification.py", line 189, in train_val_pipeline
    else:
Message: 'Epoch 246/1000'
Arguments: ()
--- Logging error ---
Traceback (most recent call last):
  File "/afs/crc.nd.edu/user/p/psoga/.conda/envs/gnn/lib/python3.10/logging/__init__.py", line 1104, in emit
    self.flush()
  File "/afs/crc.nd.edu/user/p/psoga/.conda/envs/gnn/lib/python3.10/logging/__init__.py", line 1084, in flush
    self.stream.flush()
OSError: [Errno 5] Input/output error
Call stack:
  File "/afs/crc.nd.edu/user/p/psoga/benchmarking-gnns/main_SBMs_node_classification.py", line 382, in <module>
    net_params['in_dim'] = torch.unique(dataset.train[0][0].ndata['feat'],dim=0).size(0) # node_dim (feat is an integer)
  File "/afs/crc.nd.edu/user/p/psoga/benchmarking-gnns/main_SBMs_node_classification.py", line 380, in main
    dataset.test.spatial_pos_lists = []
  File "/afs/crc.nd.edu/user/p/psoga/benchmarking-gnns/main_SBMs_node_classification.py", line 231, in train_val_pipeline
    # writer.add_scalar('train/_loss', epoch_train_loss, epoch)
Message: '\tTime: 138.06s, LR: 0.00000, Train Loss: 0.3610, Train Acc: 83.7002,\n                            Val Loss: 0.3627, Val Acc: 83.5466, Test Acc: 83.7740'
Arguments: ()
--- Logging error ---
Traceback (most recent call last):
  File "/afs/crc.nd.edu/user/p/psoga/.conda/envs/gnn/lib/python3.10/logging/__init__.py", line 1104, in emit
    self.flush()
  File "/afs/crc.nd.edu/user/p/psoga/.conda/envs/gnn/lib/python3.10/logging/__init__.py", line 1084, in flush
    self.stream.flush()
OSError: [Errno 5] Input/output error
Call stack:
  File "/afs/crc.nd.edu/user/p/psoga/benchmarking-gnns/main_SBMs_node_classification.py", line 382, in <module>
    net_params['in_dim'] = torch.unique(dataset.train[0][0].ndata['feat'],dim=0).size(0) # node_dim (feat is an integer)
  File "/afs/crc.nd.edu/user/p/psoga/benchmarking-gnns/main_SBMs_node_classification.py", line 380, in main
    dataset.test.spatial_pos_lists = []
  File "/afs/crc.nd.edu/user/p/psoga/benchmarking-gnns/main_SBMs_node_classification.py", line 189, in train_val_pipeline
    else:
Message: 'Epoch 247/1000'
Arguments: ()
--- Logging error ---
Traceback (most recent call last):
  File "/afs/crc.nd.edu/user/p/psoga/.conda/envs/gnn/lib/python3.10/logging/__init__.py", line 1104, in emit
    self.flush()
  File "/afs/crc.nd.edu/user/p/psoga/.conda/envs/gnn/lib/python3.10/logging/__init__.py", line 1084, in flush
    self.stream.flush()
OSError: [Errno 5] Input/output error
Call stack:
  File "/afs/crc.nd.edu/user/p/psoga/benchmarking-gnns/main_SBMs_node_classification.py", line 382, in <module>
    net_params['in_dim'] = torch.unique(dataset.train[0][0].ndata['feat'],dim=0).size(0) # node_dim (feat is an integer)
  File "/afs/crc.nd.edu/user/p/psoga/benchmarking-gnns/main_SBMs_node_classification.py", line 380, in main
    dataset.test.spatial_pos_lists = []
  File "/afs/crc.nd.edu/user/p/psoga/benchmarking-gnns/main_SBMs_node_classification.py", line 231, in train_val_pipeline
    # writer.add_scalar('train/_loss', epoch_train_loss, epoch)
Message: '\tTime: 138.16s, LR: 0.00000, Train Loss: 0.3610, Train Acc: 83.6900,\n                            Val Loss: 0.3625, Val Acc: 83.6070, Test Acc: 83.7186'
Arguments: ()
--- Logging error ---
Traceback (most recent call last):
  File "/afs/crc.nd.edu/user/p/psoga/.conda/envs/gnn/lib/python3.10/logging/__init__.py", line 1104, in emit
    self.flush()
  File "/afs/crc.nd.edu/user/p/psoga/.conda/envs/gnn/lib/python3.10/logging/__init__.py", line 1084, in flush
    self.stream.flush()
OSError: [Errno 5] Input/output error
Call stack:
  File "/afs/crc.nd.edu/user/p/psoga/benchmarking-gnns/main_SBMs_node_classification.py", line 382, in <module>
    net_params['in_dim'] = torch.unique(dataset.train[0][0].ndata['feat'],dim=0).size(0) # node_dim (feat is an integer)
  File "/afs/crc.nd.edu/user/p/psoga/benchmarking-gnns/main_SBMs_node_classification.py", line 380, in main
    dataset.test.spatial_pos_lists = []
  File "/afs/crc.nd.edu/user/p/psoga/benchmarking-gnns/main_SBMs_node_classification.py", line 189, in train_val_pipeline
    else:
Message: 'Epoch 248/1000'
Arguments: ()
--- Logging error ---
Traceback (most recent call last):
  File "/afs/crc.nd.edu/user/p/psoga/.conda/envs/gnn/lib/python3.10/logging/__init__.py", line 1104, in emit
    self.flush()
  File "/afs/crc.nd.edu/user/p/psoga/.conda/envs/gnn/lib/python3.10/logging/__init__.py", line 1084, in flush
    self.stream.flush()
OSError: [Errno 5] Input/output error
Call stack:
  File "/afs/crc.nd.edu/user/p/psoga/benchmarking-gnns/main_SBMs_node_classification.py", line 382, in <module>
    net_params['in_dim'] = torch.unique(dataset.train[0][0].ndata['feat'],dim=0).size(0) # node_dim (feat is an integer)
  File "/afs/crc.nd.edu/user/p/psoga/benchmarking-gnns/main_SBMs_node_classification.py", line 380, in main
    dataset.test.spatial_pos_lists = []
  File "/afs/crc.nd.edu/user/p/psoga/benchmarking-gnns/main_SBMs_node_classification.py", line 231, in train_val_pipeline
    # writer.add_scalar('train/_loss', epoch_train_loss, epoch)
Message: '\tTime: 138.22s, LR: 0.00000, Train Loss: 0.3608, Train Acc: 83.7213,\n                            Val Loss: 0.3626, Val Acc: 83.5805, Test Acc: 83.7433'
Arguments: ()
--- Logging error ---
Traceback (most recent call last):
  File "/afs/crc.nd.edu/user/p/psoga/.conda/envs/gnn/lib/python3.10/logging/__init__.py", line 1104, in emit
    self.flush()
  File "/afs/crc.nd.edu/user/p/psoga/.conda/envs/gnn/lib/python3.10/logging/__init__.py", line 1084, in flush
    self.stream.flush()
OSError: [Errno 5] Input/output error
Call stack:
  File "/afs/crc.nd.edu/user/p/psoga/benchmarking-gnns/main_SBMs_node_classification.py", line 382, in <module>
    net_params['in_dim'] = torch.unique(dataset.train[0][0].ndata['feat'],dim=0).size(0) # node_dim (feat is an integer)
  File "/afs/crc.nd.edu/user/p/psoga/benchmarking-gnns/main_SBMs_node_classification.py", line 380, in main
    dataset.test.spatial_pos_lists = []
  File "/afs/crc.nd.edu/user/p/psoga/benchmarking-gnns/main_SBMs_node_classification.py", line 189, in train_val_pipeline
    else:
Message: 'Epoch 249/1000'
Arguments: ()
--- Logging error ---
Traceback (most recent call last):
  File "/afs/crc.nd.edu/user/p/psoga/.conda/envs/gnn/lib/python3.10/logging/__init__.py", line 1104, in emit
    self.flush()
  File "/afs/crc.nd.edu/user/p/psoga/.conda/envs/gnn/lib/python3.10/logging/__init__.py", line 1084, in flush
    self.stream.flush()
OSError: [Errno 5] Input/output error
Call stack:
  File "/afs/crc.nd.edu/user/p/psoga/benchmarking-gnns/main_SBMs_node_classification.py", line 382, in <module>
    net_params['in_dim'] = torch.unique(dataset.train[0][0].ndata['feat'],dim=0).size(0) # node_dim (feat is an integer)
  File "/afs/crc.nd.edu/user/p/psoga/benchmarking-gnns/main_SBMs_node_classification.py", line 380, in main
    dataset.test.spatial_pos_lists = []
  File "/afs/crc.nd.edu/user/p/psoga/benchmarking-gnns/main_SBMs_node_classification.py", line 231, in train_val_pipeline
    # writer.add_scalar('train/_loss', epoch_train_loss, epoch)
Message: '\tTime: 138.32s, LR: 0.00000, Train Loss: 0.3610, Train Acc: 83.6895,\n                            Val Loss: 0.3620, Val Acc: 83.6647, Test Acc: 83.7582'
Arguments: ()
--- Logging error ---
Traceback (most recent call last):
  File "/afs/crc.nd.edu/user/p/psoga/.conda/envs/gnn/lib/python3.10/logging/__init__.py", line 1104, in emit
    self.flush()
  File "/afs/crc.nd.edu/user/p/psoga/.conda/envs/gnn/lib/python3.10/logging/__init__.py", line 1084, in flush
    self.stream.flush()
OSError: [Errno 5] Input/output error
Call stack:
  File "/afs/crc.nd.edu/user/p/psoga/benchmarking-gnns/main_SBMs_node_classification.py", line 382, in <module>
    net_params['in_dim'] = torch.unique(dataset.train[0][0].ndata['feat'],dim=0).size(0) # node_dim (feat is an integer)
  File "/afs/crc.nd.edu/user/p/psoga/benchmarking-gnns/main_SBMs_node_classification.py", line 380, in main
    dataset.test.spatial_pos_lists = []
  File "/afs/crc.nd.edu/user/p/psoga/benchmarking-gnns/main_SBMs_node_classification.py", line 189, in train_val_pipeline
    else:
Message: 'Epoch 250/1000'
Arguments: ()
--- Logging error ---
Traceback (most recent call last):
  File "/afs/crc.nd.edu/user/p/psoga/.conda/envs/gnn/lib/python3.10/logging/__init__.py", line 1104, in emit
    self.flush()
  File "/afs/crc.nd.edu/user/p/psoga/.conda/envs/gnn/lib/python3.10/logging/__init__.py", line 1084, in flush
    self.stream.flush()
OSError: [Errno 5] Input/output error
Call stack:
  File "/afs/crc.nd.edu/user/p/psoga/benchmarking-gnns/main_SBMs_node_classification.py", line 382, in <module>
    net_params['in_dim'] = torch.unique(dataset.train[0][0].ndata['feat'],dim=0).size(0) # node_dim (feat is an integer)
  File "/afs/crc.nd.edu/user/p/psoga/benchmarking-gnns/main_SBMs_node_classification.py", line 380, in main
    dataset.test.spatial_pos_lists = []
  File "/afs/crc.nd.edu/user/p/psoga/benchmarking-gnns/main_SBMs_node_classification.py", line 231, in train_val_pipeline
    # writer.add_scalar('train/_loss', epoch_train_loss, epoch)
Message: '\tTime: 138.20s, LR: 0.00000, Train Loss: 0.3609, Train Acc: 83.7350,\n                            Val Loss: 0.3622, Val Acc: 83.6593, Test Acc: 83.7189'
Arguments: ()
--- Logging error ---
Traceback (most recent call last):
  File "/afs/crc.nd.edu/user/p/psoga/.conda/envs/gnn/lib/python3.10/logging/__init__.py", line 1104, in emit
    self.flush()
  File "/afs/crc.nd.edu/user/p/psoga/.conda/envs/gnn/lib/python3.10/logging/__init__.py", line 1084, in flush
    self.stream.flush()
OSError: [Errno 5] Input/output error
Call stack:
  File "/afs/crc.nd.edu/user/p/psoga/benchmarking-gnns/main_SBMs_node_classification.py", line 382, in <module>
    net_params['in_dim'] = torch.unique(dataset.train[0][0].ndata['feat'],dim=0).size(0) # node_dim (feat is an integer)
  File "/afs/crc.nd.edu/user/p/psoga/benchmarking-gnns/main_SBMs_node_classification.py", line 380, in main
    dataset.test.spatial_pos_lists = []
  File "/afs/crc.nd.edu/user/p/psoga/benchmarking-gnns/main_SBMs_node_classification.py", line 189, in train_val_pipeline
    else:
Message: 'Epoch 251/1000'
Arguments: ()
--- Logging error ---
Traceback (most recent call last):
  File "/afs/crc.nd.edu/user/p/psoga/.conda/envs/gnn/lib/python3.10/logging/__init__.py", line 1104, in emit
    self.flush()
  File "/afs/crc.nd.edu/user/p/psoga/.conda/envs/gnn/lib/python3.10/logging/__init__.py", line 1084, in flush
    self.stream.flush()
OSError: [Errno 5] Input/output error
Call stack:
  File "/afs/crc.nd.edu/user/p/psoga/benchmarking-gnns/main_SBMs_node_classification.py", line 382, in <module>
    net_params['in_dim'] = torch.unique(dataset.train[0][0].ndata['feat'],dim=0).size(0) # node_dim (feat is an integer)
  File "/afs/crc.nd.edu/user/p/psoga/benchmarking-gnns/main_SBMs_node_classification.py", line 380, in main
    dataset.test.spatial_pos_lists = []
  File "/afs/crc.nd.edu/user/p/psoga/benchmarking-gnns/main_SBMs_node_classification.py", line 231, in train_val_pipeline
    # writer.add_scalar('train/_loss', epoch_train_loss, epoch)
Message: '\tTime: 138.32s, LR: 0.00000, Train Loss: 0.3609, Train Acc: 83.7098,\n                            Val Loss: 0.3620, Val Acc: 83.6412, Test Acc: 83.7604'
Arguments: ()
--- Logging error ---
Traceback (most recent call last):
  File "/afs/crc.nd.edu/user/p/psoga/.conda/envs/gnn/lib/python3.10/logging/__init__.py", line 1104, in emit
    self.flush()
  File "/afs/crc.nd.edu/user/p/psoga/.conda/envs/gnn/lib/python3.10/logging/__init__.py", line 1084, in flush
    self.stream.flush()
OSError: [Errno 5] Input/output error
Call stack:
  File "/afs/crc.nd.edu/user/p/psoga/benchmarking-gnns/main_SBMs_node_classification.py", line 382, in <module>
    net_params['in_dim'] = torch.unique(dataset.train[0][0].ndata['feat'],dim=0).size(0) # node_dim (feat is an integer)
  File "/afs/crc.nd.edu/user/p/psoga/benchmarking-gnns/main_SBMs_node_classification.py", line 380, in main
    dataset.test.spatial_pos_lists = []
  File "/afs/crc.nd.edu/user/p/psoga/benchmarking-gnns/main_SBMs_node_classification.py", line 189, in train_val_pipeline
    else:
Message: 'Epoch 252/1000'
Arguments: ()
--- Logging error ---
Traceback (most recent call last):
  File "/afs/crc.nd.edu/user/p/psoga/.conda/envs/gnn/lib/python3.10/logging/__init__.py", line 1104, in emit
    self.flush()
  File "/afs/crc.nd.edu/user/p/psoga/.conda/envs/gnn/lib/python3.10/logging/__init__.py", line 1084, in flush
    self.stream.flush()
OSError: [Errno 5] Input/output error
Call stack:
  File "/afs/crc.nd.edu/user/p/psoga/benchmarking-gnns/main_SBMs_node_classification.py", line 382, in <module>
    net_params['in_dim'] = torch.unique(dataset.train[0][0].ndata['feat'],dim=0).size(0) # node_dim (feat is an integer)
  File "/afs/crc.nd.edu/user/p/psoga/benchmarking-gnns/main_SBMs_node_classification.py", line 380, in main
    dataset.test.spatial_pos_lists = []
  File "/afs/crc.nd.edu/user/p/psoga/benchmarking-gnns/main_SBMs_node_classification.py", line 231, in train_val_pipeline
    # writer.add_scalar('train/_loss', epoch_train_loss, epoch)
Message: '\tTime: 138.15s, LR: 0.00000, Train Loss: 0.3611, Train Acc: 83.6739,\n                            Val Loss: 0.3622, Val Acc: 83.6098, Test Acc: 83.7057'
Arguments: ()
--- Logging error ---
Traceback (most recent call last):
  File "/afs/crc.nd.edu/user/p/psoga/.conda/envs/gnn/lib/python3.10/logging/__init__.py", line 1104, in emit
    self.flush()
  File "/afs/crc.nd.edu/user/p/psoga/.conda/envs/gnn/lib/python3.10/logging/__init__.py", line 1084, in flush
    self.stream.flush()
OSError: [Errno 5] Input/output error
Call stack:
  File "/afs/crc.nd.edu/user/p/psoga/benchmarking-gnns/main_SBMs_node_classification.py", line 382, in <module>
    net_params['in_dim'] = torch.unique(dataset.train[0][0].ndata['feat'],dim=0).size(0) # node_dim (feat is an integer)
  File "/afs/crc.nd.edu/user/p/psoga/benchmarking-gnns/main_SBMs_node_classification.py", line 380, in main
    dataset.test.spatial_pos_lists = []
  File "/afs/crc.nd.edu/user/p/psoga/benchmarking-gnns/main_SBMs_node_classification.py", line 189, in train_val_pipeline
    else:
Message: 'Epoch 253/1000'
Arguments: ()
--- Logging error ---
Traceback (most recent call last):
  File "/afs/crc.nd.edu/user/p/psoga/.conda/envs/gnn/lib/python3.10/logging/__init__.py", line 1104, in emit
    self.flush()
  File "/afs/crc.nd.edu/user/p/psoga/.conda/envs/gnn/lib/python3.10/logging/__init__.py", line 1084, in flush
    self.stream.flush()
OSError: [Errno 5] Input/output error
Call stack:
  File "/afs/crc.nd.edu/user/p/psoga/benchmarking-gnns/main_SBMs_node_classification.py", line 382, in <module>
    net_params['in_dim'] = torch.unique(dataset.train[0][0].ndata['feat'],dim=0).size(0) # node_dim (feat is an integer)
  File "/afs/crc.nd.edu/user/p/psoga/benchmarking-gnns/main_SBMs_node_classification.py", line 380, in main
    dataset.test.spatial_pos_lists = []
  File "/afs/crc.nd.edu/user/p/psoga/benchmarking-gnns/main_SBMs_node_classification.py", line 231, in train_val_pipeline
    # writer.add_scalar('train/_loss', epoch_train_loss, epoch)
Message: '\tTime: 138.70s, LR: 0.00000, Train Loss: 0.3612, Train Acc: 83.6985,\n                            Val Loss: 0.3621, Val Acc: 83.6412, Test Acc: 83.7432'
Arguments: ()
--- Logging error ---
Traceback (most recent call last):
  File "/afs/crc.nd.edu/user/p/psoga/.conda/envs/gnn/lib/python3.10/logging/__init__.py", line 1104, in emit
    self.flush()
  File "/afs/crc.nd.edu/user/p/psoga/.conda/envs/gnn/lib/python3.10/logging/__init__.py", line 1084, in flush
    self.stream.flush()
OSError: [Errno 5] Input/output error
Call stack:
  File "/afs/crc.nd.edu/user/p/psoga/benchmarking-gnns/main_SBMs_node_classification.py", line 382, in <module>
    net_params['in_dim'] = torch.unique(dataset.train[0][0].ndata['feat'],dim=0).size(0) # node_dim (feat is an integer)
  File "/afs/crc.nd.edu/user/p/psoga/benchmarking-gnns/main_SBMs_node_classification.py", line 380, in main
    dataset.test.spatial_pos_lists = []
  File "/afs/crc.nd.edu/user/p/psoga/benchmarking-gnns/main_SBMs_node_classification.py", line 189, in train_val_pipeline
    else:
Message: 'Epoch 254/1000'
Arguments: ()
--- Logging error ---
Traceback (most recent call last):
  File "/afs/crc.nd.edu/user/p/psoga/.conda/envs/gnn/lib/python3.10/logging/__init__.py", line 1104, in emit
    self.flush()
  File "/afs/crc.nd.edu/user/p/psoga/.conda/envs/gnn/lib/python3.10/logging/__init__.py", line 1084, in flush
    self.stream.flush()
OSError: [Errno 5] Input/output error
Call stack:
  File "/afs/crc.nd.edu/user/p/psoga/benchmarking-gnns/main_SBMs_node_classification.py", line 382, in <module>
    net_params['in_dim'] = torch.unique(dataset.train[0][0].ndata['feat'],dim=0).size(0) # node_dim (feat is an integer)
  File "/afs/crc.nd.edu/user/p/psoga/benchmarking-gnns/main_SBMs_node_classification.py", line 380, in main
    dataset.test.spatial_pos_lists = []
  File "/afs/crc.nd.edu/user/p/psoga/benchmarking-gnns/main_SBMs_node_classification.py", line 231, in train_val_pipeline
    # writer.add_scalar('train/_loss', epoch_train_loss, epoch)
Message: '\tTime: 138.42s, LR: 0.00000, Train Loss: 0.3613, Train Acc: 83.6763,\n                            Val Loss: 0.3621, Val Acc: 83.6296, Test Acc: 83.7739'
Arguments: ()
--- Logging error ---
Traceback (most recent call last):
  File "/afs/crc.nd.edu/user/p/psoga/.conda/envs/gnn/lib/python3.10/logging/__init__.py", line 1104, in emit
    self.flush()
  File "/afs/crc.nd.edu/user/p/psoga/.conda/envs/gnn/lib/python3.10/logging/__init__.py", line 1084, in flush
    self.stream.flush()
OSError: [Errno 5] Input/output error
Call stack:
  File "/afs/crc.nd.edu/user/p/psoga/benchmarking-gnns/main_SBMs_node_classification.py", line 382, in <module>
    net_params['in_dim'] = torch.unique(dataset.train[0][0].ndata['feat'],dim=0).size(0) # node_dim (feat is an integer)
  File "/afs/crc.nd.edu/user/p/psoga/benchmarking-gnns/main_SBMs_node_classification.py", line 380, in main
    dataset.test.spatial_pos_lists = []
  File "/afs/crc.nd.edu/user/p/psoga/benchmarking-gnns/main_SBMs_node_classification.py", line 189, in train_val_pipeline
    else:
Message: 'Epoch 255/1000'
Arguments: ()
--- Logging error ---
Traceback (most recent call last):
  File "/afs/crc.nd.edu/user/p/psoga/.conda/envs/gnn/lib/python3.10/logging/__init__.py", line 1104, in emit
    self.flush()
  File "/afs/crc.nd.edu/user/p/psoga/.conda/envs/gnn/lib/python3.10/logging/__init__.py", line 1084, in flush
    self.stream.flush()
OSError: [Errno 5] Input/output error
Call stack:
  File "/afs/crc.nd.edu/user/p/psoga/benchmarking-gnns/main_SBMs_node_classification.py", line 382, in <module>
    net_params['in_dim'] = torch.unique(dataset.train[0][0].ndata['feat'],dim=0).size(0) # node_dim (feat is an integer)
  File "/afs/crc.nd.edu/user/p/psoga/benchmarking-gnns/main_SBMs_node_classification.py", line 380, in main
    dataset.test.spatial_pos_lists = []
  File "/afs/crc.nd.edu/user/p/psoga/benchmarking-gnns/main_SBMs_node_classification.py", line 231, in train_val_pipeline
    # writer.add_scalar('train/_loss', epoch_train_loss, epoch)
Message: '\tTime: 138.78s, LR: 0.00000, Train Loss: 0.3610, Train Acc: 83.7061,\n                            Val Loss: 0.3623, Val Acc: 83.5930, Test Acc: 83.7632'
Arguments: ()
--- Logging error ---
Traceback (most recent call last):
  File "/afs/crc.nd.edu/user/p/psoga/.conda/envs/gnn/lib/python3.10/logging/__init__.py", line 1104, in emit
    self.flush()
  File "/afs/crc.nd.edu/user/p/psoga/.conda/envs/gnn/lib/python3.10/logging/__init__.py", line 1084, in flush
    self.stream.flush()
OSError: [Errno 5] Input/output error
Call stack:
  File "/afs/crc.nd.edu/user/p/psoga/benchmarking-gnns/main_SBMs_node_classification.py", line 382, in <module>
    net_params['in_dim'] = torch.unique(dataset.train[0][0].ndata['feat'],dim=0).size(0) # node_dim (feat is an integer)
  File "/afs/crc.nd.edu/user/p/psoga/benchmarking-gnns/main_SBMs_node_classification.py", line 380, in main
    dataset.test.spatial_pos_lists = []
  File "/afs/crc.nd.edu/user/p/psoga/benchmarking-gnns/main_SBMs_node_classification.py", line 189, in train_val_pipeline
    else:
Message: 'Epoch 256/1000'
Arguments: ()
--- Logging error ---
Traceback (most recent call last):
  File "/afs/crc.nd.edu/user/p/psoga/.conda/envs/gnn/lib/python3.10/logging/__init__.py", line 1104, in emit
    self.flush()
  File "/afs/crc.nd.edu/user/p/psoga/.conda/envs/gnn/lib/python3.10/logging/__init__.py", line 1084, in flush
    self.stream.flush()
OSError: [Errno 5] Input/output error
Call stack:
  File "/afs/crc.nd.edu/user/p/psoga/benchmarking-gnns/main_SBMs_node_classification.py", line 382, in <module>
    net_params['in_dim'] = torch.unique(dataset.train[0][0].ndata['feat'],dim=0).size(0) # node_dim (feat is an integer)
  File "/afs/crc.nd.edu/user/p/psoga/benchmarking-gnns/main_SBMs_node_classification.py", line 380, in main
    dataset.test.spatial_pos_lists = []
  File "/afs/crc.nd.edu/user/p/psoga/benchmarking-gnns/main_SBMs_node_classification.py", line 231, in train_val_pipeline
    # writer.add_scalar('train/_loss', epoch_train_loss, epoch)
Message: '\tTime: 138.29s, LR: 0.00000, Train Loss: 0.3610, Train Acc: 83.7294,\n                            Val Loss: 0.3622, Val Acc: 83.6219, Test Acc: 83.7445'
Arguments: ()
--- Logging error ---
Traceback (most recent call last):
  File "/afs/crc.nd.edu/user/p/psoga/.conda/envs/gnn/lib/python3.10/logging/__init__.py", line 1104, in emit
    self.flush()
  File "/afs/crc.nd.edu/user/p/psoga/.conda/envs/gnn/lib/python3.10/logging/__init__.py", line 1084, in flush
    self.stream.flush()
OSError: [Errno 5] Input/output error
Call stack:
  File "/afs/crc.nd.edu/user/p/psoga/benchmarking-gnns/main_SBMs_node_classification.py", line 382, in <module>
    net_params['in_dim'] = torch.unique(dataset.train[0][0].ndata['feat'],dim=0).size(0) # node_dim (feat is an integer)
  File "/afs/crc.nd.edu/user/p/psoga/benchmarking-gnns/main_SBMs_node_classification.py", line 380, in main
    dataset.test.spatial_pos_lists = []
  File "/afs/crc.nd.edu/user/p/psoga/benchmarking-gnns/main_SBMs_node_classification.py", line 189, in train_val_pipeline
    else:
Message: 'Epoch 257/1000'
Arguments: ()
--- Logging error ---
Traceback (most recent call last):
  File "/afs/crc.nd.edu/user/p/psoga/.conda/envs/gnn/lib/python3.10/logging/__init__.py", line 1104, in emit
    self.flush()
  File "/afs/crc.nd.edu/user/p/psoga/.conda/envs/gnn/lib/python3.10/logging/__init__.py", line 1084, in flush
    self.stream.flush()
OSError: [Errno 5] Input/output error
Call stack:
  File "/afs/crc.nd.edu/user/p/psoga/benchmarking-gnns/main_SBMs_node_classification.py", line 382, in <module>
    net_params['in_dim'] = torch.unique(dataset.train[0][0].ndata['feat'],dim=0).size(0) # node_dim (feat is an integer)
  File "/afs/crc.nd.edu/user/p/psoga/benchmarking-gnns/main_SBMs_node_classification.py", line 380, in main
    dataset.test.spatial_pos_lists = []
  File "/afs/crc.nd.edu/user/p/psoga/benchmarking-gnns/main_SBMs_node_classification.py", line 231, in train_val_pipeline
    # writer.add_scalar('train/_loss', epoch_train_loss, epoch)
Message: '\tTime: 138.30s, LR: 0.00000, Train Loss: 0.3611, Train Acc: 83.6911,\n                            Val Loss: 0.3623, Val Acc: 83.6212, Test Acc: 83.7628'
Arguments: ()
--- Logging error ---
Traceback (most recent call last):
  File "/afs/crc.nd.edu/user/p/psoga/.conda/envs/gnn/lib/python3.10/logging/__init__.py", line 1104, in emit
    self.flush()
  File "/afs/crc.nd.edu/user/p/psoga/.conda/envs/gnn/lib/python3.10/logging/__init__.py", line 1084, in flush
    self.stream.flush()
OSError: [Errno 5] Input/output error
Call stack:
  File "/afs/crc.nd.edu/user/p/psoga/benchmarking-gnns/main_SBMs_node_classification.py", line 382, in <module>
    net_params['in_dim'] = torch.unique(dataset.train[0][0].ndata['feat'],dim=0).size(0) # node_dim (feat is an integer)
  File "/afs/crc.nd.edu/user/p/psoga/benchmarking-gnns/main_SBMs_node_classification.py", line 380, in main
    dataset.test.spatial_pos_lists = []
  File "/afs/crc.nd.edu/user/p/psoga/benchmarking-gnns/main_SBMs_node_classification.py", line 189, in train_val_pipeline
    else:
Message: 'Epoch 258/1000'
Arguments: ()
--- Logging error ---
Traceback (most recent call last):
  File "/afs/crc.nd.edu/user/p/psoga/.conda/envs/gnn/lib/python3.10/logging/__init__.py", line 1104, in emit
    self.flush()
  File "/afs/crc.nd.edu/user/p/psoga/.conda/envs/gnn/lib/python3.10/logging/__init__.py", line 1084, in flush
    self.stream.flush()
OSError: [Errno 5] Input/output error
Call stack:
  File "/afs/crc.nd.edu/user/p/psoga/benchmarking-gnns/main_SBMs_node_classification.py", line 382, in <module>
    net_params['in_dim'] = torch.unique(dataset.train[0][0].ndata['feat'],dim=0).size(0) # node_dim (feat is an integer)
  File "/afs/crc.nd.edu/user/p/psoga/benchmarking-gnns/main_SBMs_node_classification.py", line 380, in main
    dataset.test.spatial_pos_lists = []
  File "/afs/crc.nd.edu/user/p/psoga/benchmarking-gnns/main_SBMs_node_classification.py", line 231, in train_val_pipeline
    # writer.add_scalar('train/_loss', epoch_train_loss, epoch)
Message: '\tTime: 138.28s, LR: 0.00000, Train Loss: 0.3611, Train Acc: 83.6932,\n                            Val Loss: 0.3624, Val Acc: 83.5708, Test Acc: 83.7720'
Arguments: ()
--- Logging error ---
Traceback (most recent call last):
  File "/afs/crc.nd.edu/user/p/psoga/.conda/envs/gnn/lib/python3.10/logging/__init__.py", line 1104, in emit
    self.flush()
  File "/afs/crc.nd.edu/user/p/psoga/.conda/envs/gnn/lib/python3.10/logging/__init__.py", line 1084, in flush
    self.stream.flush()
OSError: [Errno 5] Input/output error
Call stack:
  File "/afs/crc.nd.edu/user/p/psoga/benchmarking-gnns/main_SBMs_node_classification.py", line 382, in <module>
    net_params['in_dim'] = torch.unique(dataset.train[0][0].ndata['feat'],dim=0).size(0) # node_dim (feat is an integer)
  File "/afs/crc.nd.edu/user/p/psoga/benchmarking-gnns/main_SBMs_node_classification.py", line 380, in main
    dataset.test.spatial_pos_lists = []
  File "/afs/crc.nd.edu/user/p/psoga/benchmarking-gnns/main_SBMs_node_classification.py", line 189, in train_val_pipeline
    else:
Message: 'Epoch 259/1000'
Arguments: ()
--- Logging error ---
Traceback (most recent call last):
  File "/afs/crc.nd.edu/user/p/psoga/.conda/envs/gnn/lib/python3.10/logging/__init__.py", line 1104, in emit
    self.flush()
  File "/afs/crc.nd.edu/user/p/psoga/.conda/envs/gnn/lib/python3.10/logging/__init__.py", line 1084, in flush
    self.stream.flush()
OSError: [Errno 5] Input/output error
Call stack:
  File "/afs/crc.nd.edu/user/p/psoga/benchmarking-gnns/main_SBMs_node_classification.py", line 382, in <module>
    net_params['in_dim'] = torch.unique(dataset.train[0][0].ndata['feat'],dim=0).size(0) # node_dim (feat is an integer)
  File "/afs/crc.nd.edu/user/p/psoga/benchmarking-gnns/main_SBMs_node_classification.py", line 380, in main
    dataset.test.spatial_pos_lists = []
  File "/afs/crc.nd.edu/user/p/psoga/benchmarking-gnns/main_SBMs_node_classification.py", line 231, in train_val_pipeline
    # writer.add_scalar('train/_loss', epoch_train_loss, epoch)
Message: '\tTime: 138.52s, LR: 0.00000, Train Loss: 0.3610, Train Acc: 83.6860,\n                            Val Loss: 0.3620, Val Acc: 83.6307, Test Acc: 83.7752'
Arguments: ()
--- Logging error ---
Traceback (most recent call last):
  File "/afs/crc.nd.edu/user/p/psoga/.conda/envs/gnn/lib/python3.10/logging/__init__.py", line 1104, in emit
    self.flush()
  File "/afs/crc.nd.edu/user/p/psoga/.conda/envs/gnn/lib/python3.10/logging/__init__.py", line 1084, in flush
    self.stream.flush()
OSError: [Errno 5] Input/output error
Call stack:
  File "/afs/crc.nd.edu/user/p/psoga/benchmarking-gnns/main_SBMs_node_classification.py", line 382, in <module>
    net_params['in_dim'] = torch.unique(dataset.train[0][0].ndata['feat'],dim=0).size(0) # node_dim (feat is an integer)
  File "/afs/crc.nd.edu/user/p/psoga/benchmarking-gnns/main_SBMs_node_classification.py", line 380, in main
    dataset.test.spatial_pos_lists = []
  File "/afs/crc.nd.edu/user/p/psoga/benchmarking-gnns/main_SBMs_node_classification.py", line 189, in train_val_pipeline
    else:
Message: 'Epoch 260/1000'
Arguments: ()
--- Logging error ---
Traceback (most recent call last):
  File "/afs/crc.nd.edu/user/p/psoga/.conda/envs/gnn/lib/python3.10/logging/__init__.py", line 1104, in emit
    self.flush()
  File "/afs/crc.nd.edu/user/p/psoga/.conda/envs/gnn/lib/python3.10/logging/__init__.py", line 1084, in flush
    self.stream.flush()
OSError: [Errno 5] Input/output error
Call stack:
  File "/afs/crc.nd.edu/user/p/psoga/benchmarking-gnns/main_SBMs_node_classification.py", line 382, in <module>
    net_params['in_dim'] = torch.unique(dataset.train[0][0].ndata['feat'],dim=0).size(0) # node_dim (feat is an integer)
  File "/afs/crc.nd.edu/user/p/psoga/benchmarking-gnns/main_SBMs_node_classification.py", line 380, in main
    dataset.test.spatial_pos_lists = []
  File "/afs/crc.nd.edu/user/p/psoga/benchmarking-gnns/main_SBMs_node_classification.py", line 231, in train_val_pipeline
    # writer.add_scalar('train/_loss', epoch_train_loss, epoch)
Message: '\tTime: 138.97s, LR: 0.00000, Train Loss: 0.3609, Train Acc: 83.7078,\n                            Val Loss: 0.3623, Val Acc: 83.6100, Test Acc: 83.7379'
Arguments: ()
--- Logging error ---
Traceback (most recent call last):
  File "/afs/crc.nd.edu/user/p/psoga/.conda/envs/gnn/lib/python3.10/logging/__init__.py", line 1104, in emit
    self.flush()
  File "/afs/crc.nd.edu/user/p/psoga/.conda/envs/gnn/lib/python3.10/logging/__init__.py", line 1084, in flush
    self.stream.flush()
OSError: [Errno 5] Input/output error
Call stack:
  File "/afs/crc.nd.edu/user/p/psoga/benchmarking-gnns/main_SBMs_node_classification.py", line 382, in <module>
    net_params['in_dim'] = torch.unique(dataset.train[0][0].ndata['feat'],dim=0).size(0) # node_dim (feat is an integer)
  File "/afs/crc.nd.edu/user/p/psoga/benchmarking-gnns/main_SBMs_node_classification.py", line 380, in main
    dataset.test.spatial_pos_lists = []
  File "/afs/crc.nd.edu/user/p/psoga/benchmarking-gnns/main_SBMs_node_classification.py", line 189, in train_val_pipeline
    else:
Message: 'Epoch 261/1000'
Arguments: ()
--- Logging error ---
Traceback (most recent call last):
  File "/afs/crc.nd.edu/user/p/psoga/.conda/envs/gnn/lib/python3.10/logging/__init__.py", line 1104, in emit
    self.flush()
  File "/afs/crc.nd.edu/user/p/psoga/.conda/envs/gnn/lib/python3.10/logging/__init__.py", line 1084, in flush
    self.stream.flush()
OSError: [Errno 5] Input/output error
Call stack:
  File "/afs/crc.nd.edu/user/p/psoga/benchmarking-gnns/main_SBMs_node_classification.py", line 382, in <module>
    net_params['in_dim'] = torch.unique(dataset.train[0][0].ndata['feat'],dim=0).size(0) # node_dim (feat is an integer)
  File "/afs/crc.nd.edu/user/p/psoga/benchmarking-gnns/main_SBMs_node_classification.py", line 380, in main
    dataset.test.spatial_pos_lists = []
  File "/afs/crc.nd.edu/user/p/psoga/benchmarking-gnns/main_SBMs_node_classification.py", line 231, in train_val_pipeline
    # writer.add_scalar('train/_loss', epoch_train_loss, epoch)
Message: '\tTime: 138.67s, LR: 0.00000, Train Loss: 0.3610, Train Acc: 83.7218,\n                            Val Loss: 0.3621, Val Acc: 83.6411, Test Acc: 83.7746'
Arguments: ()
--- Logging error ---
Traceback (most recent call last):
  File "/afs/crc.nd.edu/user/p/psoga/.conda/envs/gnn/lib/python3.10/logging/__init__.py", line 1104, in emit
    self.flush()
  File "/afs/crc.nd.edu/user/p/psoga/.conda/envs/gnn/lib/python3.10/logging/__init__.py", line 1084, in flush
    self.stream.flush()
OSError: [Errno 5] Input/output error
Call stack:
  File "/afs/crc.nd.edu/user/p/psoga/benchmarking-gnns/main_SBMs_node_classification.py", line 382, in <module>
    net_params['in_dim'] = torch.unique(dataset.train[0][0].ndata['feat'],dim=0).size(0) # node_dim (feat is an integer)
  File "/afs/crc.nd.edu/user/p/psoga/benchmarking-gnns/main_SBMs_node_classification.py", line 380, in main
    dataset.test.spatial_pos_lists = []
  File "/afs/crc.nd.edu/user/p/psoga/benchmarking-gnns/main_SBMs_node_classification.py", line 189, in train_val_pipeline
    else:
Message: 'Epoch 262/1000'
Arguments: ()
--- Logging error ---
Traceback (most recent call last):
  File "/afs/crc.nd.edu/user/p/psoga/.conda/envs/gnn/lib/python3.10/logging/__init__.py", line 1104, in emit
    self.flush()
  File "/afs/crc.nd.edu/user/p/psoga/.conda/envs/gnn/lib/python3.10/logging/__init__.py", line 1084, in flush
    self.stream.flush()
OSError: [Errno 5] Input/output error
Call stack:
  File "/afs/crc.nd.edu/user/p/psoga/benchmarking-gnns/main_SBMs_node_classification.py", line 382, in <module>
    net_params['in_dim'] = torch.unique(dataset.train[0][0].ndata['feat'],dim=0).size(0) # node_dim (feat is an integer)
  File "/afs/crc.nd.edu/user/p/psoga/benchmarking-gnns/main_SBMs_node_classification.py", line 380, in main
    dataset.test.spatial_pos_lists = []
  File "/afs/crc.nd.edu/user/p/psoga/benchmarking-gnns/main_SBMs_node_classification.py", line 209, in train_val_pipeline
    epoch_train_loss, epoch_train_acc, optimizer = train_epoch(model, optimizer, device, train_loader, epoch, params['batch_size'])
Message: 'Saving best model with test accuracy: 83.7859 to out/SBMs_node_classification_b26-500k-baseline-trialscheckpoints/GraphTransformer_SBM_PATTERN_GPU0_2_2_20h33m01s_on_Sep_20_2022/MODELS_'
Arguments: ()
--- Logging error ---
Traceback (most recent call last):
  File "/afs/crc.nd.edu/user/p/psoga/.conda/envs/gnn/lib/python3.10/logging/__init__.py", line 1104, in emit
    self.flush()
  File "/afs/crc.nd.edu/user/p/psoga/.conda/envs/gnn/lib/python3.10/logging/__init__.py", line 1084, in flush
    self.stream.flush()
OSError: [Errno 5] Input/output error
Call stack:
  File "/afs/crc.nd.edu/user/p/psoga/benchmarking-gnns/main_SBMs_node_classification.py", line 382, in <module>
    net_params['in_dim'] = torch.unique(dataset.train[0][0].ndata['feat'],dim=0).size(0) # node_dim (feat is an integer)
  File "/afs/crc.nd.edu/user/p/psoga/benchmarking-gnns/main_SBMs_node_classification.py", line 380, in main
    dataset.test.spatial_pos_lists = []
  File "/afs/crc.nd.edu/user/p/psoga/benchmarking-gnns/main_SBMs_node_classification.py", line 231, in train_val_pipeline
    # writer.add_scalar('train/_loss', epoch_train_loss, epoch)
Message: '\tTime: 138.41s, LR: 0.00000, Train Loss: 0.3605, Train Acc: 83.7506,\n                            Val Loss: 0.3624, Val Acc: 83.6183, Test Acc: 83.7859'
Arguments: ()
--- Logging error ---
Traceback (most recent call last):
  File "/afs/crc.nd.edu/user/p/psoga/.conda/envs/gnn/lib/python3.10/logging/__init__.py", line 1104, in emit
    self.flush()
  File "/afs/crc.nd.edu/user/p/psoga/.conda/envs/gnn/lib/python3.10/logging/__init__.py", line 1084, in flush
    self.stream.flush()
OSError: [Errno 5] Input/output error
Call stack:
  File "/afs/crc.nd.edu/user/p/psoga/benchmarking-gnns/main_SBMs_node_classification.py", line 382, in <module>
    net_params['in_dim'] = torch.unique(dataset.train[0][0].ndata['feat'],dim=0).size(0) # node_dim (feat is an integer)
  File "/afs/crc.nd.edu/user/p/psoga/benchmarking-gnns/main_SBMs_node_classification.py", line 380, in main
    dataset.test.spatial_pos_lists = []
  File "/afs/crc.nd.edu/user/p/psoga/benchmarking-gnns/main_SBMs_node_classification.py", line 189, in train_val_pipeline
    else:
Message: 'Epoch 263/1000'
Arguments: ()
--- Logging error ---
Traceback (most recent call last):
  File "/afs/crc.nd.edu/user/p/psoga/.conda/envs/gnn/lib/python3.10/logging/__init__.py", line 1104, in emit
    self.flush()
  File "/afs/crc.nd.edu/user/p/psoga/.conda/envs/gnn/lib/python3.10/logging/__init__.py", line 1084, in flush
    self.stream.flush()
OSError: [Errno 5] Input/output error
Call stack:
  File "/afs/crc.nd.edu/user/p/psoga/benchmarking-gnns/main_SBMs_node_classification.py", line 382, in <module>
    net_params['in_dim'] = torch.unique(dataset.train[0][0].ndata['feat'],dim=0).size(0) # node_dim (feat is an integer)
  File "/afs/crc.nd.edu/user/p/psoga/benchmarking-gnns/main_SBMs_node_classification.py", line 380, in main
    dataset.test.spatial_pos_lists = []
  File "/afs/crc.nd.edu/user/p/psoga/benchmarking-gnns/main_SBMs_node_classification.py", line 231, in train_val_pipeline
    # writer.add_scalar('train/_loss', epoch_train_loss, epoch)
Message: '\tTime: 138.22s, LR: 0.00000, Train Loss: 0.3606, Train Acc: 83.7190,\n                            Val Loss: 0.3623, Val Acc: 83.6073, Test Acc: 83.7768'
Arguments: ()
--- Logging error ---
Traceback (most recent call last):
  File "/afs/crc.nd.edu/user/p/psoga/.conda/envs/gnn/lib/python3.10/logging/__init__.py", line 1104, in emit
    self.flush()
  File "/afs/crc.nd.edu/user/p/psoga/.conda/envs/gnn/lib/python3.10/logging/__init__.py", line 1084, in flush
    self.stream.flush()
OSError: [Errno 5] Input/output error
Call stack:
  File "/afs/crc.nd.edu/user/p/psoga/benchmarking-gnns/main_SBMs_node_classification.py", line 382, in <module>
    net_params['in_dim'] = torch.unique(dataset.train[0][0].ndata['feat'],dim=0).size(0) # node_dim (feat is an integer)
  File "/afs/crc.nd.edu/user/p/psoga/benchmarking-gnns/main_SBMs_node_classification.py", line 380, in main
    dataset.test.spatial_pos_lists = []
  File "/afs/crc.nd.edu/user/p/psoga/benchmarking-gnns/main_SBMs_node_classification.py", line 189, in train_val_pipeline
    else:
Message: 'Epoch 264/1000'
Arguments: ()
--- Logging error ---
Traceback (most recent call last):
  File "/afs/crc.nd.edu/user/p/psoga/.conda/envs/gnn/lib/python3.10/logging/__init__.py", line 1104, in emit
    self.flush()
  File "/afs/crc.nd.edu/user/p/psoga/.conda/envs/gnn/lib/python3.10/logging/__init__.py", line 1084, in flush
    self.stream.flush()
OSError: [Errno 5] Input/output error
Call stack:
  File "/afs/crc.nd.edu/user/p/psoga/benchmarking-gnns/main_SBMs_node_classification.py", line 382, in <module>
    net_params['in_dim'] = torch.unique(dataset.train[0][0].ndata['feat'],dim=0).size(0) # node_dim (feat is an integer)
  File "/afs/crc.nd.edu/user/p/psoga/benchmarking-gnns/main_SBMs_node_classification.py", line 380, in main
    dataset.test.spatial_pos_lists = []
  File "/afs/crc.nd.edu/user/p/psoga/benchmarking-gnns/main_SBMs_node_classification.py", line 231, in train_val_pipeline
    # writer.add_scalar('train/_loss', epoch_train_loss, epoch)
Message: '\tTime: 138.17s, LR: 0.00000, Train Loss: 0.3609, Train Acc: 83.7051,\n                            Val Loss: 0.3625, Val Acc: 83.6226, Test Acc: 83.7414'
Arguments: ()
--- Logging error ---
Traceback (most recent call last):
  File "/afs/crc.nd.edu/user/p/psoga/.conda/envs/gnn/lib/python3.10/logging/__init__.py", line 1104, in emit
    self.flush()
  File "/afs/crc.nd.edu/user/p/psoga/.conda/envs/gnn/lib/python3.10/logging/__init__.py", line 1084, in flush
    self.stream.flush()
OSError: [Errno 5] Input/output error
Call stack:
  File "/afs/crc.nd.edu/user/p/psoga/benchmarking-gnns/main_SBMs_node_classification.py", line 382, in <module>
    net_params['in_dim'] = torch.unique(dataset.train[0][0].ndata['feat'],dim=0).size(0) # node_dim (feat is an integer)
  File "/afs/crc.nd.edu/user/p/psoga/benchmarking-gnns/main_SBMs_node_classification.py", line 380, in main
    dataset.test.spatial_pos_lists = []
  File "/afs/crc.nd.edu/user/p/psoga/benchmarking-gnns/main_SBMs_node_classification.py", line 189, in train_val_pipeline
    else:
Message: 'Epoch 265/1000'
Arguments: ()
--- Logging error ---
Traceback (most recent call last):
  File "/afs/crc.nd.edu/user/p/psoga/.conda/envs/gnn/lib/python3.10/logging/__init__.py", line 1104, in emit
    self.flush()
  File "/afs/crc.nd.edu/user/p/psoga/.conda/envs/gnn/lib/python3.10/logging/__init__.py", line 1084, in flush
    self.stream.flush()
OSError: [Errno 5] Input/output error
Call stack:
  File "/afs/crc.nd.edu/user/p/psoga/benchmarking-gnns/main_SBMs_node_classification.py", line 382, in <module>
    net_params['in_dim'] = torch.unique(dataset.train[0][0].ndata['feat'],dim=0).size(0) # node_dim (feat is an integer)
  File "/afs/crc.nd.edu/user/p/psoga/benchmarking-gnns/main_SBMs_node_classification.py", line 380, in main
    dataset.test.spatial_pos_lists = []
  File "/afs/crc.nd.edu/user/p/psoga/benchmarking-gnns/main_SBMs_node_classification.py", line 209, in train_val_pipeline
    epoch_train_loss, epoch_train_acc, optimizer = train_epoch(model, optimizer, device, train_loader, epoch, params['batch_size'])
Message: 'Saving best model with test accuracy: 83.7873 to out/SBMs_node_classification_b26-500k-baseline-trialscheckpoints/GraphTransformer_SBM_PATTERN_GPU0_2_2_20h33m01s_on_Sep_20_2022/MODELS_'
Arguments: ()
--- Logging error ---
Traceback (most recent call last):
  File "/afs/crc.nd.edu/user/p/psoga/.conda/envs/gnn/lib/python3.10/logging/__init__.py", line 1104, in emit
    self.flush()
  File "/afs/crc.nd.edu/user/p/psoga/.conda/envs/gnn/lib/python3.10/logging/__init__.py", line 1084, in flush
    self.stream.flush()
OSError: [Errno 5] Input/output error
Call stack:
  File "/afs/crc.nd.edu/user/p/psoga/benchmarking-gnns/main_SBMs_node_classification.py", line 382, in <module>
    net_params['in_dim'] = torch.unique(dataset.train[0][0].ndata['feat'],dim=0).size(0) # node_dim (feat is an integer)
  File "/afs/crc.nd.edu/user/p/psoga/benchmarking-gnns/main_SBMs_node_classification.py", line 380, in main
    dataset.test.spatial_pos_lists = []
  File "/afs/crc.nd.edu/user/p/psoga/benchmarking-gnns/main_SBMs_node_classification.py", line 231, in train_val_pipeline
    # writer.add_scalar('train/_loss', epoch_train_loss, epoch)
Message: '\tTime: 138.24s, LR: 0.00000, Train Loss: 0.3609, Train Acc: 83.7162,\n                            Val Loss: 0.3623, Val Acc: 83.6055, Test Acc: 83.7873'
Arguments: ()
--- Logging error ---
Traceback (most recent call last):
  File "/afs/crc.nd.edu/user/p/psoga/.conda/envs/gnn/lib/python3.10/logging/__init__.py", line 1104, in emit
    self.flush()
  File "/afs/crc.nd.edu/user/p/psoga/.conda/envs/gnn/lib/python3.10/logging/__init__.py", line 1084, in flush
    self.stream.flush()
OSError: [Errno 5] Input/output error
Call stack:
  File "/afs/crc.nd.edu/user/p/psoga/benchmarking-gnns/main_SBMs_node_classification.py", line 382, in <module>
    net_params['in_dim'] = torch.unique(dataset.train[0][0].ndata['feat'],dim=0).size(0) # node_dim (feat is an integer)
  File "/afs/crc.nd.edu/user/p/psoga/benchmarking-gnns/main_SBMs_node_classification.py", line 380, in main
    dataset.test.spatial_pos_lists = []
  File "/afs/crc.nd.edu/user/p/psoga/benchmarking-gnns/main_SBMs_node_classification.py", line 252, in train_val_pipeline
    # ckpt_dir = os.path.join(root_ckpt_dir, "RUN_")
Message: '\n!! LR SMALLER OR EQUAL TO MIN LR THRESHOLD.'
Arguments: ()
--- Logging error ---
Traceback (most recent call last):
  File "/afs/crc.nd.edu/user/p/psoga/.conda/envs/gnn/lib/python3.10/logging/__init__.py", line 1104, in emit
    self.flush()
  File "/afs/crc.nd.edu/user/p/psoga/.conda/envs/gnn/lib/python3.10/logging/__init__.py", line 1084, in flush
    self.stream.flush()
OSError: [Errno 5] Input/output error
Call stack:
  File "/afs/crc.nd.edu/user/p/psoga/benchmarking-gnns/main_SBMs_node_classification.py", line 382, in <module>
    net_params['in_dim'] = torch.unique(dataset.train[0][0].ndata['feat'],dim=0).size(0) # node_dim (feat is an integer)
  File "/afs/crc.nd.edu/user/p/psoga/benchmarking-gnns/main_SBMs_node_classification.py", line 380, in main
    dataset.test.spatial_pos_lists = []
  File "/afs/crc.nd.edu/user/p/psoga/benchmarking-gnns/main_SBMs_node_classification.py", line 271, in train_val_pipeline
    if time.time()-start0 > params['max_time']*3600:
Message: 'Test Accuracy: 83.7873'
Arguments: ()
--- Logging error ---
Traceback (most recent call last):
  File "/afs/crc.nd.edu/user/p/psoga/.conda/envs/gnn/lib/python3.10/logging/__init__.py", line 1104, in emit
    self.flush()
  File "/afs/crc.nd.edu/user/p/psoga/.conda/envs/gnn/lib/python3.10/logging/__init__.py", line 1084, in flush
    self.stream.flush()
OSError: [Errno 5] Input/output error
Call stack:
  File "/afs/crc.nd.edu/user/p/psoga/benchmarking-gnns/main_SBMs_node_classification.py", line 382, in <module>
    net_params['in_dim'] = torch.unique(dataset.train[0][0].ndata['feat'],dim=0).size(0) # node_dim (feat is an integer)
  File "/afs/crc.nd.edu/user/p/psoga/benchmarking-gnns/main_SBMs_node_classification.py", line 380, in main
    dataset.test.spatial_pos_lists = []
  File "/afs/crc.nd.edu/user/p/psoga/benchmarking-gnns/main_SBMs_node_classification.py", line 272, in train_val_pipeline
    logger.info('-' * 89)
Message: 'Best Test Accuracy: 83.7873'
Arguments: ()
--- Logging error ---
Traceback (most recent call last):
  File "/afs/crc.nd.edu/user/p/psoga/.conda/envs/gnn/lib/python3.10/logging/__init__.py", line 1104, in emit
    self.flush()
  File "/afs/crc.nd.edu/user/p/psoga/.conda/envs/gnn/lib/python3.10/logging/__init__.py", line 1084, in flush
    self.stream.flush()
OSError: [Errno 5] Input/output error
Call stack:
  File "/afs/crc.nd.edu/user/p/psoga/benchmarking-gnns/main_SBMs_node_classification.py", line 382, in <module>
    net_params['in_dim'] = torch.unique(dataset.train[0][0].ndata['feat'],dim=0).size(0) # node_dim (feat is an integer)
  File "/afs/crc.nd.edu/user/p/psoga/benchmarking-gnns/main_SBMs_node_classification.py", line 380, in main
    dataset.test.spatial_pos_lists = []
  File "/afs/crc.nd.edu/user/p/psoga/benchmarking-gnns/main_SBMs_node_classification.py", line 273, in train_val_pipeline
    logger.info("Max_time for training elapsed {:.2f} hours, so stopping".format(params['max_time']))
Message: 'Train Accuracy: 83.8357'
Arguments: ()
--- Logging error ---
Traceback (most recent call last):
  File "/afs/crc.nd.edu/user/p/psoga/.conda/envs/gnn/lib/python3.10/logging/__init__.py", line 1104, in emit
    self.flush()
  File "/afs/crc.nd.edu/user/p/psoga/.conda/envs/gnn/lib/python3.10/logging/__init__.py", line 1084, in flush
    self.stream.flush()
OSError: [Errno 5] Input/output error
Call stack:
  File "/afs/crc.nd.edu/user/p/psoga/benchmarking-gnns/main_SBMs_node_classification.py", line 382, in <module>
    net_params['in_dim'] = torch.unique(dataset.train[0][0].ndata['feat'],dim=0).size(0) # node_dim (feat is an integer)
  File "/afs/crc.nd.edu/user/p/psoga/benchmarking-gnns/main_SBMs_node_classification.py", line 380, in main
    dataset.test.spatial_pos_lists = []
  File "/afs/crc.nd.edu/user/p/psoga/benchmarking-gnns/main_SBMs_node_classification.py", line 274, in train_val_pipeline
    break
Message: 'Best Train Accuracy Corresponding to Best Test Accuracy: 83.7162'
Arguments: ()
--- Logging error ---
Traceback (most recent call last):
  File "/afs/crc.nd.edu/user/p/psoga/.conda/envs/gnn/lib/python3.10/logging/__init__.py", line 1104, in emit
    self.flush()
  File "/afs/crc.nd.edu/user/p/psoga/.conda/envs/gnn/lib/python3.10/logging/__init__.py", line 1084, in flush
    self.stream.flush()
OSError: [Errno 5] Input/output error
Call stack:
  File "/afs/crc.nd.edu/user/p/psoga/benchmarking-gnns/main_SBMs_node_classification.py", line 382, in <module>
    net_params['in_dim'] = torch.unique(dataset.train[0][0].ndata['feat'],dim=0).size(0) # node_dim (feat is an integer)
  File "/afs/crc.nd.edu/user/p/psoga/benchmarking-gnns/main_SBMs_node_classification.py", line 380, in main
    dataset.test.spatial_pos_lists = []
  File "/afs/crc.nd.edu/user/p/psoga/benchmarking-gnns/main_SBMs_node_classification.py", line 275, in train_val_pipeline
Message: 'Convergence Time (Epochs): 264.0000'
Arguments: ()
--- Logging error ---
Traceback (most recent call last):
  File "/afs/crc.nd.edu/user/p/psoga/.conda/envs/gnn/lib/python3.10/logging/__init__.py", line 1104, in emit
    self.flush()
  File "/afs/crc.nd.edu/user/p/psoga/.conda/envs/gnn/lib/python3.10/logging/__init__.py", line 1084, in flush
    self.stream.flush()
OSError: [Errno 5] Input/output error
Call stack:
  File "/afs/crc.nd.edu/user/p/psoga/benchmarking-gnns/main_SBMs_node_classification.py", line 382, in <module>
    net_params['in_dim'] = torch.unique(dataset.train[0][0].ndata['feat'],dim=0).size(0) # node_dim (feat is an integer)
  File "/afs/crc.nd.edu/user/p/psoga/benchmarking-gnns/main_SBMs_node_classification.py", line 380, in main
    dataset.test.spatial_pos_lists = []
  File "/afs/crc.nd.edu/user/p/psoga/benchmarking-gnns/main_SBMs_node_classification.py", line 276, in train_val_pipeline
    except KeyboardInterrupt:
Message: 'TOTAL TIME TAKEN: 37760.0977s'
Arguments: ()
--- Logging error ---
Traceback (most recent call last):
  File "/afs/crc.nd.edu/user/p/psoga/.conda/envs/gnn/lib/python3.10/logging/__init__.py", line 1104, in emit
    self.flush()
  File "/afs/crc.nd.edu/user/p/psoga/.conda/envs/gnn/lib/python3.10/logging/__init__.py", line 1084, in flush
    self.stream.flush()
OSError: [Errno 5] Input/output error
Call stack:
  File "/afs/crc.nd.edu/user/p/psoga/benchmarking-gnns/main_SBMs_node_classification.py", line 382, in <module>
    net_params['in_dim'] = torch.unique(dataset.train[0][0].ndata['feat'],dim=0).size(0) # node_dim (feat is an integer)
  File "/afs/crc.nd.edu/user/p/psoga/benchmarking-gnns/main_SBMs_node_classification.py", line 380, in main
    dataset.test.spatial_pos_lists = []
  File "/afs/crc.nd.edu/user/p/psoga/benchmarking-gnns/main_SBMs_node_classification.py", line 277, in train_val_pipeline
    logger.info('-' * 89)
Message: 'AVG TIME PER EPOCH: 142.1774s'
Arguments: ()
--- Logging error ---
Traceback (most recent call last):
  File "/afs/crc.nd.edu/user/p/psoga/.conda/envs/gnn/lib/python3.10/logging/__init__.py", line 1104, in emit
    self.flush()
  File "/afs/crc.nd.edu/user/p/psoga/.conda/envs/gnn/lib/python3.10/logging/__init__.py", line 1084, in flush
    self.stream.flush()
OSError: [Errno 5] Input/output error
Call stack:
  File "/afs/crc.nd.edu/user/p/psoga/benchmarking-gnns/main_SBMs_node_classification.py", line 382, in <module>
    net_params['in_dim'] = torch.unique(dataset.train[0][0].ndata['feat'],dim=0).size(0) # node_dim (feat is an integer)
  File "/afs/crc.nd.edu/user/p/psoga/benchmarking-gnns/main_SBMs_node_classification.py", line 380, in main
    dataset.test.spatial_pos_lists = []
  File "/afs/crc.nd.edu/user/p/psoga/benchmarking-gnns/main_SBMs_node_classification.py", line 279, in train_val_pipeline
Message: {'seed': 41, 'epochs': 1000, 'batch_size': 26, 'init_lr': 0.0005, 'lr_reduce_factor': 0.5, 'lr_schedule_patience': 10, 'min_lr': 1e-06, 'weight_decay': 0.0, 'print_epoch_interval': 5, 'max_time': 24, 'seed_array': [41], 'job_num': 2}
Arguments: ()
--- Logging error ---
Traceback (most recent call last):
  File "/afs/crc.nd.edu/user/p/psoga/.conda/envs/gnn/lib/python3.10/logging/__init__.py", line 1104, in emit
    self.flush()
  File "/afs/crc.nd.edu/user/p/psoga/.conda/envs/gnn/lib/python3.10/logging/__init__.py", line 1084, in flush
    self.stream.flush()
OSError: [Errno 5] Input/output error
Call stack:
  File "/afs/crc.nd.edu/user/p/psoga/benchmarking-gnns/main_SBMs_node_classification.py", line 382, in <module>
    net_params['in_dim'] = torch.unique(dataset.train[0][0].ndata['feat'],dim=0).size(0) # node_dim (feat is an integer)
  File "/afs/crc.nd.edu/user/p/psoga/benchmarking-gnns/main_SBMs_node_classification.py", line 380, in main
    dataset.test.spatial_pos_lists = []
  File "/afs/crc.nd.edu/user/p/psoga/benchmarking-gnns/main_SBMs_node_classification.py", line 280, in train_val_pipeline
    test_history.append(test_acc)
Message: 'train history: [83.71621529245374]'
Arguments: ()
--- Logging error ---
Traceback (most recent call last):
  File "/afs/crc.nd.edu/user/p/psoga/.conda/envs/gnn/lib/python3.10/logging/__init__.py", line 1104, in emit
    self.flush()
  File "/afs/crc.nd.edu/user/p/psoga/.conda/envs/gnn/lib/python3.10/logging/__init__.py", line 1084, in flush
    self.stream.flush()
OSError: [Errno 5] Input/output error
Call stack:
  File "/afs/crc.nd.edu/user/p/psoga/benchmarking-gnns/main_SBMs_node_classification.py", line 382, in <module>
    net_params['in_dim'] = torch.unique(dataset.train[0][0].ndata['feat'],dim=0).size(0) # node_dim (feat is an integer)
  File "/afs/crc.nd.edu/user/p/psoga/benchmarking-gnns/main_SBMs_node_classification.py", line 380, in main
    dataset.test.spatial_pos_lists = []
  File "/afs/crc.nd.edu/user/p/psoga/benchmarking-gnns/main_SBMs_node_classification.py", line 281, in train_val_pipeline
    val_history.append(val_acc)
Message: 'test history: [83.78727305871935]'
Arguments: ()
--- Logging error ---
Traceback (most recent call last):
  File "/afs/crc.nd.edu/user/p/psoga/.conda/envs/gnn/lib/python3.10/logging/__init__.py", line 1104, in emit
    self.flush()
  File "/afs/crc.nd.edu/user/p/psoga/.conda/envs/gnn/lib/python3.10/logging/__init__.py", line 1084, in flush
    self.stream.flush()
OSError: [Errno 5] Input/output error
Call stack:
  File "/afs/crc.nd.edu/user/p/psoga/benchmarking-gnns/main_SBMs_node_classification.py", line 382, in <module>
    net_params['in_dim'] = torch.unique(dataset.train[0][0].ndata['feat'],dim=0).size(0) # node_dim (feat is an integer)
  File "/afs/crc.nd.edu/user/p/psoga/benchmarking-gnns/main_SBMs_node_classification.py", line 380, in main
    dataset.test.spatial_pos_lists = []
  File "/afs/crc.nd.edu/user/p/psoga/benchmarking-gnns/main_SBMs_node_classification.py", line 282, in train_val_pipeline
    train_history.append(train_acc)
Message: 'val history: [83.60545756857255]'
Arguments: ()
[I] Loading dataset SBM_PATTERN...
train, test, val sizes : 10000 2000 2000
[I] Finished loading.
[I] Data load time: 16.2595s
Epoch 00040: reducing learning rate of group 0 to 2.5000e-04.
Epoch 00054: reducing learning rate of group 0 to 1.2500e-04.
Epoch 00117: reducing learning rate of group 0 to 6.2500e-05.
Epoch 00160: reducing learning rate of group 0 to 3.1250e-05.
Epoch 00190: reducing learning rate of group 0 to 1.5625e-05.
Epoch 00211: reducing learning rate of group 0 to 7.8125e-06.
Epoch 00235: reducing learning rate of group 0 to 3.9063e-06.
Epoch 00254: reducing learning rate of group 0 to 1.9531e-06.
Epoch 00265: reducing learning rate of group 0 to 9.7656e-07.
