[I] Loading dataset SBM_PATTERN...
train, test, val sizes : 10000 2000 2000
[I] Finished loading.
[I] Data load time: 16.8618s
0it [00:00, ?it/s]0it [00:02, ?it/s]
Traceback (most recent call last):
  File "/afs/crc.nd.edu/user/p/psoga/benchmarking-gnns/train/train_SBMs_node_classification.py", line 30, in train_epoch_sparse
    batch_pos_enc = batch_graphs.ndata['pos_enc'].to(device)
  File "/afs/crc.nd.edu/user/p/psoga/.conda/envs/gnn/lib/python3.10/site-packages/dgl/view.py", line 67, in __getitem__
    return self._graph._get_n_repr(self._ntid, self._nodes)[key]
  File "/afs/crc.nd.edu/user/p/psoga/.conda/envs/gnn/lib/python3.10/site-packages/dgl/frame.py", line 523, in __getitem__
    return self._columns[name].data
KeyError: 'pos_enc'

During handling of the above exception, another exception occurred:

Traceback (most recent call last):
  File "/afs/crc.nd.edu/user/p/psoga/benchmarking-gnns/main_SBMs_node_classification.py", line 291, in <module>
    main()    
  File "/afs/crc.nd.edu/user/p/psoga/benchmarking-gnns/main_SBMs_node_classification.py", line 289, in main
    train_val_pipeline(MODEL_NAME, dataset, params, net_params, dirs)
  File "/afs/crc.nd.edu/user/p/psoga/benchmarking-gnns/main_SBMs_node_classification.py", line 125, in train_val_pipeline
    epoch_train_loss, epoch_train_acc, optimizer = train_epoch(model, optimizer, device, train_loader, epoch)
  File "/afs/crc.nd.edu/user/p/psoga/benchmarking-gnns/train/train_SBMs_node_classification.py", line 36, in train_epoch_sparse
    batch_scores = model.forward(batch_graphs, batch_x, batch_e)
  File "/afs/crc.nd.edu/user/p/psoga/benchmarking-gnns/nets/SBMs_node_classification/graph_transformer.py", line 51, in forward
    h = self.pe_layer(g, h, pos_enc)
  File "/afs/crc.nd.edu/user/p/psoga/.conda/envs/gnn/lib/python3.10/site-packages/torch/nn/modules/module.py", line 1130, in _call_impl
    return forward_call(*input, **kwargs)
  File "/afs/crc.nd.edu/user/p/psoga/benchmarking-gnns/layers/pe_layer.py", line 129, in forward
    B = torch.eye(kron_prod.shape[1]).to(self.device) - kron_prod
RuntimeError: CUDA out of memory. Tried to allocate 5.29 GiB (GPU 0; 11.91 GiB total capacity; 10.61 GiB already allocated; 841.00 MiB free; 10.61 GiB reserved in total by PyTorch) If reserved memory is >> allocated memory try setting max_split_size_mb to avoid fragmentation.  See documentation for Memory Management and PYTORCH_CUDA_ALLOC_CONF
